Workbook

Sheet Sheet1
A2: Unit: | B2: Millimeters
A3: Type: | B3: Bend Deduction
A4: Material: | B4: Aço
A7: Thickness: | B7: 1
A8: Angle | B8: Radius
B9: 0.5 | C9: 1 | D9: 1.1 | E9: 1.2 | F9: 1.3 | G9: 1.4 | H9: 1.6 | I9: 1.7 | J9: 1.9 | K9: 2 | L9: 2.3 | M9: 2.5 | N9: 2.6 | O9: 2.7 | P9: 3 | Q9: 3.2 | R9: 3.3 | S9: 3.4 | T9: 3.7 | U9: 3.9 | V9: 4.3 | W9: 4.5 | X9: 5.5
A10: 15 | B10: 1 | C10: 0 | D10: =2*(-1*INDEX('Desconto Processos'!$B$5:$H$32,MATCH(180-$A10,'Desconto Processos'!$A$5:$A$32,0),MATCH(D$9,'Desconto Processos'!$B$3:$H$3,0))+INDEX('Acrescimo Tangente'!$B$4:$W$31,MATCH($A10,$A$10:$A$37,0),MATCH(D$9,$C$9:$X$9,0))) -> 0.2 | E10: 0 | F10: 0 | G10: =2*(-1*INDEX('Desconto Processos'!$B$5:$H$32,MATCH(180-$A10,'Desconto Processos'!$A$5:$A$32,0),MATCH(G$9,'Desconto Processos'!$B$3:$H$3,0))+INDEX('Acrescimo Tangente'!$B$4:$W$31,MATCH($A10,$A$10:$A$37,0),MATCH(G$9,$C$9:$X$9,0))) -> 0.2 | H10: 0 | I10: 0 | J10: =2*(-1*INDEX('Desconto Processos'!$B$5:$H$32,MATCH(180-$A10,'Desconto Processos'!$A$5:$A$32,0),MATCH(J$9,'Desconto Processos'!$B$3:$H$3,0))+INDEX('Acrescimo Tangente'!$B$4:$W$31,MATCH($A10,$A$10:$A$37,0),MATCH(J$9,$C$9:$X$9,0))) -> 0.2 | K10: 0 | L10: 0 | M10: =2*(-1*INDEX('Desconto Processos'!$B$5:$H$32,MATCH(180-$A10,'Desconto Processos'!$A$5:$A$32,0),MATCH(M$9,'Desconto Processos'!$B$3:$H$3,0))+INDEX('Acrescimo Tangente'!$B$4:$W$31,MATCH($A10,$A$10:$A$37,0),MATCH(M$9,$C$9:$X$9,0))) -> 0.2 | N10: 0 | O10: 0 | P10: 0 | Q10: 0 | R10: 0 | S10: 0 | T10: =2*(-1*INDEX('Desconto Processos'!$B$5:$H$32,MATCH(180-$A10,'Desconto Processos'!$A$5:$A$32,0),MATCH(T$9,'Desconto Processos'!$B$3:$H$3,0))+INDEX('Acrescimo Tangente'!$B$4:$W$31,MATCH($A10,$A$10:$A$37,0),MATCH(T$9,$C$9:$X$9,0))) -> 0.2 | U10: 0 | V10: 0 | W10: =2*(-1*INDEX('Desconto Processos'!$B$5:$H$32,MATCH(180-$A10,'Desconto Processos'!$A$5:$A$32,0),MATCH(W$9,'Desconto Processos'!$B$3:$H$3,0))+INDEX('Acrescimo Tangente'!$B$4:$W$31,MATCH($A10,$A$10:$A$37,0),MATCH(W$9,$C$9:$X$9,0))) -> 0.2 | X10: =2*(-1*INDEX('Desconto Processos'!$B$5:$H$32,MATCH(180-$A10,'Desconto Processos'!$A$5:$A$32,0),MATCH(X$9,'Desconto Processos'!$B$3:$H$3,0))+INDEX('Acrescimo Tangente'!$B$4:$W$31,MATCH($A10,$A$10:$A$37,0),MATCH(X$9,$C$9:$X$9,0))) -> 0.2
A11: 20 | B11: 1 | C11: 0 | D11: =2*(-1*INDEX('Desconto Processos'!$B$5:$H$32,MATCH(180-$A11,'Desconto Processos'!$A$5:$A$32,0),MATCH(D$9,'Desconto Processos'!$B$3:$H$3,0))+INDEX('Acrescimo Tangente'!$B$4:$W$31,MATCH($A11,$A$10:$A$37,0),MATCH(D$9,$C$9:$X$9,0))) -> 0.2 | E11: 0 | F11: 0 | G11: =2*(-1*INDEX('Desconto Processos'!$B$5:$H$32,MATCH(180-$A11,'Desconto Processos'!$A$5:$A$32,0),MATCH(G$9,'Desconto Processos'!$B$3:$H$3,0))+INDEX('Acrescimo Tangente'!$B$4:$W$31,MATCH($A11,$A$10:$A$37,0),MATCH(G$9,$C$9:$X$9,0))) -> 0.2 | H11: 0 | I11: 0 | J11: =2*(-1*INDEX('Desconto Processos'!$B$5:$H$32,MATCH(180-$A11,'Desconto Processos'!$A$5:$A$32,0),MATCH(J$9,'Desconto Processos'!$B$3:$H$3,0))+INDEX('Acrescimo Tangente'!$B$4:$W$31,MATCH($A11,$A$10:$A$37,0),MATCH(J$9,$C$9:$X$9,0))) -> 0.2 | K11: 0 | L11: 0 | M11: =2*(-1*INDEX('Desconto Processos'!$B$5:$H$32,MATCH(180-$A11,'Desconto Processos'!$A$5:$A$32,0),MATCH(M$9,'Desconto Processos'!$B$3:$H$3,0))+INDEX('Acrescimo Tangente'!$B$4:$W$31,MATCH($A11,$A$10:$A$37,0),MATCH(M$9,$C$9:$X$9,0))) -> 0.2 | N11: 0 | O11: 0 | P11: 0 | Q11: 0 | R11: 0 | S11: 0 | T11: =2*(-1*INDEX('Desconto Processos'!$B$5:$H$32,MATCH(180-$A11,'Desconto Processos'!$A$5:$A$32,0),MATCH(T$9,'Desconto Processos'!$B$3:$H$3,0))+INDEX('Acrescimo Tangente'!$B$4:$W$31,MATCH($A11,$A$10:$A$37,0),MATCH(T$9,$C$9:$X$9,0))) -> 0.2 | U11: 0 | V11: 0 | W11: =2*(-1*INDEX('Desconto Processos'!$B$5:$H$32,MATCH(180-$A11,'Desconto Processos'!$A$5:$A$32,0),MATCH(W$9,'Desconto Processos'!$B$3:$H$3,0))+INDEX('Acrescimo Tangente'!$B$4:$W$31,MATCH($A11,$A$10:$A$37,0),MATCH(W$9,$C$9:$X$9,0))) -> 0.2 | X11: =2*(-1*INDEX('Desconto Processos'!$B$5:$H$32,MATCH(180-$A11,'Desconto Processos'!$A$5:$A$32,0),MATCH(X$9,'Desconto Processos'!$B$3:$H$3,0))+INDEX('Acrescimo Tangente'!$B$4:$W$31,MATCH($A11,$A$10:$A$37,0),MATCH(X$9,$C$9:$X$9,0))) -> 0.2
A12: 25 | B12: 1 | C12: 0 | D12: =2*(-1*INDEX('Desconto Processos'!$B$5:$H$32,MATCH(180-$A12,'Desconto Processos'!$A$5:$A$32,0),MATCH(D$9,'Desconto Processos'!$B$3:$H$3,0))+INDEX('Acrescimo Tangente'!$B$4:$W$31,MATCH($A12,$A$10:$A$37,0),MATCH(D$9,$C$9:$X$9,0))) -> 0.3 | E12: 0 | F12: 0 | G12: =2*(-1*INDEX('Desconto Processos'!$B$5:$H$32,MATCH(180-$A12,'Desconto Processos'!$A$5:$A$32,0),MATCH(G$9,'Desconto Processos'!$B$3:$H$3,0))+INDEX('Acrescimo Tangente'!$B$4:$W$31,MATCH($A12,$A$10:$A$37,0),MATCH(G$9,$C$9:$X$9,0))) -> 0.3 | H12: 0 | I12: 0 | J12: =2*(-1*INDEX('Desconto Processos'!$B$5:$H$32,MATCH(180-$A12,'Desconto Processos'!$A$5:$A$32,0),MATCH(J$9,'Desconto Processos'!$B$3:$H$3,0))+INDEX('Acrescimo Tangente'!$B$4:$W$31,MATCH($A12,$A$10:$A$37,0),MATCH(J$9,$C$9:$X$9,0))) -> 0.3 | K12: 0 | L12: 0 | M12: =2*(-1*INDEX('Desconto Processos'!$B$5:$H$32,MATCH(180-$A12,'Desconto Processos'!$A$5:$A$32,0),MATCH(M$9,'Desconto Processos'!$B$3:$H$3,0))+INDEX('Acrescimo Tangente'!$B$4:$W$31,MATCH($A12,$A$10:$A$37,0),MATCH(M$9,$C$9:$X$9,0))) -> 0.3 | N12: 0 | O12: 0 | P12: 0 | Q12: 0 | R12: 0 | S12: 0 | T12: =2*(-1*INDEX('Desconto Processos'!$B$5:$H$32,MATCH(180-$A12,'Desconto Processos'!$A$5:$A$32,0),MATCH(T$9,'Desconto Processos'!$B$3:$H$3,0))+INDEX('Acrescimo Tangente'!$B$4:$W$31,MATCH($A12,$A$10:$A$37,0),MATCH(T$9,$C$9:$X$9,0))) -> 0.3 | U12: 0 | V12: 0 | W12: =2*(-1*INDEX('Desconto Processos'!$B$5:$H$32,MATCH(180-$A12,'Desconto Processos'!$A$5:$A$32,0),MATCH(W$9,'Desconto Processos'!$B$3:$H$3,0))+INDEX('Acrescimo Tangente'!$B$4:$W$31,MATCH($A12,$A$10:$A$37,0),MATCH(W$9,$C$9:$X$9,0))) -> 0.3 | X12: =2*(-1*INDEX('Desconto Processos'!$B$5:$H$32,MATCH(180-$A12,'Desconto Processos'!$A$5:$A$32,0),MATCH(X$9,'Desconto Processos'!$B$3:$H$3,0))+INDEX('Acrescimo Tangente'!$B$4:$W$31,MATCH($A12,$A$10:$A$37,0),MATCH(X$9,$C$9:$X$9,0))) -> 0.3
A13: 30 | B13: 1 | C13: 0 | D13: =2*(-1*INDEX('Desconto Processos'!$B$5:$H$32,MATCH(180-$A13,'Desconto Processos'!$A$5:$A$32,0),MATCH(D$9,'Desconto Processos'!$B$3:$H$3,0))+INDEX('Acrescimo Tangente'!$B$4:$W$31,MATCH($A13,$A$10:$A$37,0),MATCH(D$9,$C$9:$X$9,0))) -> 0.3 | E13: 0 | F13: 0 | G13: =2*(-1*INDEX('Desconto Processos'!$B$5:$H$32,MATCH(180-$A13,'Desconto Processos'!$A$5:$A$32,0),MATCH(G$9,'Desconto Processos'!$B$3:$H$3,0))+INDEX('Acrescimo Tangente'!$B$4:$W$31,MATCH($A13,$A$10:$A$37,0),MATCH(G$9,$C$9:$X$9,0))) -> 0.3 | H13: 0 | I13: 0 | J13: =2*(-1*INDEX('Desconto Processos'!$B$5:$H$32,MATCH(180-$A13,'Desconto Processos'!$A$5:$A$32,0),MATCH(J$9,'Desconto Processos'!$B$3:$H$3,0))+INDEX('Acrescimo Tangente'!$B$4:$W$31,MATCH($A13,$A$10:$A$37,0),MATCH(J$9,$C$9:$X$9,0))) -> 0.3 | K13: 0 | L13: 0 | M13: =2*(-1*INDEX('Desconto Processos'!$B$5:$H$32,MATCH(180-$A13,'Desconto Processos'!$A$5:$A$32,0),MATCH(M$9,'Desconto Processos'!$B$3:$H$3,0))+INDEX('Acrescimo Tangente'!$B$4:$W$31,MATCH($A13,$A$10:$A$37,0),MATCH(M$9,$C$9:$X$9,0))) -> 0.4 | N13: 0 | O13: 0 | P13: 0 | Q13: 0 | R13: 0 | S13: 0 | T13: =2*(-1*INDEX('Desconto Processos'!$B$5:$H$32,MATCH(180-$A13,'Desconto Processos'!$A$5:$A$32,0),MATCH(T$9,'Desconto Processos'!$B$3:$H$3,0))+INDEX('Acrescimo Tangente'!$B$4:$W$31,MATCH($A13,$A$10:$A$37,0),MATCH(T$9,$C$9:$X$9,0))) -> 0.4 | U13: 0 | V13: 0 | W13: =2*(-1*INDEX('Desconto Processos'!$B$5:$H$32,MATCH(180-$A13,'Desconto Processos'!$A$5:$A$32,0),MATCH(W$9,'Desconto Processos'!$B$3:$H$3,0))+INDEX('Acrescimo Tangente'!$B$4:$W$31,MATCH($A13,$A$10:$A$37,0),MATCH(W$9,$C$9:$X$9,0))) -> 0.4 | X13: =2*(-1*INDEX('Desconto Processos'!$B$5:$H$32,MATCH(180-$A13,'Desconto Processos'!$A$5:$A$32,0),MATCH(X$9,'Desconto Processos'!$B$3:$H$3,0))+INDEX('Acrescimo Tangente'!$B$4:$W$31,MATCH($A13,$A$10:$A$37,0),MATCH(X$9,$C$9:$X$9,0))) -> 0.5
A14: 35 | B14: 1 | C14: 0 | D14: =2*(-1*INDEX('Desconto Processos'!$B$5:$H$32,MATCH(180-$A14,'Desconto Processos'!$A$5:$A$32,0),MATCH(D$9,'Desconto Processos'!$B$3:$H$3,0))+INDEX('Acrescimo Tangente'!$B$4:$W$31,MATCH($A14,$A$10:$A$37,0),MATCH(D$9,$C$9:$X$9,0))) -> 0.4 | E14: 0 | F14: 0 | G14: =2*(-1*INDEX('Desconto Processos'!$B$5:$H$32,MATCH(180-$A14,'Desconto Processos'!$A$5:$A$32,0),MATCH(G$9,'Desconto Processos'!$B$3:$H$3,0))+INDEX('Acrescimo Tangente'!$B$4:$W$31,MATCH($A14,$A$10:$A$37,0),MATCH(G$9,$C$9:$X$9,0))) -> 0.4 | H14: 0 | I14: 0 | J14: =2*(-1*INDEX('Desconto Processos'!$B$5:$H$32,MATCH(180-$A14,'Desconto Processos'!$A$5:$A$32,0),MATCH(J$9,'Desconto Processos'!$B$3:$H$3,0))+INDEX('Acrescimo Tangente'!$B$4:$W$31,MATCH($A14,$A$10:$A$37,0),MATCH(J$9,$C$9:$X$9,0))) -> 0.4 | K14: 0 | L14: 0 | M14: =2*(-1*INDEX('Desconto Processos'!$B$5:$H$32,MATCH(180-$A14,'Desconto Processos'!$A$5:$A$32,0),MATCH(M$9,'Desconto Processos'!$B$3:$H$3,0))+INDEX('Acrescimo Tangente'!$B$4:$W$31,MATCH($A14,$A$10:$A$37,0),MATCH(M$9,$C$9:$X$9,0))) -> 0.4 | N14: 0 | O14: 0 | P14: 0 | Q14: 0 | R14: 0 | S14: 0 | T14: =2*(-1*INDEX('Desconto Processos'!$B$5:$H$32,MATCH(180-$A14,'Desconto Processos'!$A$5:$A$32,0),MATCH(T$9,'Desconto Processos'!$B$3:$H$3,0))+INDEX('Acrescimo Tangente'!$B$4:$W$31,MATCH($A14,$A$10:$A$37,0),MATCH(T$9,$C$9:$X$9,0))) -> 0.4 | U14: 0 | V14: 0 | W14: =2*(-1*INDEX('Desconto Processos'!$B$5:$H$32,MATCH(180-$A14,'Desconto Processos'!$A$5:$A$32,0),MATCH(W$9,'Desconto Processos'!$B$3:$H$3,0))+INDEX('Acrescimo Tangente'!$B$4:$W$31,MATCH($A14,$A$10:$A$37,0),MATCH(W$9,$C$9:$X$9,0))) -> 0.5 | X14: =2*(-1*INDEX('Desconto Processos'!$B$5:$H$32,MATCH(180-$A14,'Desconto Processos'!$A$5:$A$32,0),MATCH(X$9,'Desconto Processos'!$B$3:$H$3,0))+INDEX('Acrescimo Tangente'!$B$4:$W$31,MATCH($A14,$A$10:$A$37,0),MATCH(X$9,$C$9:$X$9,0))) -> 0.6
A15: 40 | B15: 1 | C15: 0 | D15: =2*(-1*INDEX('Desconto Processos'!$B$5:$H$32,MATCH(180-$A15,'Desconto Processos'!$A$5:$A$32,0),MATCH(D$9,'Desconto Processos'!$B$3:$H$3,0))+INDEX('Acrescimo Tangente'!$B$4:$W$31,MATCH($A15,$A$10:$A$37,0),MATCH(D$9,$C$9:$X$9,0))) -> 0.5 | E15: 0 | F15: 0 | G15: =2*(-1*INDEX('Desconto Processos'!$B$5:$H$32,MATCH(180-$A15,'Desconto Processos'!$A$5:$A$32,0),MATCH(G$9,'Desconto Processos'!$B$3:$H$3,0))+INDEX('Acrescimo Tangente'!$B$4:$W$31,MATCH($A15,$A$10:$A$37,0),MATCH(G$9,$C$9:$X$9,0))) -> 0.5 | H15: 0 | I15: 0 | J15: =2*(-1*INDEX('Desconto Processos'!$B$5:$H$32,MATCH(180-$A15,'Desconto Processos'!$A$5:$A$32,0),MATCH(J$9,'Desconto Processos'!$B$3:$H$3,0))+INDEX('Acrescimo Tangente'!$B$4:$W$31,MATCH($A15,$A$10:$A$37,0),MATCH(J$9,$C$9:$X$9,0))) -> 0.5 | K15: 0 | L15: 0 | M15: =2*(-1*INDEX('Desconto Processos'!$B$5:$H$32,MATCH(180-$A15,'Desconto Processos'!$A$5:$A$32,0),MATCH(M$9,'Desconto Processos'!$B$3:$H$3,0))+INDEX('Acrescimo Tangente'!$B$4:$W$31,MATCH($A15,$A$10:$A$37,0),MATCH(M$9,$C$9:$X$9,0))) -> 0.5 | N15: 0 | O15: 0 | P15: 0 | Q15: 0 | R15: 0 | S15: 0 | T15: =2*(-1*INDEX('Desconto Processos'!$B$5:$H$32,MATCH(180-$A15,'Desconto Processos'!$A$5:$A$32,0),MATCH(T$9,'Desconto Processos'!$B$3:$H$3,0))+INDEX('Acrescimo Tangente'!$B$4:$W$31,MATCH($A15,$A$10:$A$37,0),MATCH(T$9,$C$9:$X$9,0))) -> 0.6 | U15: 0 | V15: 0 | W15: =2*(-1*INDEX('Desconto Processos'!$B$5:$H$32,MATCH(180-$A15,'Desconto Processos'!$A$5:$A$32,0),MATCH(W$9,'Desconto Processos'!$B$3:$H$3,0))+INDEX('Acrescimo Tangente'!$B$4:$W$31,MATCH($A15,$A$10:$A$37,0),MATCH(W$9,$C$9:$X$9,0))) -> 0.6 | X15: =2*(-1*INDEX('Desconto Processos'!$B$5:$H$32,MATCH(180-$A15,'Desconto Processos'!$A$5:$A$32,0),MATCH(X$9,'Desconto Processos'!$B$3:$H$3,0))+INDEX('Acrescimo Tangente'!$B$4:$W$31,MATCH($A15,$A$10:$A$37,0),MATCH(X$9,$C$9:$X$9,0))) -> 0.7
A16: 45 | B16: 1 | C16: 0 | D16: =2*(-1*INDEX('Desconto Processos'!$B$5:$H$32,MATCH(180-$A16,'Desconto Processos'!$A$5:$A$32,0),MATCH(D$9,'Desconto Processos'!$B$3:$H$3,0))+INDEX('Acrescimo Tangente'!$B$4:$W$31,MATCH($A16,$A$10:$A$37,0),MATCH(D$9,$C$9:$X$9,0))) -> 0.6 | E16: 0 | F16: 0 | G16: =2*(-1*INDEX('Desconto Processos'!$B$5:$H$32,MATCH(180-$A16,'Desconto Processos'!$A$5:$A$32,0),MATCH(G$9,'Desconto Processos'!$B$3:$H$3,0))+INDEX('Acrescimo Tangente'!$B$4:$W$31,MATCH($A16,$A$10:$A$37,0),MATCH(G$9,$C$9:$X$9,0))) -> 0.6 | H16: 0 | I16: 0 | J16: =2*(-1*INDEX('Desconto Processos'!$B$5:$H$32,MATCH(180-$A16,'Desconto Processos'!$A$5:$A$32,0),MATCH(J$9,'Desconto Processos'!$B$3:$H$3,0))+INDEX('Acrescimo Tangente'!$B$4:$W$31,MATCH($A16,$A$10:$A$37,0),MATCH(J$9,$C$9:$X$9,0))) -> 0.6 | K16: 0 | L16: 0 | M16: =2*(-1*INDEX('Desconto Processos'!$B$5:$H$32,MATCH(180-$A16,'Desconto Processos'!$A$5:$A$32,0),MATCH(M$9,'Desconto Processos'!$B$3:$H$3,0))+INDEX('Acrescimo Tangente'!$B$4:$W$31,MATCH($A16,$A$10:$A$37,0),MATCH(M$9,$C$9:$X$9,0))) -> 0.7 | N16: 0 | O16: 0 | P16: 0 | Q16: 0 | R16: 0 | S16: 0 | T16: =2*(-1*INDEX('Desconto Processos'!$B$5:$H$32,MATCH(180-$A16,'Desconto Processos'!$A$5:$A$32,0),MATCH(T$9,'Desconto Processos'!$B$3:$H$3,0))+INDEX('Acrescimo Tangente'!$B$4:$W$31,MATCH($A16,$A$10:$A$37,0),MATCH(T$9,$C$9:$X$9,0))) -> 0.7 | U16: 0 | V16: 0 | W16: =2*(-1*INDEX('Desconto Processos'!$B$5:$H$32,MATCH(180-$A16,'Desconto Processos'!$A$5:$A$32,0),MATCH(W$9,'Desconto Processos'!$B$3:$H$3,0))+INDEX('Acrescimo Tangente'!$B$4:$W$31,MATCH($A16,$A$10:$A$37,0),MATCH(W$9,$C$9:$X$9,0))) -> 0.8 | X16: =2*(-1*INDEX('Desconto Processos'!$B$5:$H$32,MATCH(180-$A16,'Desconto Processos'!$A$5:$A$32,0),MATCH(X$9,'Desconto Processos'!$B$3:$H$3,0))+INDEX('Acrescimo Tangente'!$B$4:$W$31,MATCH($A16,$A$10:$A$37,0),MATCH(X$9,$C$9:$X$9,0))) -> 0.9
A17: 50 | B17: 1 | C17: 0 | D17: =2*(-1*INDEX('Desconto Processos'!$B$5:$H$32,MATCH(180-$A17,'Desconto Processos'!$A$5:$A$32,0),MATCH(D$9,'Desconto Processos'!$B$3:$H$3,0))+INDEX('Acrescimo Tangente'!$B$4:$W$31,MATCH($A17,$A$10:$A$37,0),MATCH(D$9,$C$9:$X$9,0))) -> 0.7 | E17: 0 | F17: 0 | G17: =2*(-1*INDEX('Desconto Processos'!$B$5:$H$32,MATCH(180-$A17,'Desconto Processos'!$A$5:$A$32,0),MATCH(G$9,'Desconto Processos'!$B$3:$H$3,0))+INDEX('Acrescimo Tangente'!$B$4:$W$31,MATCH($A17,$A$10:$A$37,0),MATCH(G$9,$C$9:$X$9,0))) -> 0.7 | H17: 0 | I17: 0 | J17: =2*(-1*INDEX('Desconto Processos'!$B$5:$H$32,MATCH(180-$A17,'Desconto Processos'!$A$5:$A$32,0),MATCH(J$9,'Desconto Processos'!$B$3:$H$3,0))+INDEX('Acrescimo Tangente'!$B$4:$W$31,MATCH($A17,$A$10:$A$37,0),MATCH(J$9,$C$9:$X$9,0))) -> 0.7 | K17: 0 | L17: 0 | M17: =2*(-1*INDEX('Desconto Processos'!$B$5:$H$32,MATCH(180-$A17,'Desconto Processos'!$A$5:$A$32,0),MATCH(M$9,'Desconto Processos'!$B$3:$H$3,0))+INDEX('Acrescimo Tangente'!$B$4:$W$31,MATCH($A17,$A$10:$A$37,0),MATCH(M$9,$C$9:$X$9,0))) -> 0.7 | N17: 0 | O17: 0 | P17: 0 | Q17: 0 | R17: 0 | S17: 0 | T17: =2*(-1*INDEX('Desconto Processos'!$B$5:$H$32,MATCH(180-$A17,'Desconto Processos'!$A$5:$A$32,0),MATCH(T$9,'Desconto Processos'!$B$3:$H$3,0))+INDEX('Acrescimo Tangente'!$B$4:$W$31,MATCH($A17,$A$10:$A$37,0),MATCH(T$9,$C$9:$X$9,0))) -> 0.8 | U17: 0 | V17: 0 | W17: =2*(-1*INDEX('Desconto Processos'!$B$5:$H$32,MATCH(180-$A17,'Desconto Processos'!$A$5:$A$32,0),MATCH(W$9,'Desconto Processos'!$B$3:$H$3,0))+INDEX('Acrescimo Tangente'!$B$4:$W$31,MATCH($A17,$A$10:$A$37,0),MATCH(W$9,$C$9:$X$9,0))) -> 0.8 | X17: =2*(-1*INDEX('Desconto Processos'!$B$5:$H$32,MATCH(180-$A17,'Desconto Processos'!$A$5:$A$32,0),MATCH(X$9,'Desconto Processos'!$B$3:$H$3,0))+INDEX('Acrescimo Tangente'!$B$4:$W$31,MATCH($A17,$A$10:$A$37,0),MATCH(X$9,$C$9:$X$9,0))) -> 1
A18: 55 | B18: 1 | C18: 0 | D18: =2*(-1*INDEX('Desconto Processos'!$B$5:$H$32,MATCH(180-$A18,'Desconto Processos'!$A$5:$A$32,0),MATCH(D$9,'Desconto Processos'!$B$3:$H$3,0))+INDEX('Acrescimo Tangente'!$B$4:$W$31,MATCH($A18,$A$10:$A$37,0),MATCH(D$9,$C$9:$X$9,0))) -> 0.8 | E18: 0 | F18: 0 | G18: =2*(-1*INDEX('Desconto Processos'!$B$5:$H$32,MATCH(180-$A18,'Desconto Processos'!$A$5:$A$32,0),MATCH(G$9,'Desconto Processos'!$B$3:$H$3,0))+INDEX('Acrescimo Tangente'!$B$4:$W$31,MATCH($A18,$A$10:$A$37,0),MATCH(G$9,$C$9:$X$9,0))) -> 0.8 | H18: 0 | I18: 0 | J18: =2*(-1*INDEX('Desconto Processos'!$B$5:$H$32,MATCH(180-$A18,'Desconto Processos'!$A$5:$A$32,0),MATCH(J$9,'Desconto Processos'!$B$3:$H$3,0))+INDEX('Acrescimo Tangente'!$B$4:$W$31,MATCH($A18,$A$10:$A$37,0),MATCH(J$9,$C$9:$X$9,0))) -> 0.8 | K18: 0 | L18: 0 | M18: =2*(-1*INDEX('Desconto Processos'!$B$5:$H$32,MATCH(180-$A18,'Desconto Processos'!$A$5:$A$32,0),MATCH(M$9,'Desconto Processos'!$B$3:$H$3,0))+INDEX('Acrescimo Tangente'!$B$4:$W$31,MATCH($A18,$A$10:$A$37,0),MATCH(M$9,$C$9:$X$9,0))) -> 0.8 | N18: 0 | O18: 0 | P18: 0 | Q18: 0 | R18: 0 | S18: 0 | T18: =2*(-1*INDEX('Desconto Processos'!$B$5:$H$32,MATCH(180-$A18,'Desconto Processos'!$A$5:$A$32,0),MATCH(T$9,'Desconto Processos'!$B$3:$H$3,0))+INDEX('Acrescimo Tangente'!$B$4:$W$31,MATCH($A18,$A$10:$A$37,0),MATCH(T$9,$C$9:$X$9,0))) -> 0.9 | U18: 0 | V18: 0 | W18: =2*(-1*INDEX('Desconto Processos'!$B$5:$H$32,MATCH(180-$A18,'Desconto Processos'!$A$5:$A$32,0),MATCH(W$9,'Desconto Processos'!$B$3:$H$3,0))+INDEX('Acrescimo Tangente'!$B$4:$W$31,MATCH($A18,$A$10:$A$37,0),MATCH(W$9,$C$9:$X$9,0))) -> 1 | X18: =2*(-1*INDEX('Desconto Processos'!$B$5:$H$32,MATCH(180-$A18,'Desconto Processos'!$A$5:$A$32,0),MATCH(X$9,'Desconto Processos'!$B$3:$H$3,0))+INDEX('Acrescimo Tangente'!$B$4:$W$31,MATCH($A18,$A$10:$A$37,0),MATCH(X$9,$C$9:$X$9,0))) -> 1.2
A19: 60 | B19: 1 | C19: 0 | D19: =2*(-1*INDEX('Desconto Processos'!$B$5:$H$32,MATCH(180-$A19,'Desconto Processos'!$A$5:$A$32,0),MATCH(D$9,'Desconto Processos'!$B$3:$H$3,0))+INDEX('Acrescimo Tangente'!$B$4:$W$31,MATCH($A19,$A$10:$A$37,0),MATCH(D$9,$C$9:$X$9,0))) -> 0.8 | E19: 0 | F19: 0 | G19: =2*(-1*INDEX('Desconto Processos'!$B$5:$H$32,MATCH(180-$A19,'Desconto Processos'!$A$5:$A$32,0),MATCH(G$9,'Desconto Processos'!$B$3:$H$3,0))+INDEX('Acrescimo Tangente'!$B$4:$W$31,MATCH($A19,$A$10:$A$37,0),MATCH(G$9,$C$9:$X$9,0))) -> 0.9 | H19: 0 | I19: 0 | J19: =2*(-1*INDEX('Desconto Processos'!$B$5:$H$32,MATCH(180-$A19,'Desconto Processos'!$A$5:$A$32,0),MATCH(J$9,'Desconto Processos'!$B$3:$H$3,0))+INDEX('Acrescimo Tangente'!$B$4:$W$31,MATCH($A19,$A$10:$A$37,0),MATCH(J$9,$C$9:$X$9,0))) -> 1 | K19: 0 | L19: 0 | M19: =2*(-1*INDEX('Desconto Processos'!$B$5:$H$32,MATCH(180-$A19,'Desconto Processos'!$A$5:$A$32,0),MATCH(M$9,'Desconto Processos'!$B$3:$H$3,0))+INDEX('Acrescimo Tangente'!$B$4:$W$31,MATCH($A19,$A$10:$A$37,0),MATCH(M$9,$C$9:$X$9,0))) -> 1.1 | N19: 0 | O19: 0 | P19: 0 | Q19: 0 | R19: 0 | S19: 0 | T19: =2*(-1*INDEX('Desconto Processos'!$B$5:$H$32,MATCH(180-$A19,'Desconto Processos'!$A$5:$A$32,0),MATCH(T$9,'Desconto Processos'!$B$3:$H$3,0))+INDEX('Acrescimo Tangente'!$B$4:$W$31,MATCH($A19,$A$10:$A$37,0),MATCH(T$9,$C$9:$X$9,0))) -> 1.2 | U19: 0 | V19: 0 | W19: =2*(-1*INDEX('Desconto Processos'!$B$5:$H$32,MATCH(180-$A19,'Desconto Processos'!$A$5:$A$32,0),MATCH(W$9,'Desconto Processos'!$B$3:$H$3,0))+INDEX('Acrescimo Tangente'!$B$4:$W$31,MATCH($A19,$A$10:$A$37,0),MATCH(W$9,$C$9:$X$9,0))) -> 1.4 | X19: =2*(-1*INDEX('Desconto Processos'!$B$5:$H$32,MATCH(180-$A19,'Desconto Processos'!$A$5:$A$32,0),MATCH(X$9,'Desconto Processos'!$B$3:$H$3,0))+INDEX('Acrescimo Tangente'!$B$4:$W$31,MATCH($A19,$A$10:$A$37,0),MATCH(X$9,$C$9:$X$9,0))) -> 1.5
A20: 65 | B20: 1 | C20: 0 | D20: =2*(-1*INDEX('Desconto Processos'!$B$5:$H$32,MATCH(180-$A20,'Desconto Processos'!$A$5:$A$32,0),MATCH(D$9,'Desconto Processos'!$B$3:$H$3,0))+INDEX('Acrescimo Tangente'!$B$4:$W$31,MATCH($A20,$A$10:$A$37,0),MATCH(D$9,$C$9:$X$9,0))) -> 1 | E20: 0 | F20: 0 | G20: =2*(-1*INDEX('Desconto Processos'!$B$5:$H$32,MATCH(180-$A20,'Desconto Processos'!$A$5:$A$32,0),MATCH(G$9,'Desconto Processos'!$B$3:$H$3,0))+INDEX('Acrescimo Tangente'!$B$4:$W$31,MATCH($A20,$A$10:$A$37,0),MATCH(G$9,$C$9:$X$9,0))) -> 1.1 | H20: 0 | I20: 0 | J20: =2*(-1*INDEX('Desconto Processos'!$B$5:$H$32,MATCH(180-$A20,'Desconto Processos'!$A$5:$A$32,0),MATCH(J$9,'Desconto Processos'!$B$3:$H$3,0))+INDEX('Acrescimo Tangente'!$B$4:$W$31,MATCH($A20,$A$10:$A$37,0),MATCH(J$9,$C$9:$X$9,0))) -> 1.1 | K20: 0 | L20: 0 | M20: =2*(-1*INDEX('Desconto Processos'!$B$5:$H$32,MATCH(180-$A20,'Desconto Processos'!$A$5:$A$32,0),MATCH(M$9,'Desconto Processos'!$B$3:$H$3,0))+INDEX('Acrescimo Tangente'!$B$4:$W$31,MATCH($A20,$A$10:$A$37,0),MATCH(M$9,$C$9:$X$9,0))) -> 1.2 | N20: 0 | O20: 0 | P20: 0 | Q20: 0 | R20: 0 | S20: 0 | T20: =2*(-1*INDEX('Desconto Processos'!$B$5:$H$32,MATCH(180-$A20,'Desconto Processos'!$A$5:$A$32,0),MATCH(T$9,'Desconto Processos'!$B$3:$H$3,0))+INDEX('Acrescimo Tangente'!$B$4:$W$31,MATCH($A20,$A$10:$A$37,0),MATCH(T$9,$C$9:$X$9,0))) -> 1.3 | U20: 0 | V20: 0 | W20: =2*(-1*INDEX('Desconto Processos'!$B$5:$H$32,MATCH(180-$A20,'Desconto Processos'!$A$5:$A$32,0),MATCH(W$9,'Desconto Processos'!$B$3:$H$3,0))+INDEX('Acrescimo Tangente'!$B$4:$W$31,MATCH($A20,$A$10:$A$37,0),MATCH(W$9,$C$9:$X$9,0))) -> 1.4 | X20: =2*(-1*INDEX('Desconto Processos'!$B$5:$H$32,MATCH(180-$A20,'Desconto Processos'!$A$5:$A$32,0),MATCH(X$9,'Desconto Processos'!$B$3:$H$3,0))+INDEX('Acrescimo Tangente'!$B$4:$W$31,MATCH($A20,$A$10:$A$37,0),MATCH(X$9,$C$9:$X$9,0))) -> 1.6
A21: 70 | B21: 1 | C21: 0 | D21: =2*(-1*INDEX('Desconto Processos'!$B$5:$H$32,MATCH(180-$A21,'Desconto Processos'!$A$5:$A$32,0),MATCH(D$9,'Desconto Processos'!$B$3:$H$3,0))+INDEX('Acrescimo Tangente'!$B$4:$W$31,MATCH($A21,$A$10:$A$37,0),MATCH(D$9,$C$9:$X$9,0))) -> 1.2 | E21: 0 | F21: 0 | G21: =2*(-1*INDEX('Desconto Processos'!$B$5:$H$32,MATCH(180-$A21,'Desconto Processos'!$A$5:$A$32,0),MATCH(G$9,'Desconto Processos'!$B$3:$H$3,0))+INDEX('Acrescimo Tangente'!$B$4:$W$31,MATCH($A21,$A$10:$A$37,0),MATCH(G$9,$C$9:$X$9,0))) -> 1.2 | H21: 0 | I21: 0 | J21: =2*(-1*INDEX('Desconto Processos'!$B$5:$H$32,MATCH(180-$A21,'Desconto Processos'!$A$5:$A$32,0),MATCH(J$9,'Desconto Processos'!$B$3:$H$3,0))+INDEX('Acrescimo Tangente'!$B$4:$W$31,MATCH($A21,$A$10:$A$37,0),MATCH(J$9,$C$9:$X$9,0))) -> 1.3 | K21: 0 | L21: 0 | M21: =2*(-1*INDEX('Desconto Processos'!$B$5:$H$32,MATCH(180-$A21,'Desconto Processos'!$A$5:$A$32,0),MATCH(M$9,'Desconto Processos'!$B$3:$H$3,0))+INDEX('Acrescimo Tangente'!$B$4:$W$31,MATCH($A21,$A$10:$A$37,0),MATCH(M$9,$C$9:$X$9,0))) -> 1.3 | N21: 0 | O21: 0 | P21: 0 | Q21: 0 | R21: 0 | S21: 0 | T21: =2*(-1*INDEX('Desconto Processos'!$B$5:$H$32,MATCH(180-$A21,'Desconto Processos'!$A$5:$A$32,0),MATCH(T$9,'Desconto Processos'!$B$3:$H$3,0))+INDEX('Acrescimo Tangente'!$B$4:$W$31,MATCH($A21,$A$10:$A$37,0),MATCH(T$9,$C$9:$X$9,0))) -> 1.5 | U21: 0 | V21: 0 | W21: =2*(-1*INDEX('Desconto Processos'!$B$5:$H$32,MATCH(180-$A21,'Desconto Processos'!$A$5:$A$32,0),MATCH(W$9,'Desconto Processos'!$B$3:$H$3,0))+INDEX('Acrescimo Tangente'!$B$4:$W$31,MATCH($A21,$A$10:$A$37,0),MATCH(W$9,$C$9:$X$9,0))) -> 1.6 | X21: =2*(-1*INDEX('Desconto Processos'!$B$5:$H$32,MATCH(180-$A21,'Desconto Processos'!$A$5:$A$32,0),MATCH(X$9,'Desconto Processos'!$B$3:$H$3,0))+INDEX('Acrescimo Tangente'!$B$4:$W$31,MATCH($A21,$A$10:$A$37,0),MATCH(X$9,$C$9:$X$9,0))) -> 1.8
... A37: 150 | B37: 1 | C37: 0 | D37: =2*(-1*INDEX('Desconto Processos'!$B$5:$H$32,MATCH(180-$A37,'Desconto Processos'!$A$5:$A$32,0),MATCH(D$9,'Desconto Processos'!$B$3:$H$3,0))+INDEX('Acrescimo Tangente'!$B$4:$W$31,MATCH($A37,$A$10:$A$37,0),MATCH(D$9,$C$9:$X$9,0))) -> 11.974613 | E37: 0 | F37: 0 | G37: =2*(-1*INDEX('Desconto Processos'!$B$5:$H$32,MATCH(180-$A37,'Desconto Processos'!$A$5:$A$32,0),MATCH(G$9,'Desconto Processos'!$B$3:$H$3,0))+INDEX('Acrescimo Tangente'!$B$4:$W$31,MATCH($A37,$A$10:$A$37,0),MATCH(G$9,$C$9:$X$9,0))) -> 13.313844 | H37: 0 | I37: 0 | J37: =2*(-1*INDEX('Desconto Processos'!$B$5:$H$32,MATCH(180-$A37,'Desconto Processos'!$A$5:$A$32,0),MATCH(J$9,'Desconto Processos'!$B$3:$H$3,0))+INDEX('Acrescimo Tangente'!$B$4:$W$31,MATCH($A37,$A$10:$A$37,0),MATCH(J$9,$C$9:$X$9,0))) -> 16.045895 | K37: 0 | L37: 0 | M37: =2*(-1*INDEX('Desconto Processos'!$B$5:$H$32,MATCH(180-$A37,'Desconto Processos'!$A$5:$A$32,0),MATCH(M$9,'Desconto Processos'!$B$3:$H$3,0))+INDEX('Acrescimo Tangente'!$B$4:$W$31,MATCH($A37,$A$10:$A$37,0),MATCH(M$9,$C$9:$X$9,0))) -> 19.324356 | N37: 0 | O37: 0 | P37: 0 | Q37: 0 | R37: 0 | S37: 0 | T37: =2*(-1*INDEX('Desconto Processos'!$B$5:$H$32,MATCH(180-$A37,'Desconto Processos'!$A$5:$A$32,0),MATCH(T$9,'Desconto Processos'!$B$3:$H$3,0))+INDEX('Acrescimo Tangente'!$B$4:$W$31,MATCH($A37,$A$10:$A$37,0),MATCH(T$9,$C$9:$X$9,0))) -> 25.881278 | U37: 0 | V37: 0 | W37: =2*(-1*INDEX('Desconto Processos'!$B$5:$H$32,MATCH(180-$A37,'Desconto Processos'!$A$5:$A$32,0),MATCH(W$9,'Desconto Processos'!$B$3:$H$3,0))+INDEX('Acrescimo Tangente'!$B$4:$W$31,MATCH($A37,$A$10:$A$37,0),MATCH(W$9,$C$9:$X$9,0))) -> 30.752559 | X37: =2*(-1*INDEX('Desconto Processos'!$B$5:$H$32,MATCH(180-$A37,'Desconto Processos'!$A$5:$A$32,0),MATCH(X$9,'Desconto Processos'!$B$3:$H$3,0))+INDEX('Acrescimo Tangente'!$B$4:$W$31,MATCH($A37,$A$10:$A$37,0),MATCH(X$9,$C$9:$X$9,0))) -> 36.11666
A39: Thickness: | B39: 1.2
A40: Angle | B40: Radius
B41: 0.5 | C41: 1 | D41: 1.1 | E41: 1.2 | F41: 1.3 | G41: 1.4 | H41: 1.6 | I41: 1.7 | J41: 1.9 | K41: 2 | L41: 2.3 | M41: 2.5 | N41: 2.6 | O41: 2.7 | P41: 3 | Q41: 3.2 | R41: 3.3 | S41: 3.4 | T41: 3.7 | U41: 3.9 | V41: 4.3 | W41: 4.5 | X41: 5.5
A42: 15 | B42: 0 | C42: =2*(-1*INDEX('Desconto Processos'!$I$5:$M$32,MATCH(180-$A42,'Desconto Processos'!$A$5:$A$32,0),MATCH(C$41,'Desconto Processos'!$I$3:$M$3,0))+INDEX('Acrescimo Tangente'!$B$36:$W$63,MATCH($A42,$A$10:$A$37,0),MATCH(C$9,$C$9:$X$9,0))) -> 0.2 | D42: 0 | E42: 0 | F42: =2*(-1*INDEX('Desconto Processos'!$I$5:$M$32,MATCH(180-$A42,'Desconto Processos'!$A$5:$A$32,0),MATCH(F$41,'Desconto Processos'!$I$3:$M$3,0))+INDEX('Acrescimo Tangente'!$B$36:$W$63,MATCH($A42,$A$42:$A$69,0),MATCH(F$41,$C$9:$X$9,0))) -> 0.2 | G42: 0 | H42: =2*(-1*INDEX('Desconto Processos'!$I$5:$M$32,MATCH(180-$A42,'Desconto Processos'!$A$5:$A$32,0),MATCH(H$41,'Desconto Processos'!$I$3:$M$3,0))+INDEX('Acrescimo Tangente'!$B$36:$W$63,MATCH($A42,$A$42:$A$69,0),MATCH(H$41,$C$9:$X$9,0))) -> 0.2 | I42: 0 | J42: 0 | K42: =2*(-1*INDEX('Desconto Processos'!$I$5:$M$32,MATCH(180-$A42,'Desconto Processos'!$A$5:$A$32,0),MATCH(K$41,'Desconto Processos'!$I$3:$M$3,0))+INDEX('Acrescimo Tangente'!$B$36:$W$63,MATCH($A42,$A$42:$A$69,0),MATCH(K$41,$C$9:$X$9,0))) -> 0.2 | L42: 0 | M42: 0 | N42: =2*(-1*INDEX('Desconto Processos'!$I$5:$M$32,MATCH(180-$A42,'Desconto Processos'!$A$5:$A$32,0),MATCH(N$41,'Desconto Processos'!$I$3:$M$3,0))+INDEX('Acrescimo Tangente'!$B$36:$W$63,MATCH($A42,$A$42:$A$69,0),MATCH(N$41,$C$9:$X$9,0))) -> 0.2 | O42: 0 | P42: 0 | Q42: 0 | R42: 0 | S42: 0 | T42: 0 | U42: 0 | V42: 0 | W42: 0 | X42: 0
A43: 20 | B43: 0 | C43: 0 | D43: 0 | E43: 0 | F43: 0 | G43: 0 | H43: 0 | I43: 0 | J43: 0 | K43: 0 | L43: 0 | M43: 0 | N43: 0 | O43: 0 | P43: 0 | Q43: 0 | R43: 0 | S43: 0 | T43: 0 | U43: 0 | V43: 0 | W43: 0 | X43: 0
A44: 25 | B44: 0 | C44: 0 | D44: 0 | E44: 0 | F44: 0 | G44: 0 | H44: 0 | I44: 0 | J44: 0 | K44: 0 | L44: 0 | M44: 0 | N44: 0 | O44: 0 | P44: 0 | Q44: 0 | R44: 0 | S44: 0 | T44: 0 | U44: 0 | V44: 0 | W44: 0 | X44: 0
A45: 30 | B45: 0 | C45: =2*(-1*INDEX('Desconto Processos'!$I$5:$M$32,MATCH(180-$A45,'Desconto Processos'!$A$5:$A$32,0),MATCH(C$41,'Desconto Processos'!$I$3:$M$3,0))+INDEX('Acrescimo Tangente'!$B$36:$W$63,MATCH($A45,$A$10:$A$37,0),MATCH(C$9,$C$9:$X$9,0))) -> 0.5 | D45: 0 | E45: 0 | F45: =2*(-1*INDEX('Desconto Processos'!$I$5:$M$32,MATCH(180-$A45,'Desconto Processos'!$A$5:$A$32,0),MATCH(F$41,'Desconto Processos'!$I$3:$M$3,0))+INDEX('Acrescimo Tangente'!$B$36:$W$63,MATCH($A45,$A$42:$A$69,0),MATCH(F$41,$C$9:$X$9,0))) -> 0.5 | G45: 0 | H45: =2*(-1*INDEX('Desconto Processos'!$I$5:$M$32,MATCH(180-$A45,'Desconto Processos'!$A$5:$A$32,0),MATCH(H$41,'Desconto Processos'!$I$3:$M$3,0))+INDEX('Acrescimo Tangente'!$B$36:$W$63,MATCH($A45,$A$42:$A$69,0),MATCH(H$41,$C$9:$X$9,0))) -> 0.4 | I45: 0 | J45: 0 | K45: =2*(-1*INDEX('Desconto Processos'!$I$5:$M$32,MATCH(180-$A45,'Desconto Processos'!$A$5:$A$32,0),MATCH(K$41,'Desconto Processos'!$I$3:$M$3,0))+INDEX('Acrescimo Tangente'!$B$36:$W$63,MATCH($A45,$A$42:$A$69,0),MATCH(K$41,$C$9:$X$9,0))) -> 0.4 | L45: 0 | M45: 0 | N45: =2*(-1*INDEX('Desconto Processos'!$I$5:$M$32,MATCH(180-$A45,'Desconto Processos'!$A$5:$A$32,0),MATCH(N$41,'Desconto Processos'!$I$3:$M$3,0))+INDEX('Acrescimo Tangente'!$B$36:$W$63,MATCH($A45,$A$42:$A$69,0),MATCH(N$41,$C$9:$X$9,0))) -> 0.4 | O45: 0 | P45: 0 | Q45: 0 | R45: 0 | S45: 0 | T45: 0 | U45: 0 | V45: 0 | W45: 0 | X45: 0
A46: 35 | B46: 0 | C46: 0 | D46: 0 | E46: 0 | F46: 0 | G46: 0 | H46: 0 | I46: 0 | J46: 0 | K46: 0 | L46: 0 | M46: 0 | N46: 0 | O46: 0 | P46: 0 | Q46: 0 | R46: 0 | S46: 0 | T46: 0 | U46: 0 | V46: 0 | W46: 0 | X46: 0
A47: 40 | B47: 0 | C47: 0 | D47: 0 | E47: 0 | F47: 0 | G47: 0 | H47: 0 | I47: 0 | J47: 0 | K47: 0 | L47: 0 | M47: 0 | N47: 0 | O47: 0 | P47: 0 | Q47: 0 | R47: 0 | S47: 0 | T47: 0 | U47: 0 | V47: 0 | W47: 0 | X47: 0
A48: 45 | B48: 0 | C48: =2*(-1*INDEX('Desconto Processos'!$I$5:$M$32,MATCH(180-$A48,'Desconto Processos'!$A$5:$A$32,0),MATCH(C$41,'Desconto Processos'!$I$3:$M$3,0))+INDEX('Acrescimo Tangente'!$B$36:$W$63,MATCH($A48,$A$10:$A$37,0),MATCH(C$9,$C$9:$X$9,0))) -> 0.8 | D48: 0 | E48: 0 | F48: =2*(-1*INDEX('Desconto Processos'!$I$5:$M$32,MATCH(180-$A48,'Desconto Processos'!$A$5:$A$32,0),MATCH(F$41,'Desconto Processos'!$I$3:$M$3,0))+INDEX('Acrescimo Tangente'!$B$36:$W$63,MATCH($A48,$A$42:$A$69,0),MATCH(F$41,$C$9:$X$9,0))) -> 0.7 | G48: 0 | H48: =2*(-1*INDEX('Desconto Processos'!$I$5:$M$32,MATCH(180-$A48,'Desconto Processos'!$A$5:$A$32,0),MATCH(H$41,'Desconto Processos'!$I$3:$M$3,0))+INDEX('Acrescimo Tangente'!$B$36:$W$63,MATCH($A48,$A$42:$A$69,0),MATCH(H$41,$C$9:$X$9,0))) -> 0.7 | I48: 0 | J48: 0 | K48: =2*(-1*INDEX('Desconto Processos'!$I$5:$M$32,MATCH(180-$A48,'Desconto Processos'!$A$5:$A$32,0),MATCH(K$41,'Desconto Processos'!$I$3:$M$3,0))+INDEX('Acrescimo Tangente'!$B$36:$W$63,MATCH($A48,$A$42:$A$69,0),MATCH(K$41,$C$9:$X$9,0))) -> 0.7 | L48: 0 | M48: 0 | N48: =2*(-1*INDEX('Desconto Processos'!$I$5:$M$32,MATCH(180-$A48,'Desconto Processos'!$A$5:$A$32,0),MATCH(N$41,'Desconto Processos'!$I$3:$M$3,0))+INDEX('Acrescimo Tangente'!$B$36:$W$63,MATCH($A48,$A$42:$A$69,0),MATCH(N$41,$C$9:$X$9,0))) -> 0.7 | O48: 0 | P48: 0 | Q48: 0 | R48: 0 | S48: 0 | T48: 0 | U48: 0 | V48: 0 | W48: 0 | X48: 0
A49: 50 | B49: 0 | C49: 0 | D49: 0 | E49: 0 | F49: 0 | G49: 0 | H49: 0 | I49: 0 | J49: 0 | K49: 0 | L49: 0 | M49: 0 | N49: 0 | O49: 0 | P49: 0 | Q49: 0 | R49: 0 | S49: 0 | T49: 0 | U49: 0 | V49: 0 | W49: 0 | X49: 0
A50: 55 | B50: 0 | C50: 0 | D50: 0 | E50: 0 | F50: 0 | G50: 0 | H50: 0 | I50: 0 | J50: 0 | K50: 0 | L50: 0 | M50: 0 | N50: 0 | O50: 0 | P50: 0 | Q50: 0 | R50: 0 | S50: 0 | T50: 0 | U50: 0 | V50: 0 | W50: 0 | X50: 0
A51: 60 | B51: 0 | C51: =2*(-1*INDEX('Desconto Processos'!$I$5:$M$32,MATCH(180-$A51,'Desconto Processos'!$A$5:$A$32,0),MATCH(C$41,'Desconto Processos'!$I$3:$M$3,0))+INDEX('Acrescimo Tangente'!$B$36:$W$63,MATCH($A51,$A$10:$A$37,0),MATCH(C$9,$C$9:$X$9,0))) -> 1.1 | D51: 0 | E51: 0 | F51: =2*(-1*INDEX('Desconto Processos'!$I$5:$M$32,MATCH(180-$A51,'Desconto Processos'!$A$5:$A$32,0),MATCH(F$41,'Desconto Processos'!$I$3:$M$3,0))+INDEX('Acrescimo Tangente'!$B$36:$W$63,MATCH($A51,$A$42:$A$69,0),MATCH(F$41,$C$9:$X$9,0))) -> 1.1 | G51: 0 | H51: =2*(-1*INDEX('Desconto Processos'!$I$5:$M$32,MATCH(180-$A51,'Desconto Processos'!$A$5:$A$32,0),MATCH(H$41,'Desconto Processos'!$I$3:$M$3,0))+INDEX('Acrescimo Tangente'!$B$36:$W$63,MATCH($A51,$A$42:$A$69,0),MATCH(H$41,$C$9:$X$9,0))) -> 1.1 | I51: 0 | J51: 0 | K51: =2*(-1*INDEX('Desconto Processos'!$I$5:$M$32,MATCH(180-$A51,'Desconto Processos'!$A$5:$A$32,0),MATCH(K$41,'Desconto Processos'!$I$3:$M$3,0))+INDEX('Acrescimo Tangente'!$B$36:$W$63,MATCH($A51,$A$42:$A$69,0),MATCH(K$41,$C$9:$X$9,0))) -> 1.1 | L51: 0 | M51: 0 | N51: =2*(-1*INDEX('Desconto Processos'!$I$5:$M$32,MATCH(180-$A51,'Desconto Processos'!$A$5:$A$32,0),MATCH(N$41,'Desconto Processos'!$I$3:$M$3,0))+INDEX('Acrescimo Tangente'!$B$36:$W$63,MATCH($A51,$A$42:$A$69,0),MATCH(N$41,$C$9:$X$9,0))) -> 1.2 | O51: 0 | P51: 0 | Q51: 0 | R51: 0 | S51: 0 | T51: 0 | U51: 0 | V51: 0 | W51: 0 | X51: 0
A52: 65 | B52: 0 | C52: 0 | D52: 0 | E52: 0 | F52: 0 | G52: 0 | H52: 0 | I52: 0 | J52: 0 | K52: 0 | L52: 0 | M52: 0 | N52: 0 | O52: 0 | P52: 0 | Q52: 0 | R52: 0 | S52: 0 | T52: 0 | U52: 0 | V52: 0 | W52: 0 | X52: 0
A53: 70 | B53: 0 | C53: 0 | D53: 0 | E53: 0 | F53: 0 | G53: 0 | H53: 0 | I53: 0 | J53: 0 | K53: 0 | L53: 0 | M53: 0 | N53: 0 | O53: 0 | P53: 0 | Q53: 0 | R53: 0 | S53: 0 | T53: 0 | U53: 0 | V53: 0 | W53: 0 | X53: 0
A54: 75 | B54: 0 | C54: =2*(-1*INDEX('Desconto Processos'!$I$5:$M$32,MATCH(180-$A54,'Desconto Processos'!$A$5:$A$32,0),MATCH(C$41,'Desconto Processos'!$I$3:$M$3,0))+INDEX('Acrescimo Tangente'!$B$36:$W$63,MATCH($A54,$A$10:$A$37,0),MATCH(C$9,$C$9:$X$9,0))) -> 1.6 | D54: 0 | E54: 0 | F54: =2*(-1*INDEX('Desconto Processos'!$I$5:$M$32,MATCH(180-$A54,'Desconto Processos'!$A$5:$A$32,0),MATCH(F$41,'Desconto Processos'!$I$3:$M$3,0))+INDEX('Acrescimo Tangente'!$B$36:$W$63,MATCH($A54,$A$42:$A$69,0),MATCH(F$41,$C$9:$X$9,0))) -> 1.6 | G54: 0 | H54: =2*(-1*INDEX('Desconto Processos'!$I$5:$M$32,MATCH(180-$A54,'Desconto Processos'!$A$5:$A$32,0),MATCH(H$41,'Desconto Processos'!$I$3:$M$3,0))+INDEX('Acrescimo Tangente'!$B$36:$W$63,MATCH($A54,$A$42:$A$69,0),MATCH(H$41,$C$9:$X$9,0))) -> 1.6 | I54: 0 | J54: 0 | K54: =2*(-1*INDEX('Desconto Processos'!$I$5:$M$32,MATCH(180-$A54,'Desconto Processos'!$A$5:$A$32,0),MATCH(K$41,'Desconto Processos'!$I$3:$M$3,0))+INDEX('Acrescimo Tangente'!$B$36:$W$63,MATCH($A54,$A$42:$A$69,0),MATCH(K$41,$C$9:$X$9,0))) -> 1.7 | L54: 0 | M54: 0 | N54: =2*(-1*INDEX('Desconto Processos'!$I$5:$M$32,MATCH(180-$A54,'Desconto Processos'!$A$5:$A$32,0),MATCH(N$41,'Desconto Processos'!$I$3:$M$3,0))+INDEX('Acrescimo Tangente'!$B$36:$W$63,MATCH($A54,$A$42:$A$69,0),MATCH(N$41,$C$9:$X$9,0))) -> 1.8 | O54: 0 | P54: 0 | Q54: 0 | R54: 0 | S54: 0 | T54: 0 | U54: 0 | V54: 0 | W54: 0 | X54: 0
A55: 80 | B55: 0 | C55: 0 | D55: 0 | E55: 0 | F55: 0 | G55: 0 | H55: 0 | I55: 0 | J55: 0 | K55: 0 | L55: 0 | M55: 0 | N55: 0 | O55: 0 | P55: 0 | Q55: 0 | R55: 0 | S55: 0 | T55: 0 | U55: 0 | V55: 0 | W55: 0 | X55: 0
A56: 85 | B56: 0 | C56: 0 | D56: 0 | E56: 0 | F56: 0 | G56: 0 | H56: 0 | I56: 0 | J56: 0 | K56: 0 | L56: 0 | M56: 0 | N56: 0 | O56: 0 | P56: 0 | Q56: 0 | R56: 0 | S56: 0 | T56: 0 | U56: 0 | V56: 0 | W56: 0 | X56: 0
A57: 90 | B57: 0 | C57: =2*(-1*INDEX('Desconto Processos'!$I$5:$M$32,MATCH(180-$A57,'Desconto Processos'!$A$5:$A$32,0),MATCH(C$41,'Desconto Processos'!$I$3:$M$3,0))+INDEX('Acrescimo Tangente'!$B$36:$W$63,MATCH($A57,$A$10:$A$37,0),MATCH(C$9,$C$9:$X$9,0))) -> 2.3 | D57: 0 | E57: 0 | F57: =2*(-1*INDEX('Desconto Processos'!$I$5:$M$32,MATCH(180-$A57,'Desconto Processos'!$A$5:$A$32,0),MATCH(F$41,'Desconto Processos'!$I$3:$M$3,0))+INDEX('Acrescimo Tangente'!$B$36:$W$63,MATCH($A57,$A$42:$A$69,0),MATCH(F$41,$C$9:$X$9,0))) -> 2.3 | G57: 0 | H57: =2*(-1*INDEX('Desconto Processos'!$I$5:$M$32,MATCH(180-$A57,'Desconto Processos'!$A$5:$A$32,0),MATCH(H$41,'Desconto Processos'!$I$3:$M$3,0))+INDEX('Acrescimo Tangente'!$B$36:$W$63,MATCH($A57,$A$42:$A$69,0),MATCH(H$41,$C$9:$X$9,0))) -> 2.4 | I57: 0 | J57: 0 | K57: =2*(-1*INDEX('Desconto Processos'!$I$5:$M$32,MATCH(180-$A57,'Desconto Processos'!$A$5:$A$32,0),MATCH(K$41,'Desconto Processos'!$I$3:$M$3,0))+INDEX('Acrescimo Tangente'!$B$36:$W$63,MATCH($A57,$A$42:$A$69,0),MATCH(K$41,$C$9:$X$9,0))) -> 2.5 | L57: 0 | M57: 0 | N57: =2*(-1*INDEX('Desconto Processos'!$I$5:$M$32,MATCH(180-$A57,'Desconto Processos'!$A$5:$A$32,0),MATCH(N$41,'Desconto Processos'!$I$3:$M$3,0))+INDEX('Acrescimo Tangente'!$B$36:$W$63,MATCH($A57,$A$42:$A$69,0),MATCH(N$41,$C$9:$X$9,0))) -> 2.7 | O57: 0 | P57: 0 | Q57: 0 | R57: 0 | S57: 0 | T57: 0 | U57: 0 | V57: 0 | W57: 0 | X57: 0
A58: 95 | B58: 0 | C58: 0 | D58: 0 | E58: 0 | F58: 0 | G58: 0 | H58: 0 | I58: 0 | J58: 0 | K58: 0 | L58: 0 | M58: 0 | N58: 0 | O58: 0 | P58: 0 | Q58: 0 | R58: 0 | S58: 0 | T58: 0 | U58: 0 | V58: 0 | W58: 0 | X58: 0
A59: 100 | B59: 0 | C59: 0 | D59: 0 | E59: 0 | F59: 0 | G59: 0 | H59: 0 | I59: 0 | J59: 0 | K59: 0 | L59: 0 | M59: 0 | N59: 0 | O59: 0 | P59: 0 | Q59: 0 | R59: 0 | S59: 0 | T59: 0 | U59: 0 | V59: 0 | W59: 0 | X59: 0
...

Sheet Desconto Processos
A1: ESPESSURA ( S ) | B1: 0,95 mm | I1: 1.2 mm | N1: 1.5 mm | T1: 1.9 mm | Z1: 2.66 mm | AD1: 3,04 mm
A2: MATRIZ ( V ) | B2: 6 | C2: 8 | D2: 10 | E2: 12 | F2: 16 | G2: 20 | H2: 24 | I2: 6 | J2: 8 | K2: 10 | L2: 12 | M2: 16 | N2: 8 | O2: 10 | P2: 12 | Q2: 16 | R2: 20 | S2: 24 | T2: 8 | U2: 10 | V2: 12 | W2: 16 | X2: 20 | Y2: 24 | Z2: 12 | AA2: 16 | AB2: 20 | AC2: 24 | AD2: 16 | AE2: 20 | AF2: 24
A3: RAIO ( R ) | B3: 1.1 | C3: 1.4 | D3: 1.9 | E3: 2.5 | F3: 3.7 | G3: 4.5 | H3: 5.5 | I3: 1 | J3: 1.3 | K3: 1.6 | L3: 2 | M3: 2.6 | N3: 1.4 | O3: 1.6 | P3: 1.9 | Q3: 3 | R3: 3.9 | S3: 4.3 | T3: 1.2 | U3: 1.3 | V3: 1.7 | W3: 1.9 | X3: 2.6 | Y3: 3.4 | Z3: 1.9 | AA3: 2.3 | AB3: 2.7 | AC3: 3.2 | AD3: 2 | AE3: 2.6 | AF3: 3.3
A4: ÂNGULO ( b) | B4: ENCURTAMENTO ( ∆L )
A5: 30 | B5: -0.25 | C5: -0.1 | D5: -0.1 | E5: -0.1 | F5: -0.1 | G5: -0.35 | H5: -0.3 | I5: -0.4 | J5: -0.3 | K5: -0.15 | L5: -0.1 | M5: -0.25 | N5: -0.45 | O5: -0.35 | P5: -0.25 | Q5: -0.2 | R5: -0.35 | S5: -0.4 | T5: -0.7 | U5: -0.75 | V5: -0.65 | W5: -0.6 | X5: -0.35 | Y5: -0.4 | Z5: -0.9 | AA5: -0.75 | AB5: -0.6 | AC5: -0.4
A6: 35 | B6: -0.3 | C6: -0.15 | D6: -0.1 | E6: -0.1 | F6: -0.2 | G6: -0.35 | H6: -0.3 | N6: -0.5 | O6: -0.45 | P6: -0.35 | Q6: -0.2 | R6: -0.4 | S6: -0.4 | T6: -0.8 | U6: -0.85 | V6: -0.75 | W6: -0.7 | X6: -0.45 | Y6: -0.5 | Z6: -1 | AA6: -0.9 | AB6: -0.75 | AC6: -0.55
A7: 40 | B7: -0.35 | C7: -0.25 | D7: -0.1 | E7: -0.1 | F7: -0.3 | G7: -0.35 | H7: -0.35 | N7: -0.6 | O7: -0.55 | P7: -0.45 | Q7: -0.25 | R7: -0.45 | S7: -0.45 | T7: -0.9 | U7: -1 | V7: -0.85 | W7: -0.8 | X7: -0.6 | Y7: -0.65 | Z7: -1.1 | AA7: -1 | AB7: -0.9 | AC7: -0.7 | AD7: -0.7 | AE7: -0.7 | AF7: -0.65
A8: 45 | B8: -0.4 | C8: -0.3 | D8: -0.2 | E8: -0.2 | F8: -0.35 | G8: -0.4 | H8: -0.35 | I8: -0.6 | J8: -0.5 | K8: -0.4 | L8: -0.3 | M8: -0.15 | N8: -0.7 | O8: -0.6 | P8: -0.55 | Q8: -0.3 | R8: -0.5 | S8: -0.5 | T8: -0.95 | U8: -1.1 | V8: -0.95 | W8: -0.9 | X8: -0.75 | Y8: -0.75 | Z8: -1.25 | AA8: -1.15 | AB8: -1.05 | AC8: -0.9 | AD8: -0.85 | AE8: -0.85 | AF8: -0.8
A9: 50 | B9: -0.5 | C9: -0.4 | D9: -0.3 | E9: -0.2 | F9: -0.4 | G9: -0.4 | H9: -0.4 | N9: -0.75 | O9: -0.7 | P9: -0.65 | Q9: -0.45 | R9: -0.55 | S9: -0.5 | T9: -1 | U9: -1.2 | V9: -1.05 | W9: -1 | X9: -0.9 | Y9: -0.8 | Z9: -1.4 | AA9: -1.3 | AB9: -1.2 | AC9: -1.1 | AD9: -1.3 | AE9: -1.1 | AF9: -1
A10: 55 | B10: -0.55 | C10: -0.5 | D10: -0.4 | E10: -0.3 | F10: -0.5 | G10: -0.45 | H10: -0.4 | N10: -0.85 | O10: -0.8 | P10: -0.75 | Q10: -0.6 | R10: -0.6 | S10: -0.6 | T10: -1.1 | U10: -1.3 | V10: -1.15 | W10: -1.15 | X10: -1.05 | Y10: -0.95 | Z10: -1.5 | AA10: -1.4 | AB10: -1.35 | AC10: -1.25 | AD10: -1.45 | AE10: -1.3 | AF10: -1.2
A11: 60 | B11: -0.6 | C11: -0.55 | D11: -0.5 | E11: -0.45 | F11: -0.55 | G11: -0.45 | H11: -0.45 | I11: -0.75 | J11: -0.7 | K11: -0.7 | L11: -0.65 | M11: -0.55 | N11: -0.95 | O11: -0.9 | P11: -0.85 | Q11: -0.75 | R11: -0.65 | S11: -0.7 | T11: -1.2 | U11: -1.35 | V11: -1.3 | W11: -1.25 | X11: -1.1 | Y11: -1.1 | Z11: -1.6 | AA11: -1.55 | AB11: -1.5 | AC11: -1.45 | AD11: -1.6 | AE11: -1.5 | AF11: -1.4
A12: 65 | B12: -0.65 | C12: -0.6 | D12: -0.6 | E12: -0.55 | F12: -0.6 | G12: -0.5 | H12: -0.5 | N12: -1 | O12: -1 | P12: -0.95 | Q12: -0.9 | R12: -0.85 | S12: -0.85 | T12: -1.3 | U12: -1.4 | V12: -1.4 | W12: -1.35 | X12: -1.25 | Y12: -1.35 | Z12: -1.7 | AA12: -1.6 | AB12: -1.65 | AC12: -1.6 | AD12: -1.75 | AE12: -1.6 | AF12: -1.6
A13: 70 | B13: -0.7 | C13: -0.7 | D13: -0.7 | E13: -0.7 | F13: -0.7 | G13: -0.7 | H13: -0.75 | N13: -1.1 | O13: -1.1 | P13: -1.1 | Q13: -1.05 | R13: -1.05 | S13: -1.05 | T13: -1.4 | U13: -1.5 | V13: -1.5 | W13: -1.45 | X13: -1.5 | Y13: -1.6 | Z13: -1.85 | AA13: -1.85 | AB13: -1.8 | AC13: -1.75 | AD13: -1.85 | AE13: -1.75 | AF13: -1.8
A14: 75 | B14: -0.8 | C14: -0.8 | D14: -0.8 | E14: -0.8 | F14: -0.9 | G14: -0.95 | H14: -1 | I14: -0.95 | J14: -0.95 | K14: -0.95 | L14: -0.95 | M14: -0.95 | N14: -1.2 | O14: -1.2 | P14: -1.2 | Q14: -1.2 | R14: -1.25 | S14: -1.3 | T14: -1.45 | U14: -1.55 | V14: -1.55 | W14: -1.6 | X14: -1.7 | Y14: -1.8 | Z14: -2 | AA14: -1.95 | AB14: -2 | AC14: -1.9 | AD14: -2 | AE14: -1.9 | AF14: -1.95
A15: 80 | B15: -0.85 | C15: -0.85 | D15: -0.9 | E15: -0.95 | F15: -1.05 | G15: -1.15 | H15: -1.25 | N15: -1.25 | O15: -1.3 | P15: -1.3 | Q15: -1.35 | R15: -1.45 | S15: -1.5 | T15: -1.5 | U15: -1.6 | V15: -1.6 | W15: -1.7 | X15: -1.8 | Y15: -2 | Z15: -2.1 | AA15: -2.1 | AB15: -2.2 | AC15: -2.15 | AD15: -2.15 | AE15: -2.15 | AF15: -2.3
A16: 85 | B16: -0.8 | C16: -0.95 | D16: -1 | E16: -1.1 | F16: -1.25 | G16: -1.35 | H16: -1.55 | N16: -1.35 | O16: -1.35 | P16: -1.4 | Q16: -1.5 | R16: -1.65 | S16: -1.7 | T16: -1.6 | U16: -1.65 | V16: -1.7 | W16: -1.8 | X16: -2 | Y16: -2.2 | Z16: -2.2 | AA16: -2.2 | AB16: -2.4 | AC16: -2.35 | AD16: -2.25 | AE16: -2.3 | AF16: -2.75
A17: 90 | B17: -0.9 | C17: -0.95 | D17: -1 | E17: -1.2 | F17: -1.4 | G17: -1.65 | H17: -1.9 | I17: -1.15 | J17: -1.15 | K17: -1.2 | L17: -1.25 | M17: -1.35 | N17: -1.4 | O17: -1.45 | P17: -1.5 | Q17: -1.7 | R17: -1.85 | S17: -1.9 | T17: -1.7 | U17: -1.75 | V17: -1.8 | W17: -1.95 | X17: -2.2 | Y17: -2.5 | Z17: -2.3 | AA17: -2.35 | AB17: -2.6 | AC17: -2.65 | AD17: -2.4 | AE17: -2.75 | AF17: -2.9
A18: 95 | B18: -0.85 | C18: -0.9 | D18: -0.95 | E18: -1.05 | F18: -1.2 | G18: -1.34 | H18: -1.5 | N18: -1.2 | O18: -1.3 | P18: -1.3 | Q18: -1.45 | R18: -1.6 | S18: -1.7 | T18: -1.55 | U18: -1.6 | V18: -1.65 | W18: -1.7 | X18: -2 | Y18: -2.25 | Z18: -2.15 | AA18: -2.1 | AB18: -2.15 | AC18: -2.3 | AD18: -2.05 | AE18: -2.1 | AF18: -2.6
A19: 100 | B19: -0.75 | C19: -0.8 | D19: -0.85 | E19: -0.9 | F19: -1.05 | G19: -1.15 | H19: -1.25 | N19: -1.1 | O19: -1.15 | P19: -1.2 | Q19: -1.25 | R19: -1.4 | S19: -1.6 | T19: -1.4 | U19: -1.45 | V19: -1.5 | W19: -1.5 | X19: -1.8 | Y19: -1.8 | Z19: -1.85 | AA19: -1.85 | AB19: -1.9 | AC19: -2 | AD19: -1.8 | AE19: -1.85 | AF19: -2.3
A20: 105 | B20: -0.6 | C20: -0.7 | D20: -0.8 | E20: -0.9 | F20: -1 | G20: -1.1 | H20: -1.2 | I20: -0.8 | J20: -0.8 | K20: -0.8 | L20: -0.85 | M20: -0.9 | N20: -1 | O20: -1 | P20: -1.1 | Q20: -1.2 | R20: -1.3 | S20: -1.5 | T20: -1.3 | U20: -1.25 | V20: -1.35 | W20: -1.3 | X20: -1.5 | Y20: -1.6 | Z20: -1.7 | AA20: -1.7 | AB20: -1.75 | AC20: -1.7 | AD20: -1.5 | AE20: -1.6 | AF20: -2
A21: 110 | B21: -0.6 | C21: -0.6 | D21: -0.65 | E21: -0.65 | F21: -0.75 | G21: -0.8 | H21: -0.9 | N21: -0.85 | O21: -0.9 | P21: -1 | Q21: -0.95 | R21: -1.1 | S21: -1.05 | T21: -1.2 | U21: -1.15 | V21: -1.2 | W21: -1.2 | X21: -1.25 | Y21: -1.45 | Z21: -1.5 | AA21: -1.5 | AB21: -1.55 | AC21: -1.5 | AD21: -1.3 | AE21: -1.35 | AF21: -1.8
A22: 115 | B22: -0.5 | C22: -0.55 | D22: -0.55 | E22: -0.6 | F22: -0.65 | G22: -0.7 | H22: -0.8 | N22: -0.75 | O22: -0.8 | P22: -0.9 | Q22: -0.85 | R22: -1 | S22: -0.95 | T22: -1 | U22: -1.05 | V22: -1.05 | W22: -1.1 | X22: -1.1 | Y22: -1.2 | Z22: -1.35 | AA22: -1.3 | AB22: -1.35 | AC22: -1.3 | AD22: -1.1 | AE22: -1.15 | AF22: -1.6
A23: 120 | B23: -0.4 | C23: -0.45 | D23: -0.5 | E23: -0.55 | F23: -0.6 | G23: -0.7 | H23: -0.75 | I23: -0.55 | J23: -0.55 | K23: -0.55 | L23: -0.55 | M23: -0.6 | N23: -0.7 | O23: -0.7 | P23: -0.8 | Q23: -0.8 | R23: -0.9 | S23: -0.8 | T23: -0.8 | U23: -0.9 | V23: -0.9 | W23: -0.95 | X23: -0.95 | Y23: -0.95 | Z23: -1.15 | AA23: -1.15 | AB23: -1.15 | AC23: -1.15 | AD23: -0.95 | AE23: -1 | AF23: -1.4
A24: 125 | B24: -0.4 | C24: -0.4 | D24: -0.4 | E24: -0.4 | F24: -0.45 | G24: -0.5 | H24: -0.6 | N24: -0.6 | O24: -0.6 | P24: -0.7 | Q24: -0.7 | R24: -0.75 | S24: -0.7 | T24: -0.7 | U24: -0.75 | V24: -0.8 | W24: -0.8 | X24: -0.9 | Y24: -0.9 | Z24: -1.05 | AA24: -1 | AB24: -1.05 | AC24: -1 | AD24: -0.75 | AE24: -0.8 | AF24: -1.2
A25: 130 | B25: -0.35 | C25: -0.35 | D25: -0.35 | E25: -0.35 | F25: -0.4 | G25: -0.4 | H25: -0.5 | N25: -0.5 | O25: -0.55 | P25: -0.6 | Q25: -0.55 | R25: -0.65 | S25: -0.6 | T25: -0.65 | U25: -0.65 | V25: -0.7 | W25: -0.7 | X25: -0.7 | Y25: -0.8 | Z25: -0.95 | AA25: -0.9 | AB25: -0.9 | AC25: -0.9 | AD25: -0.7 | AE25: -0.65 | AF25: -1.05
A26: 135 | B26: -0.3 | C26: -0.3 | D26: -0.3 | E26: -0.35 | F26: -0.35 | G26: -0.4 | H26: -0.45 | I26: -0.4 | J26: -0.35 | K26: -0.35 | L26: -0.35 | M26: -0.35 | N26: -0.45 | O26: -0.5 | P26: -0.5 | Q26: -0.45 | R26: -0.55 | S26: -0.5 | T26: -0.6 | U26: -0.55 | V26: -0.6 | W26: -0.6 | X26: -0.65 | Y26: -0.7 | Z26: -0.8 | AA26: -0.8 | AB26: -0.8 | AC26: -0.75 | AD26: -0.55 | AE26: -0.55 | AF26: -0.9
A27: 140 | B27: -0.25 | C27: -0.25 | D27: -0.25 | E27: -0.25 | F27: -0.3 | G27: -0.3 | H27: -0.35 | N27: -0.4 | O27: -0.4 | P27: -0.45 | Q27: -0.4 | R27: -0.45 | S27: -0.4 | T27: -0.5 | U27: -0.5 | V27: -0.55 | W27: -0.5 | X27: -0.5 | Y27: -0.6 | Z27: -0.7 | AA27: -0.65 | AB27: -0.65 | AC27: -0.65 | AD27: -0.4 | AE27: -0.4 | AF27: -0.8
A28: 145 | B28: -0.2 | C28: -0.2 | D28: -0.2 | E28: -0.2 | F28: -0.2 | G28: -0.25 | H28: -0.3 | N28: -0.35 | O28: -0.35 | P28: -0.35 | Q28: -0.35 | R28: -0.4 | S28: -0.3 | T28: -0.4 | U28: -0.4 | V28: -0.4 | W28: -0.4 | X28: -0.4 | Y28: -0.5 | Z28: -0.6 | AA28: -0.6 | AB28: -0.55 | AC28: -0.55 | AD28: -0.3 | AE28: -0.3 | AF28: -0.7
A29: 150 | B29: -0.15 | C29: -0.15 | D29: -0.15 | E29: -0.2 | F29: -0.2 | G29: -0.2 | H29: -0.25 | I29: -0.25 | J29: -0.25 | K29: -0.2 | L29: -0.2 | M29: -0.2 | N29: -0.3 | O29: -0.3 | P29: -0.3 | Q29: -0.3 | R29: -0.35 | S29: -0.35 | T29: -0.3 | U29: -0.3 | V29: -0.35 | W29: -0.35 | X29: -0.35 | Y29: -0.4 | Z29: -0.5 | AA29: -0.5 | AB29: -0.45 | AC29: -0.45 | AD29: -0.25 | AE29: -0.2 | AF29: -0.6
A30: 155 | B30: -0.15 | C30: -0.15 | D30: -0.15 | E30: -0.15 | F30: -0.15 | G30: -0.15 | H30: -0.15 | N30: -0.25 | O30: -0.25 | P30: -0.25 | Q30: -0.25 | R30: -0.25 | S30: -0.3 | T30: -0.3 | U30: -0.25 | V30: -0.25 | W30: -0.3 | X30: -0.3 | Y30: -0.35 | Z30: -0.4 | AA30: -0.4 | AB30: -0.35 | AC30: -0.35 | AD30: -0.15 | AE30: -0.15 | AF30: -0.45
A31: 160 | B31: -0.1 | C31: -0.1 | D31: -0.1 | E31: -0.1 | F31: -0.1 | G31: -0.1 | H31: -0.1 | N31: -0.2 | O31: -0.2 | P31: -0.2 | Q31: -0.2 | R31: -0.2 | S31: -0.2 | T31: -0.25 | U31: -0.2 | V31: -0.2 | W31: -0.25 | X31: -0.25 | Y31: -0.3 | Z31: -0.3 | AA31: -0.3 | AB31: -0.3 | AC31: -0.25 | AD31: -0.1 | AE31: -0.1 | AF31: -0.35
A32: 165 | B32: -0.1 | C32: -0.1 | D32: -0.1 | E32: -0.1 | F32: -0.1 | G32: -0.1 | H32: -0.1 | I32: -0.1 | J32: -0.1 | K32: -0.1 | L32: -0.1 | M32: -0.1 | N32: -0.15 | O32: -0.15 | P32: -0.15 | Q32: -0.15 | R32: -0.15 | S32: -0.15 | T32: -0.2 | U32: -0.15 | V32: -0.2 | W32: -0.2 | X32: -0.2 | Y32: -0.2 | Z32: -0.25 | AA32: -0.2 | AB32: -0.25 | AC32: -0.2 | AD32: -0.1 | AE32: -0.1 | AF32: -0.25

Sheet Acrescimo Tangente
A1: Thickness: | B1: 1
A2: Angle | B2: Radius
B3: 1 | C3: 1.1 | D3: 1.2 | E3: 1.3 | F3: 1.4 | G3: 1.6 | H3: 1.7 | I3: 1.9 | J3: 2 | K3: 2.3 | L3: 2.5 | M3: 2.6 | N3: 2.7 | O3: 3 | P3: 3.2 | Q3: 3.3 | R3: 3.4 | S3: 3.7 | T3: 3.9 | U3: 4.3 | V3: 4.5 | W3: 5.5
A4: 15 | B4: 0 | C4: 0 | D4: 0 | E4: 0 | F4: 0 | G4: 0 | H4: 0 | I4: 0 | J4: 0 | K4: 0 | L4: 0 | M4: 0 | N4: 0 | O4: 0 | P4: 0 | Q4: 0 | R4: 0 | S4: 0 | T4: 0 | U4: 0 | V4: 0 | W4: 0
A5: 20 | B5: 0 | C5: 0 | D5: 0 | E5: 0 | F5: 0 | G5: 0 | H5: 0 | I5: 0 | J5: 0 | K5: 0 | L5: 0 | M5: 0 | N5: 0 | O5: 0 | P5: 0 | Q5: 0 | R5: 0 | S5: 0 | T5: 0 | U5: 0 | V5: 0 | W5: 0
A6: 25 | B6: 0 | C6: 0 | D6: 0 | E6: 0 | F6: 0 | G6: 0 | H6: 0 | I6: 0 | J6: 0 | K6: 0 | L6: 0 | M6: 0 | N6: 0 | O6: 0 | P6: 0 | Q6: 0 | R6: 0 | S6: 0 | T6: 0 | U6: 0 | V6: 0 | W6: 0
A7: 30 | B7: 0 | C7: 0 | D7: 0 | E7: 0 | F7: 0 | G7: 0 | H7: 0 | I7: 0 | J7: 0 | K7: 0 | L7: 0 | M7: 0 | N7: 0 | O7: 0 | P7: 0 | Q7: 0 | R7: 0 | S7: 0 | T7: 0 | U7: 0 | V7: 0 | W7: 0
A8: 35 | B8: 0 | C8: 0 | D8: 0 | E8: 0 | F8: 0 | G8: 0 | H8: 0 | I8: 0 | J8: 0 | K8: 0 | L8: 0 | M8: 0 | N8: 0 | O8: 0 | P8: 0 | Q8: 0 | R8: 0 | S8: 0 | T8: 0 | U8: 0 | V8: 0 | W8: 0
A9: 40 | B9: 0 | C9: 0 | D9: 0 | E9: 0 | F9: 0 | G9: 0 | H9: 0 | I9: 0 | J9: 0 | K9: 0 | L9: 0 | M9: 0 | N9: 0 | O9: 0 | P9: 0 | Q9: 0 | R9: 0 | S9: 0 | T9: 0 | U9: 0 | V9: 0 | W9: 0
A10: 45 | B10: 0 | C10: 0 | D10: 0 | E10: 0 | F10: 0 | G10: 0 | H10: 0 | I10: 0 | J10: 0 | K10: 0 | L10: 0 | M10: 0 | N10: 0 | O10: 0 | P10: 0 | Q10: 0 | R10: 0 | S10: 0 | T10: 0 | U10: 0 | V10: 0 | W10: 0
A11: 50 | B11: 0 | C11: 0 | D11: 0 | E11: 0 | F11: 0 | G11: 0 | H11: 0 | I11: 0 | J11: 0 | K11: 0 | L11: 0 | M11: 0 | N11: 0 | O11: 0 | P11: 0 | Q11: 0 | R11: 0 | S11: 0 | T11: 0 | U11: 0 | V11: 0 | W11: 0
A12: 55 | B12: 0 | C12: 0 | D12: 0 | E12: 0 | F12: 0 | G12: 0 | H12: 0 | I12: 0 | J12: 0 | K12: 0 | L12: 0 | M12: 0 | N12: 0 | O12: 0 | P12: 0 | Q12: 0 | R12: 0 | S12: 0 | T12: 0 | U12: 0 | V12: 0 | W12: 0
A13: 60 | B13: 0 | C13: 0 | D13: 0 | E13: 0 | F13: 0 | G13: 0 | H13: 0 | I13: 0 | J13: 0 | K13: 0 | L13: 0 | M13: 0 | N13: 0 | O13: 0 | P13: 0 | Q13: 0 | R13: 0 | S13: 0 | T13: 0 | U13: 0 | V13: 0 | W13: 0
A14: 65 | B14: 0 | C14: 0 | D14: 0 | E14: 0 | F14: 0 | G14: 0 | H14: 0 | I14: 0 | J14: 0 | K14: 0 | L14: 0 | M14: 0 | N14: 0 | O14: 0 | P14: 0 | Q14: 0 | R14: 0 | S14: 0 | T14: 0 | U14: 0 | V14: 0 | W14: 0
A15: 70 | B15: 0 | C15: 0 | D15: 0 | E15: 0 | F15: 0 | G15: 0 | H15: 0 | I15: 0 | J15: 0 | K15: 0 | L15: 0 | M15: 0 | N15: 0 | O15: 0 | P15: 0 | Q15: 0 | R15: 0 | S15: 0 | T15: 0 | U15: 0 | V15: 0 | W15: 0
... A19: 90 | B19: 0 | C19: 0 | D19: 0 | E19: 0 | F19: 0 | G19: 0 | H19: 0 | I19: 0 | J19: 0 | K19: 0 | L19: 0 | M19: 0 | N19: 0 | O19: 0 | P19: 0 | Q19: 0 | R19: 0 | S19: 0 | T19: 0 | U19: 0 | V19: 0 | W19: 0
A20: 95 | B20: 0 | C20: =($B$1+C$3)*(1-TAN(RADIANS(180-$A20)/2))/TAN(RADIANS(180-$A20)/2) -> 0.19174785 | D20: 0 | E20: 0 | F20: =($B$1+F$3)*(1-TAN(RADIANS(180-$A20)/2))/TAN(RADIANS(180-$A20)/2) -> 0.2191404 | G20: 0 | H20: 0 | I20: =($B$1+I$3)*(1-TAN(RADIANS(180-$A20)/2))/TAN(RADIANS(180-$A20)/2) -> 0.26479465 | J20: 0 | K20: 0 | L20: =($B$1+L$3)*(1-TAN(RADIANS(180-$A20)/2))/TAN(RADIANS(180-$A20)/2) -> 0.31957975 | M20: 0 | N20: 0 | O20: 0 | P20: 0 | Q20: 0 | R20: 0 | S20: =($B$1+S$3)*(1-TAN(RADIANS(180-$A20)/2))/TAN(RADIANS(180-$A20)/2) -> 0.42914996 | T20: 0 | U20: 0 | V20: =($B$1+V$3)*(1-TAN(RADIANS(180-$A20)/2))/TAN(RADIANS(180-$A20)/2) -> 0.50219676 | W20: =($B$1+W$3)*(1-TAN(RADIANS(180-$A20)/2))/TAN(RADIANS(180-$A20)/2) -> 0.59350526
A21: 100 | B21: 0 | C21: =($B$1+C$3)*(1-TAN(RADIANS(180-$A21)/2))/TAN(RADIANS(180-$A21)/2) -> 0.40268254 | D21: 0 | E21: 0 | F21: =($B$1+F$3)*(1-TAN(RADIANS(180-$A21)/2))/TAN(RADIANS(180-$A21)/2) -> 0.46020862 | G21: 0 | H21: 0 | I21: =($B$1+I$3)*(1-TAN(RADIANS(180-$A21)/2))/TAN(RADIANS(180-$A21)/2) -> 0.55608542 | J21: 0 | K21: 0 | L21: =($B$1+L$3)*(1-TAN(RADIANS(180-$A21)/2))/TAN(RADIANS(180-$A21)/2) -> 0.67113757 | M21: 0 | N21: 0 | O21: 0 | P21: 0 | Q21: 0 | R21: 0 | S21: =($B$1+S$3)*(1-TAN(RADIANS(180-$A21)/2))/TAN(RADIANS(180-$A21)/2) -> 0.90124189 | T21: 0 | U21: 0 | V21: =($B$1+V$3)*(1-TAN(RADIANS(180-$A21)/2))/TAN(RADIANS(180-$A21)/2) -> 1.0546448 | W21: =($B$1+W$3)*(1-TAN(RADIANS(180-$A21)/2))/TAN(RADIANS(180-$A21)/2) -> 1.2463984
A22: 105 | B22: 0 | C22: =($B$1+C$3)*(1-TAN(RADIANS(180-$A22)/2))/TAN(RADIANS(180-$A22)/2) -> 0.63677328 | D22: 0 | E22: 0 | F22: =($B$1+F$3)*(1-TAN(RADIANS(180-$A22)/2))/TAN(RADIANS(180-$A22)/2) -> 0.72774089 | G22: 0 | H22: 0 | I22: =($B$1+I$3)*(1-TAN(RADIANS(180-$A22)/2))/TAN(RADIANS(180-$A22)/2) -> 0.87935358 | J22: 0 | K22: 0 | L22: =($B$1+L$3)*(1-TAN(RADIANS(180-$A22)/2))/TAN(RADIANS(180-$A22)/2) -> 1.0612888 | M22: 0 | N22: 0 | O22: 0 | P22: 0 | Q22: 0 | R22: 0 | S22: =($B$1+S$3)*(1-TAN(RADIANS(180-$A22)/2))/TAN(RADIANS(180-$A22)/2) -> 1.4251593 | T22: 0 | U22: 0 | V22: =($B$1+V$3)*(1-TAN(RADIANS(180-$A22)/2))/TAN(RADIANS(180-$A22)/2) -> 1.6677396 | W22: =($B$1+W$3)*(1-TAN(RADIANS(180-$A22)/2))/TAN(RADIANS(180-$A22)/2) -> 1.9709649
A23: 110 | B23: 0 | C23: =($B$1+C$3)*(1-TAN(RADIANS(180-$A23)/2))/TAN(RADIANS(180-$A23)/2) -> 0.89911081 | D23: 0 | E23: 0 | F23: =($B$1+F$3)*(1-TAN(RADIANS(180-$A23)/2))/TAN(RADIANS(180-$A23)/2) -> 1.0275552 | G23: 0 | H23: 0 | I23: =($B$1+I$3)*(1-TAN(RADIANS(180-$A23)/2))/TAN(RADIANS(180-$A23)/2) -> 1.2416292 | J23: 0 | K23: 0 | L23: =($B$1+L$3)*(1-TAN(RADIANS(180-$A23)/2))/TAN(RADIANS(180-$A23)/2) -> 1.498518 | M23: 0 | N23: 0 | O23: 0 | P23: 0 | Q23: 0 | R23: 0 | S23: =($B$1+S$3)*(1-TAN(RADIANS(180-$A23)/2))/TAN(RADIANS(180-$A23)/2) -> 2.0122956 | T23: 0 | U23: 0 | V23: =($B$1+V$3)*(1-TAN(RADIANS(180-$A23)/2))/TAN(RADIANS(180-$A23)/2) -> 2.354814 | W23: =($B$1+W$3)*(1-TAN(RADIANS(180-$A23)/2))/TAN(RADIANS(180-$A23)/2) -> 2.782962
A24: 115 | B24: 0 | C24: =($B$1+C$3)*(1-TAN(RADIANS(180-$A24)/2))/TAN(RADIANS(180-$A24)/2) -> 1.1963397 | D24: 0 | E24: 0 | F24: =($B$1+F$3)*(1-TAN(RADIANS(180-$A24)/2))/TAN(RADIANS(180-$A24)/2) -> 1.3672454 | G24: 0 | H24: 0 | I24: =($B$1+I$3)*(1-TAN(RADIANS(180-$A24)/2))/TAN(RADIANS(180-$A24)/2) -> 1.6520882 | J24: 0 | K24: 0 | L24: =($B$1+L$3)*(1-TAN(RADIANS(180-$A24)/2))/TAN(RADIANS(180-$A24)/2) -> 1.9938995 | M24: 0 | N24: 0 | O24: 0 | P24: 0 | Q24: 0 | R24: 0 | S24: =($B$1+S$3)*(1-TAN(RADIANS(180-$A24)/2))/TAN(RADIANS(180-$A24)/2) -> 2.6775222 | T24: 0 | U24: 0 | V24: =($B$1+V$3)*(1-TAN(RADIANS(180-$A24)/2))/TAN(RADIANS(180-$A24)/2) -> 3.1332707 | W24: =($B$1+W$3)*(1-TAN(RADIANS(180-$A24)/2))/TAN(RADIANS(180-$A24)/2) -> 3.7029563
A25: 120 | B25: 0 | C25: =($B$1+C$3)*(1-TAN(RADIANS(180-$A25)/2))/TAN(RADIANS(180-$A25)/2) -> 1.5373067 | D25: 0 | E25: 0 | F25: =($B$1+F$3)*(1-TAN(RADIANS(180-$A25)/2))/TAN(RADIANS(180-$A25)/2) -> 1.7569219 | G25: 0 | H25: 0 | I25: =($B$1+I$3)*(1-TAN(RADIANS(180-$A25)/2))/TAN(RADIANS(180-$A25)/2) -> 2.1229473 | J25: 0 | K25: 0 | L25: =($B$1+L$3)*(1-TAN(RADIANS(180-$A25)/2))/TAN(RADIANS(180-$A25)/2) -> 2.5621778 | M25: 0 | N25: 0 | O25: 0 | P25: 0 | Q25: 0 | R25: 0 | S25: =($B$1+S$3)*(1-TAN(RADIANS(180-$A25)/2))/TAN(RADIANS(180-$A25)/2) -> 3.4406388 | T25: 0 | U25: 0 | V25: =($B$1+V$3)*(1-TAN(RADIANS(180-$A25)/2))/TAN(RADIANS(180-$A25)/2) -> 4.0262794 | W25: =($B$1+W$3)*(1-TAN(RADIANS(180-$A25)/2))/TAN(RADIANS(180-$A25)/2) -> 4.7583302
A26: 125 | B26: 0 | C26: =($B$1+C$3)*(1-TAN(RADIANS(180-$A26)/2))/TAN(RADIANS(180-$A26)/2) -> 1.9340625 | D26: 0 | E26: 0 | F26: =($B$1+F$3)*(1-TAN(RADIANS(180-$A26)/2))/TAN(RADIANS(180-$A26)/2) -> 2.2103571 | G26: 0 | H26: 0 | I26: =($B$1+I$3)*(1-TAN(RADIANS(180-$A26)/2))/TAN(RADIANS(180-$A26)/2) -> 2.6708482 | J26: 0 | K26: 0 | L26: =($B$1+L$3)*(1-TAN(RADIANS(180-$A26)/2))/TAN(RADIANS(180-$A26)/2) -> 3.2234374 | M26: 0 | N26: 0 | O26: 0 | P26: 0 | Q26: 0 | R26: 0 | S26: =($B$1+S$3)*(1-TAN(RADIANS(180-$A26)/2))/TAN(RADIANS(180-$A26)/2) -> 4.328616 | T26: 0 | U26: 0 | V26: =($B$1+V$3)*(1-TAN(RADIANS(180-$A26)/2))/TAN(RADIANS(180-$A26)/2) -> 5.0654017 | W26: =($B$1+W$3)*(1-TAN(RADIANS(180-$A26)/2))/TAN(RADIANS(180-$A26)/2) -> 5.9863838
A27: 130 | B27: 0 | C27: =($B$1+C$3)*(1-TAN(RADIANS(180-$A27)/2))/TAN(RADIANS(180-$A27)/2) -> 2.4034645 | D27: 0 | E27: 0 | F27: =($B$1+F$3)*(1-TAN(RADIANS(180-$A27)/2))/TAN(RADIANS(180-$A27)/2) -> 2.7468166 | G27: 0 | H27: 0 | I27: =($B$1+I$3)*(1-TAN(RADIANS(180-$A27)/2))/TAN(RADIANS(180-$A27)/2) -> 3.3190701 | J27: 0 | K27: 0 | L27: =($B$1+L$3)*(1-TAN(RADIANS(180-$A27)/2))/TAN(RADIANS(180-$A27)/2) -> 4.0057742 | M27: 0 | N27: 0 | O27: 0 | P27: 0 | Q27: 0 | R27: 0 | S27: =($B$1+S$3)*(1-TAN(RADIANS(180-$A27)/2))/TAN(RADIANS(180-$A27)/2) -> 5.3791825 | T27: 0 | U27: 0 | V27: =($B$1+V$3)*(1-TAN(RADIANS(180-$A27)/2))/TAN(RADIANS(180-$A27)/2) -> 6.2947881 | W27: =($B$1+W$3)*(1-TAN(RADIANS(180-$A27)/2))/TAN(RADIANS(180-$A27)/2) -> 7.439295
A28: 135 | B28: 0 | C28: =($B$1+C$3)*(1-TAN(RADIANS(180-$A28)/2))/TAN(RADIANS(180-$A28)/2) -> 2.9698485 | D28: 0 | E28: 0 | F28: =($B$1+F$3)*(1-TAN(RADIANS(180-$A28)/2))/TAN(RADIANS(180-$A28)/2) -> 3.3941125 | G28: 0 | H28: 0 | I28: =($B$1+I$3)*(1-TAN(RADIANS(180-$A28)/2))/TAN(RADIANS(180-$A28)/2) -> 4.1012193 | J28: 0 | K28: 0 | L28: =($B$1+L$3)*(1-TAN(RADIANS(180-$A28)/2))/TAN(RADIANS(180-$A28)/2) -> 4.9497475 | M28: 0 | N28: 0 | O28: 0 | P28: 0 | Q28: 0 | R28: 0 | S28: =($B$1+S$3)*(1-TAN(RADIANS(180-$A28)/2))/TAN(RADIANS(180-$A28)/2) -> 6.6468037 | T28: 0 | U28: 0 | V28: =($B$1+V$3)*(1-TAN(RADIANS(180-$A28)/2))/TAN(RADIANS(180-$A28)/2) -> 7.7781746 | W28: =($B$1+W$3)*(1-TAN(RADIANS(180-$A28)/2))/TAN(RADIANS(180-$A28)/2) -> 9.1923882
A29: 140 | B29: 0 | C29: =($B$1+C$3)*(1-TAN(RADIANS(180-$A29)/2))/TAN(RADIANS(180-$A29)/2) -> 3.6697026 | D29: 0 | E29: 0 | F29: =($B$1+F$3)*(1-TAN(RADIANS(180-$A29)/2))/TAN(RADIANS(180-$A29)/2) -> 4.1939458 | G29: 0 | H29: 0 | I29: =($B$1+I$3)*(1-TAN(RADIANS(180-$A29)/2))/TAN(RADIANS(180-$A29)/2) -> 5.0676845 | J29: 0 | K29: 0 | L29: =($B$1+L$3)*(1-TAN(RADIANS(180-$A29)/2))/TAN(RADIANS(180-$A29)/2) -> 6.116171 | M29: 0 | N29: 0 | O29: 0 | P29: 0 | Q29: 0 | R29: 0 | S29: =($B$1+S$3)*(1-TAN(RADIANS(180-$A29)/2))/TAN(RADIANS(180-$A29)/2) -> 8.2131439 | T29: 0 | U29: 0 | V29: =($B$1+V$3)*(1-TAN(RADIANS(180-$A29)/2))/TAN(RADIANS(180-$A29)/2) -> 9.6111258 | W29: =($B$1+W$3)*(1-TAN(RADIANS(180-$A29)/2))/TAN(RADIANS(180-$A29)/2) -> 11.358603
A30: 145 | B30: 0 | C30: =($B$1+C$3)*(1-TAN(RADIANS(180-$A30)/2))/TAN(RADIANS(180-$A30)/2) -> 4.5603491 | D30: 0 | E30: 0 | F30: =($B$1+F$3)*(1-TAN(RADIANS(180-$A30)/2))/TAN(RADIANS(180-$A30)/2) -> 5.2118275 | G30: 0 | H30: 0 | I30: =($B$1+I$3)*(1-TAN(RADIANS(180-$A30)/2))/TAN(RADIANS(180-$A30)/2) -> 6.2976249 | J30: 0 | K30: 0 | L30: =($B$1+L$3)*(1-TAN(RADIANS(180-$A30)/2))/TAN(RADIANS(180-$A30)/2) -> 7.6005818 | M30: 0 | N30: 0 | O30: 0 | P30: 0 | Q30: 0 | R30: 0 | S30: =($B$1+S$3)*(1-TAN(RADIANS(180-$A30)/2))/TAN(RADIANS(180-$A30)/2) -> 10.206496 | T30: 0 | U30: 0 | V30: =($B$1+V$3)*(1-TAN(RADIANS(180-$A30)/2))/TAN(RADIANS(180-$A30)/2) -> 11.943771 | W30: =($B$1+W$3)*(1-TAN(RADIANS(180-$A30)/2))/TAN(RADIANS(180-$A30)/2) -> 14.115366
A31: 150 | B31: 0 | C31: =($B$1+C$3)*(1-TAN(RADIANS(180-$A31)/2))/TAN(RADIANS(180-$A31)/2) -> 5.7373067 | D31: 0 | E31: 0 | F31: =($B$1+F$3)*(1-TAN(RADIANS(180-$A31)/2))/TAN(RADIANS(180-$A31)/2) -> 6.5569219 | G31: 0 | H31: 0 | I31: =($B$1+I$3)*(1-TAN(RADIANS(180-$A31)/2))/TAN(RADIANS(180-$A31)/2) -> 7.9229473 | J31: 0 | K31: 0 | L31: =($B$1+L$3)*(1-TAN(RADIANS(180-$A31)/2))/TAN(RADIANS(180-$A31)/2) -> 9.5621778 | M31: 0 | N31: 0 | O31: 0 | P31: 0 | Q31: 0 | R31: 0 | S31: =($B$1+S$3)*(1-TAN(RADIANS(180-$A31)/2))/TAN(RADIANS(180-$A31)/2) -> 12.840639 | T31: 0 | U31: 0 | V31: =($B$1+V$3)*(1-TAN(RADIANS(180-$A31)/2))/TAN(RADIANS(180-$A31)/2) -> 15.026279 | W31: =($B$1+W$3)*(1-TAN(RADIANS(180-$A31)/2))/TAN(RADIANS(180-$A31)/2) -> 17.75833
A33: Thickness: | B33: 1.2
A34: Angle | B34: Radius
B35: 1 | C35: 1.1 | D35: 1.2 | E35: 1.3 | F35: 1.4 | G35: 1.6 | H35: 1.7 | I35: 1.9 | J35: 2 | K35: 2.3 | L35: 2.5 | M35: 2.6 | N35: 2.7 | O35: 3 | P35: 3.2 | Q35: 3.3 | R35: 3.4 | S35: 3.7 | T35: 3.9 | U35: 4.3 | V35: 4.5 | W35: 5.5
A36: 15 | B36: 0 | C36: 0 | D36: 0 | E36: 0 | F36: 0 | G36: 0 | H36: 0 | I36: 0 | J36: 0 | K36: 0 | L36: 0 | M36: 0 | N36: 0 | O36: 0 | P36: 0 | Q36: 0 | R36: 0 | S36: 0 | T36: 0 | U36: 0 | V36: 0 | W36: 0
A37: 20 | B37: 0 | C37: 0 | D37: 0 | E37: 0 | F37: 0 | G37: 0 | H37: 0 | I37: 0 | J37: 0 | K37: 0 | L37: 0 | M37: 0 | N37: 0 | O37: 0 | P37: 0 | Q37: 0 | R37: 0 | S37: 0 | T37: 0 | U37: 0 | V37: 0 | W37: 0
A38: 25 | B38: 0 | C38: 0 | D38: 0 | E38: 0 | F38: 0 | G38: 0 | H38: 0 | I38: 0 | J38: 0 | K38: 0 | L38: 0 | M38: 0 | N38: 0 | O38: 0 | P38: 0 | Q38: 0 | R38: 0 | S38: 0 | T38: 0 | U38: 0 | V38: 0 | W38: 0
A39: 30 | B39: 0 | C39: 0 | D39: 0 | E39: 0 | F39: 0 | G39: 0 | H39: 0 | I39: 0 | J39: 0 | K39: 0 | L39: 0 | M39: 0 | N39: 0 | O39: 0 | P39: 0 | Q39: 0 | R39: 0 | S39: 0 | T39: 0 | U39: 0 | V39: 0 | W39: 0
A40: 35 | B40: 0 | C40: 0 | D40: 0 | E40: 0 | F40: 0 | G40: 0 | H40: 0 | I40: 0 | J40: 0 | K40: 0 | L40: 0 | M40: 0 | N40: 0 | O40: 0 | P40: 0 | Q40: 0 | R40: 0 | S40: 0 | T40: 0 | U40: 0 | V40: 0 | W40: 0
A41: 40 | B41: 0 | C41: 0 | D41: 0 | E41: 0 | F41: 0 | G41: 0 | H41: 0 | I41: 0 | J41: 0 | K41: 0 | L41: 0 | M41: 0 | N41: 0 | O41: 0 | P41: 0 | Q41: 0 | R41: 0 | S41: 0 | T41: 0 | U41: 0 | V41: 0 | W41: 0
A42: 45 | B42: 0 | C42: 0 | D42: 0 | E42: 0 | F42: 0 | G42: 0 | H42: 0 | I42: 0 | J42: 0 | K42: 0 | L42: 0 | M42: 0 | N42: 0 | O42: 0 | P42: 0 | Q42: 0 | R42: 0 | S42: 0 | T42: 0 | U42: 0 | V42: 0 | W42: 0
