Workbook

Sheet Sheet1
A2: Unit: | B2: Millimeters
A3: Type: | B3: Bend Deduction
A4: Material: | B4: Cobre
A7: Thickness: | B7: 2
A8: Angle | B8: Raio
B9: 0.5 | C9: 1.3 | D9: 1.4 | E9: 1.5 | F9: 1.6 | G9: 2 | H9: 2.1 | I9: 2.5 | J9: 2.8 | K9: 3.2 | L9: 3.3 | M9: 4 | N9: 4.2
A10: 15 | B10: 1.2 | C10: =2*(-1*INDEX('Desconto Processos'!$B$5:$G$32,MATCH(180-$A10,'Desconto Processos'!$A$5:$A$32,0),MATCH(C$9,'Desconto Processos'!$B$3:$G$3,0))+INDEX('Acrescimo Tangente'!$B$4:$N$31,MATCH($A10,$A$10:$A$37,0),MATCH(C$9,$B$9:$N$9,0))) -> 0.3 | D10: =2*(-1*INDEX('Desconto Processos'!$B$5:$G$32,MATCH(180-$A10,'Desconto Processos'!$A$5:$A$32,0),MATCH(D$9,'Desconto Processos'!$B$3:$G$3,0))+INDEX('Acrescimo Tangente'!$B$4:$N$31,MATCH($A10,$A$10:$A$37,0),MATCH(D$9,$B$9:$N$9,0))) -> 0.3 | E10: =2*(-1*INDEX('Desconto Processos'!$B$5:$G$32,MATCH(180-$A10,'Desconto Processos'!$A$5:$A$32,0),MATCH(E$9,'Desconto Processos'!$B$3:$G$3,0))+INDEX('Acrescimo Tangente'!$B$4:$N$31,MATCH($A10,$A$10:$A$37,0),MATCH(E$9,$B$9:$N$9,0))) -> 0.4 | F10: =2*(-1*INDEX('Desconto Processos'!$B$5:$G$32,MATCH(180-$A10,'Desconto Processos'!$A$5:$A$32,0),MATCH(F$9,'Desconto Processos'!$B$3:$G$3,0))+INDEX('Acrescimo Tangente'!$B$4:$N$31,MATCH($A10,$A$10:$A$37,0),MATCH(F$9,$B$9:$N$9,0))) -> 0.4 | G10: 0 | H10: =2*(-1*INDEX('Desconto Processos'!$B$5:$G$32,MATCH(180-$A10,'Desconto Processos'!$A$5:$A$32,0),MATCH(H$9,'Desconto Processos'!$B$3:$G$3,0))+INDEX('Acrescimo Tangente'!$B$4:$N$31,MATCH($A10,$A$10:$A$37,0),MATCH(H$9,$B$9:$N$9,0))) -> 0.4 | I10: =2*(-1*INDEX('Desconto Processos'!$B$5:$G$32,MATCH(180-$A10,'Desconto Processos'!$A$5:$A$32,0),MATCH(I$9,'Desconto Processos'!$B$3:$G$3,0))+INDEX('Acrescimo Tangente'!$B$4:$N$31,MATCH($A10,$A$10:$A$37,0),MATCH(I$9,$B$9:$N$9,0))) -> 0.4 | J10: 0 | K10: 0 | L10: 0 | M10: 0 | N10: 0
A11: 20 | B11: 1.2 | C11: =2*(-1*INDEX('Desconto Processos'!$B$5:$G$32,MATCH(180-$A11,'Desconto Processos'!$A$5:$A$32,0),MATCH(C$9,'Desconto Processos'!$B$3:$G$3,0))+INDEX('Acrescimo Tangente'!$B$4:$N$31,MATCH($A11,$A$10:$A$37,0),MATCH(C$9,$B$9:$N$9,0))) -> 0.4 | D11: =2*(-1*INDEX('Desconto Processos'!$B$5:$G$32,MATCH(180-$A11,'Desconto Processos'!$A$5:$A$32,0),MATCH(D$9,'Desconto Processos'!$B$3:$G$3,0))+INDEX('Acrescimo Tangente'!$B$4:$N$31,MATCH($A11,$A$10:$A$37,0),MATCH(D$9,$B$9:$N$9,0))) -> 0.4 | E11: =2*(-1*INDEX('Desconto Processos'!$B$5:$G$32,MATCH(180-$A11,'Desconto Processos'!$A$5:$A$32,0),MATCH(E$9,'Desconto Processos'!$B$3:$G$3,0))+INDEX('Acrescimo Tangente'!$B$4:$N$31,MATCH($A11,$A$10:$A$37,0),MATCH(E$9,$B$9:$N$9,0))) -> 0.5 | F11: =2*(-1*INDEX('Desconto Processos'!$B$5:$G$32,MATCH(180-$A11,'Desconto Processos'!$A$5:$A$32,0),MATCH(F$9,'Desconto Processos'!$B$3:$G$3,0))+INDEX('Acrescimo Tangente'!$B$4:$N$31,MATCH($A11,$A$10:$A$37,0),MATCH(F$9,$B$9:$N$9,0))) -> 0.5 | G11: 0 | H11: =2*(-1*INDEX('Desconto Processos'!$B$5:$G$32,MATCH(180-$A11,'Desconto Processos'!$A$5:$A$32,0),MATCH(H$9,'Desconto Processos'!$B$3:$G$3,0))+INDEX('Acrescimo Tangente'!$B$4:$N$31,MATCH($A11,$A$10:$A$37,0),MATCH(H$9,$B$9:$N$9,0))) -> 0.5 | I11: =2*(-1*INDEX('Desconto Processos'!$B$5:$G$32,MATCH(180-$A11,'Desconto Processos'!$A$5:$A$32,0),MATCH(I$9,'Desconto Processos'!$B$3:$G$3,0))+INDEX('Acrescimo Tangente'!$B$4:$N$31,MATCH($A11,$A$10:$A$37,0),MATCH(I$9,$B$9:$N$9,0))) -> 0.5 | J11: 0 | K11: 0 | L11: 0 | M11: 0 | N11: 0
A12: 25 | B12: 1.2 | C12: =2*(-1*INDEX('Desconto Processos'!$B$5:$G$32,MATCH(180-$A12,'Desconto Processos'!$A$5:$A$32,0),MATCH(C$9,'Desconto Processos'!$B$3:$G$3,0))+INDEX('Acrescimo Tangente'!$B$4:$N$31,MATCH($A12,$A$10:$A$37,0),MATCH(C$9,$B$9:$N$9,0))) -> 0.6 | D12: =2*(-1*INDEX('Desconto Processos'!$B$5:$G$32,MATCH(180-$A12,'Desconto Processos'!$A$5:$A$32,0),MATCH(D$9,'Desconto Processos'!$B$3:$G$3,0))+INDEX('Acrescimo Tangente'!$B$4:$N$31,MATCH($A12,$A$10:$A$37,0),MATCH(D$9,$B$9:$N$9,0))) -> 0.6 | E12: =2*(-1*INDEX('Desconto Processos'!$B$5:$G$32,MATCH(180-$A12,'Desconto Processos'!$A$5:$A$32,0),MATCH(E$9,'Desconto Processos'!$B$3:$G$3,0))+INDEX('Acrescimo Tangente'!$B$4:$N$31,MATCH($A12,$A$10:$A$37,0),MATCH(E$9,$B$9:$N$9,0))) -> 0.6 | F12: =2*(-1*INDEX('Desconto Processos'!$B$5:$G$32,MATCH(180-$A12,'Desconto Processos'!$A$5:$A$32,0),MATCH(F$9,'Desconto Processos'!$B$3:$G$3,0))+INDEX('Acrescimo Tangente'!$B$4:$N$31,MATCH($A12,$A$10:$A$37,0),MATCH(F$9,$B$9:$N$9,0))) -> 0.7 | G12: 0 | H12: =2*(-1*INDEX('Desconto Processos'!$B$5:$G$32,MATCH(180-$A12,'Desconto Processos'!$A$5:$A$32,0),MATCH(H$9,'Desconto Processos'!$B$3:$G$3,0))+INDEX('Acrescimo Tangente'!$B$4:$N$31,MATCH($A12,$A$10:$A$37,0),MATCH(H$9,$B$9:$N$9,0))) -> 0.6 | I12: =2*(-1*INDEX('Desconto Processos'!$B$5:$G$32,MATCH(180-$A12,'Desconto Processos'!$A$5:$A$32,0),MATCH(I$9,'Desconto Processos'!$B$3:$G$3,0))+INDEX('Acrescimo Tangente'!$B$4:$N$31,MATCH($A12,$A$10:$A$37,0),MATCH(I$9,$B$9:$N$9,0))) -> 0.6 | J12: 0 | K12: 0 | L12: 0 | M12: 0 | N12: 0
A13: 30 | B13: 1.2 | C13: =2*(-1*INDEX('Desconto Processos'!$B$5:$G$32,MATCH(180-$A13,'Desconto Processos'!$A$5:$A$32,0),MATCH(C$9,'Desconto Processos'!$B$3:$G$3,0))+INDEX('Acrescimo Tangente'!$B$4:$N$31,MATCH($A13,$A$10:$A$37,0),MATCH(C$9,$B$9:$N$9,0))) -> 0.7 | D13: =2*(-1*INDEX('Desconto Processos'!$B$5:$G$32,MATCH(180-$A13,'Desconto Processos'!$A$5:$A$32,0),MATCH(D$9,'Desconto Processos'!$B$3:$G$3,0))+INDEX('Acrescimo Tangente'!$B$4:$N$31,MATCH($A13,$A$10:$A$37,0),MATCH(D$9,$B$9:$N$9,0))) -> 0.7 | E13: =2*(-1*INDEX('Desconto Processos'!$B$5:$G$32,MATCH(180-$A13,'Desconto Processos'!$A$5:$A$32,0),MATCH(E$9,'Desconto Processos'!$B$3:$G$3,0))+INDEX('Acrescimo Tangente'!$B$4:$N$31,MATCH($A13,$A$10:$A$37,0),MATCH(E$9,$B$9:$N$9,0))) -> 0.7 | F13: =2*(-1*INDEX('Desconto Processos'!$B$5:$G$32,MATCH(180-$A13,'Desconto Processos'!$A$5:$A$32,0),MATCH(F$9,'Desconto Processos'!$B$3:$G$3,0))+INDEX('Acrescimo Tangente'!$B$4:$N$31,MATCH($A13,$A$10:$A$37,0),MATCH(F$9,$B$9:$N$9,0))) -> 0.8 | G13: 0 | H13: =2*(-1*INDEX('Desconto Processos'!$B$5:$G$32,MATCH(180-$A13,'Desconto Processos'!$A$5:$A$32,0),MATCH(H$9,'Desconto Processos'!$B$3:$G$3,0))+INDEX('Acrescimo Tangente'!$B$4:$N$31,MATCH($A13,$A$10:$A$37,0),MATCH(H$9,$B$9:$N$9,0))) -> 0.8 | I13: =2*(-1*INDEX('Desconto Processos'!$B$5:$G$32,MATCH(180-$A13,'Desconto Processos'!$A$5:$A$32,0),MATCH(I$9,'Desconto Processos'!$B$3:$G$3,0))+INDEX('Acrescimo Tangente'!$B$4:$N$31,MATCH($A13,$A$10:$A$37,0),MATCH(I$9,$B$9:$N$9,0))) -> 0.8 | J13: 0 | K13: 0 | L13: 0 | M13: 0 | N13: 0
A14: 35 | B14: 1.2 | C14: =2*(-1*INDEX('Desconto Processos'!$B$5:$G$32,MATCH(180-$A14,'Desconto Processos'!$A$5:$A$32,0),MATCH(C$9,'Desconto Processos'!$B$3:$G$3,0))+INDEX('Acrescimo Tangente'!$B$4:$N$31,MATCH($A14,$A$10:$A$37,0),MATCH(C$9,$B$9:$N$9,0))) -> 0.9 | D14: =2*(-1*INDEX('Desconto Processos'!$B$5:$G$32,MATCH(180-$A14,'Desconto Processos'!$A$5:$A$32,0),MATCH(D$9,'Desconto Processos'!$B$3:$G$3,0))+INDEX('Acrescimo Tangente'!$B$4:$N$31,MATCH($A14,$A$10:$A$37,0),MATCH(D$9,$B$9:$N$9,0))) -> 0.8 | E14: =2*(-1*INDEX('Desconto Processos'!$B$5:$G$32,MATCH(180-$A14,'Desconto Processos'!$A$5:$A$32,0),MATCH(E$9,'Desconto Processos'!$B$3:$G$3,0))+INDEX('Acrescimo Tangente'!$B$4:$N$31,MATCH($A14,$A$10:$A$37,0),MATCH(E$9,$B$9:$N$9,0))) -> 0.8 | F14: =2*(-1*INDEX('Desconto Processos'!$B$5:$G$32,MATCH(180-$A14,'Desconto Processos'!$A$5:$A$32,0),MATCH(F$9,'Desconto Processos'!$B$3:$G$3,0))+INDEX('Acrescimo Tangente'!$B$4:$N$31,MATCH($A14,$A$10:$A$37,0),MATCH(F$9,$B$9:$N$9,0))) -> 1 | G14: 0 | H14: =2*(-1*INDEX('Desconto Processos'!$B$5:$G$32,MATCH(180-$A14,'Desconto Processos'!$A$5:$A$32,0),MATCH(H$9,'Desconto Processos'!$B$3:$G$3,0))+INDEX('Acrescimo Tangente'!$B$4:$N$31,MATCH($A14,$A$10:$A$37,0),MATCH(H$9,$B$9:$N$9,0))) -> 1 | I14: =2*(-1*INDEX('Desconto Processos'!$B$5:$G$32,MATCH(180-$A14,'Desconto Processos'!$A$5:$A$32,0),MATCH(I$9,'Desconto Processos'!$B$3:$G$3,0))+INDEX('Acrescimo Tangente'!$B$4:$N$31,MATCH($A14,$A$10:$A$37,0),MATCH(I$9,$B$9:$N$9,0))) -> 0.9 | J14: 0 | K14: 0 | L14: 0 | M14: 0 | N14: 0
A15: 40 | B15: 1.2 | C15: =2*(-1*INDEX('Desconto Processos'!$B$5:$G$32,MATCH(180-$A15,'Desconto Processos'!$A$5:$A$32,0),MATCH(C$9,'Desconto Processos'!$B$3:$G$3,0))+INDEX('Acrescimo Tangente'!$B$4:$N$31,MATCH($A15,$A$10:$A$37,0),MATCH(C$9,$B$9:$N$9,0))) -> 1.1 | D15: =2*(-1*INDEX('Desconto Processos'!$B$5:$G$32,MATCH(180-$A15,'Desconto Processos'!$A$5:$A$32,0),MATCH(D$9,'Desconto Processos'!$B$3:$G$3,0))+INDEX('Acrescimo Tangente'!$B$4:$N$31,MATCH($A15,$A$10:$A$37,0),MATCH(D$9,$B$9:$N$9,0))) -> 1.1 | E15: =2*(-1*INDEX('Desconto Processos'!$B$5:$G$32,MATCH(180-$A15,'Desconto Processos'!$A$5:$A$32,0),MATCH(E$9,'Desconto Processos'!$B$3:$G$3,0))+INDEX('Acrescimo Tangente'!$B$4:$N$31,MATCH($A15,$A$10:$A$37,0),MATCH(E$9,$B$9:$N$9,0))) -> 1 | F15: =2*(-1*INDEX('Desconto Processos'!$B$5:$G$32,MATCH(180-$A15,'Desconto Processos'!$A$5:$A$32,0),MATCH(F$9,'Desconto Processos'!$B$3:$G$3,0))+INDEX('Acrescimo Tangente'!$B$4:$N$31,MATCH($A15,$A$10:$A$37,0),MATCH(F$9,$B$9:$N$9,0))) -> 1.1 | G15: 0 | H15: =2*(-1*INDEX('Desconto Processos'!$B$5:$G$32,MATCH(180-$A15,'Desconto Processos'!$A$5:$A$32,0),MATCH(H$9,'Desconto Processos'!$B$3:$G$3,0))+INDEX('Acrescimo Tangente'!$B$4:$N$31,MATCH($A15,$A$10:$A$37,0),MATCH(H$9,$B$9:$N$9,0))) -> 1.1 | I15: =2*(-1*INDEX('Desconto Processos'!$B$5:$G$32,MATCH(180-$A15,'Desconto Processos'!$A$5:$A$32,0),MATCH(I$9,'Desconto Processos'!$B$3:$G$3,0))+INDEX('Acrescimo Tangente'!$B$4:$N$31,MATCH($A15,$A$10:$A$37,0),MATCH(I$9,$B$9:$N$9,0))) -> 1 | J15: 0 | K15: 0 | L15: 0 | M15: 0 | N15: 0
A16: 45 | B16: 1.2 | C16: =2*(-1*INDEX('Desconto Processos'!$B$5:$G$32,MATCH(180-$A16,'Desconto Processos'!$A$5:$A$32,0),MATCH(C$9,'Desconto Processos'!$B$3:$G$3,0))+INDEX('Acrescimo Tangente'!$B$4:$N$31,MATCH($A16,$A$10:$A$37,0),MATCH(C$9,$B$9:$N$9,0))) -> 1.2 | D16: =2*(-1*INDEX('Desconto Processos'!$B$5:$G$32,MATCH(180-$A16,'Desconto Processos'!$A$5:$A$32,0),MATCH(D$9,'Desconto Processos'!$B$3:$G$3,0))+INDEX('Acrescimo Tangente'!$B$4:$N$31,MATCH($A16,$A$10:$A$37,0),MATCH(D$9,$B$9:$N$9,0))) -> 1.2 | E16: =2*(-1*INDEX('Desconto Processos'!$B$5:$G$32,MATCH(180-$A16,'Desconto Processos'!$A$5:$A$32,0),MATCH(E$9,'Desconto Processos'!$B$3:$G$3,0))+INDEX('Acrescimo Tangente'!$B$4:$N$31,MATCH($A16,$A$10:$A$37,0),MATCH(E$9,$B$9:$N$9,0))) -> 1.2 | F16: =2*(-1*INDEX('Desconto Processos'!$B$5:$G$32,MATCH(180-$A16,'Desconto Processos'!$A$5:$A$32,0),MATCH(F$9,'Desconto Processos'!$B$3:$G$3,0))+INDEX('Acrescimo Tangente'!$B$4:$N$31,MATCH($A16,$A$10:$A$37,0),MATCH(F$9,$B$9:$N$9,0))) -> 1.3 | G16: 0 | H16: =2*(-1*INDEX('Desconto Processos'!$B$5:$G$32,MATCH(180-$A16,'Desconto Processos'!$A$5:$A$32,0),MATCH(H$9,'Desconto Processos'!$B$3:$G$3,0))+INDEX('Acrescimo Tangente'!$B$4:$N$31,MATCH($A16,$A$10:$A$37,0),MATCH(H$9,$B$9:$N$9,0))) -> 1.3 | I16: =2*(-1*INDEX('Desconto Processos'!$B$5:$G$32,MATCH(180-$A16,'Desconto Processos'!$A$5:$A$32,0),MATCH(I$9,'Desconto Processos'!$B$3:$G$3,0))+INDEX('Acrescimo Tangente'!$B$4:$N$31,MATCH($A16,$A$10:$A$37,0),MATCH(I$9,$B$9:$N$9,0))) -> 1.2 | J16: 0 | K16: 0 | L16: 0 | M16: 0 | N16: 0
A17: 50 | B17: 1.2 | C17: =2*(-1*INDEX('Desconto Processos'!$B$5:$G$32,MATCH(180-$A17,'Desconto Processos'!$A$5:$A$32,0),MATCH(C$9,'Desconto Processos'!$B$3:$G$3,0))+INDEX('Acrescimo Tangente'!$B$4:$N$31,MATCH($A17,$A$10:$A$37,0),MATCH(C$9,$B$9:$N$9,0))) -> 1.4 | D17: =2*(-1*INDEX('Desconto Processos'!$B$5:$G$32,MATCH(180-$A17,'Desconto Processos'!$A$5:$A$32,0),MATCH(D$9,'Desconto Processos'!$B$3:$G$3,0))+INDEX('Acrescimo Tangente'!$B$4:$N$31,MATCH($A17,$A$10:$A$37,0),MATCH(D$9,$B$9:$N$9,0))) -> 1.4 | E17: =2*(-1*INDEX('Desconto Processos'!$B$5:$G$32,MATCH(180-$A17,'Desconto Processos'!$A$5:$A$32,0),MATCH(E$9,'Desconto Processos'!$B$3:$G$3,0))+INDEX('Acrescimo Tangente'!$B$4:$N$31,MATCH($A17,$A$10:$A$37,0),MATCH(E$9,$B$9:$N$9,0))) -> 1.4 | F17: =2*(-1*INDEX('Desconto Processos'!$B$5:$G$32,MATCH(180-$A17,'Desconto Processos'!$A$5:$A$32,0),MATCH(F$9,'Desconto Processos'!$B$3:$G$3,0))+INDEX('Acrescimo Tangente'!$B$4:$N$31,MATCH($A17,$A$10:$A$37,0),MATCH(F$9,$B$9:$N$9,0))) -> 1.4 | G17: 0 | H17: =2*(-1*INDEX('Desconto Processos'!$B$5:$G$32,MATCH(180-$A17,'Desconto Processos'!$A$5:$A$32,0),MATCH(H$9,'Desconto Processos'!$B$3:$G$3,0))+INDEX('Acrescimo Tangente'!$B$4:$N$31,MATCH($A17,$A$10:$A$37,0),MATCH(H$9,$B$9:$N$9,0))) -> 1.4 | I17: =2*(-1*INDEX('Desconto Processos'!$B$5:$G$32,MATCH(180-$A17,'Desconto Processos'!$A$5:$A$32,0),MATCH(I$9,'Desconto Processos'!$B$3:$G$3,0))+INDEX('Acrescimo Tangente'!$B$4:$N$31,MATCH($A17,$A$10:$A$37,0),MATCH(I$9,$B$9:$N$9,0))) -> 1.4 | J17: 0 | K17: 0 | L17: 0 | M17: 0 | N17: 0
A18: 55 | B18: 1.2 | C18: =2*(-1*INDEX('Desconto Processos'!$B$5:$G$32,MATCH(180-$A18,'Desconto Processos'!$A$5:$A$32,0),MATCH(C$9,'Desconto Processos'!$B$3:$G$3,0))+INDEX('Acrescimo Tangente'!$B$4:$N$31,MATCH($A18,$A$10:$A$37,0),MATCH(C$9,$B$9:$N$9,0))) -> 1.6 | D18: =2*(-1*INDEX('Desconto Processos'!$B$5:$G$32,MATCH(180-$A18,'Desconto Processos'!$A$5:$A$32,0),MATCH(D$9,'Desconto Processos'!$B$3:$G$3,0))+INDEX('Acrescimo Tangente'!$B$4:$N$31,MATCH($A18,$A$10:$A$37,0),MATCH(D$9,$B$9:$N$9,0))) -> 1.6 | E18: =2*(-1*INDEX('Desconto Processos'!$B$5:$G$32,MATCH(180-$A18,'Desconto Processos'!$A$5:$A$32,0),MATCH(E$9,'Desconto Processos'!$B$3:$G$3,0))+INDEX('Acrescimo Tangente'!$B$4:$N$31,MATCH($A18,$A$10:$A$37,0),MATCH(E$9,$B$9:$N$9,0))) -> 1.6 | F18: =2*(-1*INDEX('Desconto Processos'!$B$5:$G$32,MATCH(180-$A18,'Desconto Processos'!$A$5:$A$32,0),MATCH(F$9,'Desconto Processos'!$B$3:$G$3,0))+INDEX('Acrescimo Tangente'!$B$4:$N$31,MATCH($A18,$A$10:$A$37,0),MATCH(F$9,$B$9:$N$9,0))) -> 1.7 | G18: 0 | H18: =2*(-1*INDEX('Desconto Processos'!$B$5:$G$32,MATCH(180-$A18,'Desconto Processos'!$A$5:$A$32,0),MATCH(H$9,'Desconto Processos'!$B$3:$G$3,0))+INDEX('Acrescimo Tangente'!$B$4:$N$31,MATCH($A18,$A$10:$A$37,0),MATCH(H$9,$B$9:$N$9,0))) -> 1.6 | I18: =2*(-1*INDEX('Desconto Processos'!$B$5:$G$32,MATCH(180-$A18,'Desconto Processos'!$A$5:$A$32,0),MATCH(I$9,'Desconto Processos'!$B$3:$G$3,0))+INDEX('Acrescimo Tangente'!$B$4:$N$31,MATCH($A18,$A$10:$A$37,0),MATCH(I$9,$B$9:$N$9,0))) -> 1.7 | J18: 0 | K18: 0 | L18: 0 | M18: 0 | N18: 0
A19: 60 | B19: 1.2 | C19: =2*(-1*INDEX('Desconto Processos'!$B$5:$G$32,MATCH(180-$A19,'Desconto Processos'!$A$5:$A$32,0),MATCH(C$9,'Desconto Processos'!$B$3:$G$3,0))+INDEX('Acrescimo Tangente'!$B$4:$N$31,MATCH($A19,$A$10:$A$37,0),MATCH(C$9,$B$9:$N$9,0))) -> 1.7 | D19: =2*(-1*INDEX('Desconto Processos'!$B$5:$G$32,MATCH(180-$A19,'Desconto Processos'!$A$5:$A$32,0),MATCH(D$9,'Desconto Processos'!$B$3:$G$3,0))+INDEX('Acrescimo Tangente'!$B$4:$N$31,MATCH($A19,$A$10:$A$37,0),MATCH(D$9,$B$9:$N$9,0))) -> 1.8 | E19: =2*(-1*INDEX('Desconto Processos'!$B$5:$G$32,MATCH(180-$A19,'Desconto Processos'!$A$5:$A$32,0),MATCH(E$9,'Desconto Processos'!$B$3:$G$3,0))+INDEX('Acrescimo Tangente'!$B$4:$N$31,MATCH($A19,$A$10:$A$37,0),MATCH(E$9,$B$9:$N$9,0))) -> 1.8 | F19: =2*(-1*INDEX('Desconto Processos'!$B$5:$G$32,MATCH(180-$A19,'Desconto Processos'!$A$5:$A$32,0),MATCH(F$9,'Desconto Processos'!$B$3:$G$3,0))+INDEX('Acrescimo Tangente'!$B$4:$N$31,MATCH($A19,$A$10:$A$37,0),MATCH(F$9,$B$9:$N$9,0))) -> 1.9 | G19: 0 | H19: =2*(-1*INDEX('Desconto Processos'!$B$5:$G$32,MATCH(180-$A19,'Desconto Processos'!$A$5:$A$32,0),MATCH(H$9,'Desconto Processos'!$B$3:$G$3,0))+INDEX('Acrescimo Tangente'!$B$4:$N$31,MATCH($A19,$A$10:$A$37,0),MATCH(H$9,$B$9:$N$9,0))) -> 1.9 | I19: =2*(-1*INDEX('Desconto Processos'!$B$5:$G$32,MATCH(180-$A19,'Desconto Processos'!$A$5:$A$32,0),MATCH(I$9,'Desconto Processos'!$B$3:$G$3,0))+INDEX('Acrescimo Tangente'!$B$4:$N$31,MATCH($A19,$A$10:$A$37,0),MATCH(I$9,$B$9:$N$9,0))) -> 2 | J19: 0 | K19: 0 | L19: 0 | M19: 0 | N19: 0
A20: 65 | B20: 1.2 | C20: =2*(-1*INDEX('Desconto Processos'!$B$5:$G$32,MATCH(180-$A20,'Desconto Processos'!$A$5:$A$32,0),MATCH(C$9,'Desconto Processos'!$B$3:$G$3,0))+INDEX('Acrescimo Tangente'!$B$4:$N$31,MATCH($A20,$A$10:$A$37,0),MATCH(C$9,$B$9:$N$9,0))) -> 2 | D20: =2*(-1*INDEX('Desconto Processos'!$B$5:$G$32,MATCH(180-$A20,'Desconto Processos'!$A$5:$A$32,0),MATCH(D$9,'Desconto Processos'!$B$3:$G$3,0))+INDEX('Acrescimo Tangente'!$B$4:$N$31,MATCH($A20,$A$10:$A$37,0),MATCH(D$9,$B$9:$N$9,0))) -> 2 | E20: =2*(-1*INDEX('Desconto Processos'!$B$5:$G$32,MATCH(180-$A20,'Desconto Processos'!$A$5:$A$32,0),MATCH(E$9,'Desconto Processos'!$B$3:$G$3,0))+INDEX('Acrescimo Tangente'!$B$4:$N$31,MATCH($A20,$A$10:$A$37,0),MATCH(E$9,$B$9:$N$9,0))) -> 2.1 | F20: =2*(-1*INDEX('Desconto Processos'!$B$5:$G$32,MATCH(180-$A20,'Desconto Processos'!$A$5:$A$32,0),MATCH(F$9,'Desconto Processos'!$B$3:$G$3,0))+INDEX('Acrescimo Tangente'!$B$4:$N$31,MATCH($A20,$A$10:$A$37,0),MATCH(F$9,$B$9:$N$9,0))) -> 2.1 | G20: 0 | H20: =2*(-1*INDEX('Desconto Processos'!$B$5:$G$32,MATCH(180-$A20,'Desconto Processos'!$A$5:$A$32,0),MATCH(H$9,'Desconto Processos'!$B$3:$G$3,0))+INDEX('Acrescimo Tangente'!$B$4:$N$31,MATCH($A20,$A$10:$A$37,0),MATCH(H$9,$B$9:$N$9,0))) -> 2.2 | I20: =2*(-1*INDEX('Desconto Processos'!$B$5:$G$32,MATCH(180-$A20,'Desconto Processos'!$A$5:$A$32,0),MATCH(I$9,'Desconto Processos'!$B$3:$G$3,0))+INDEX('Acrescimo Tangente'!$B$4:$N$31,MATCH($A20,$A$10:$A$37,0),MATCH(I$9,$B$9:$N$9,0))) -> 2.2 | J20: 0 | K20: 0 | L20: 0 | M20: 0 | N20: 0
A21: 70 | B21: 1.2 | C21: =2*(-1*INDEX('Desconto Processos'!$B$5:$G$32,MATCH(180-$A21,'Desconto Processos'!$A$5:$A$32,0),MATCH(C$9,'Desconto Processos'!$B$3:$G$3,0))+INDEX('Acrescimo Tangente'!$B$4:$N$31,MATCH($A21,$A$10:$A$37,0),MATCH(C$9,$B$9:$N$9,0))) -> 2.2 | D21: =2*(-1*INDEX('Desconto Processos'!$B$5:$G$32,MATCH(180-$A21,'Desconto Processos'!$A$5:$A$32,0),MATCH(D$9,'Desconto Processos'!$B$3:$G$3,0))+INDEX('Acrescimo Tangente'!$B$4:$N$31,MATCH($A21,$A$10:$A$37,0),MATCH(D$9,$B$9:$N$9,0))) -> 2.4 | E21: =2*(-1*INDEX('Desconto Processos'!$B$5:$G$32,MATCH(180-$A21,'Desconto Processos'!$A$5:$A$32,0),MATCH(E$9,'Desconto Processos'!$B$3:$G$3,0))+INDEX('Acrescimo Tangente'!$B$4:$N$31,MATCH($A21,$A$10:$A$37,0),MATCH(E$9,$B$9:$N$9,0))) -> 2.3 | F21: =2*(-1*INDEX('Desconto Processos'!$B$5:$G$32,MATCH(180-$A21,'Desconto Processos'!$A$5:$A$32,0),MATCH(F$9,'Desconto Processos'!$B$3:$G$3,0))+INDEX('Acrescimo Tangente'!$B$4:$N$31,MATCH($A21,$A$10:$A$37,0),MATCH(F$9,$B$9:$N$9,0))) -> 2.4 | G21: 0 | H21: =2*(-1*INDEX('Desconto Processos'!$B$5:$G$32,MATCH(180-$A21,'Desconto Processos'!$A$5:$A$32,0),MATCH(H$9,'Desconto Processos'!$B$3:$G$3,0))+INDEX('Acrescimo Tangente'!$B$4:$N$31,MATCH($A21,$A$10:$A$37,0),MATCH(H$9,$B$9:$N$9,0))) -> 2.5 | I21: =2*(-1*INDEX('Desconto Processos'!$B$5:$G$32,MATCH(180-$A21,'Desconto Processos'!$A$5:$A$32,0),MATCH(I$9,'Desconto Processos'!$B$3:$G$3,0))+INDEX('Acrescimo Tangente'!$B$4:$N$31,MATCH($A21,$A$10:$A$37,0),MATCH(I$9,$B$9:$N$9,0))) -> 2.5 | J21: 0 | K21: 0 | L21: 0 | M21: 0 | N21: 0
... A37: 150 | B37: 1.2 | C37: =2*(-1*INDEX('Desconto Processos'!$B$5:$G$32,MATCH(180-$A37,'Desconto Processos'!$A$5:$A$32,0),MATCH(C$9,'Desconto Processos'!$B$3:$G$3,0))+INDEX('Acrescimo Tangente'!$B$4:$N$31,MATCH($A37,$A$10:$A$37,0),MATCH(C$9,$B$9:$N$9,0))) -> 19.631535 | D37: =2*(-1*INDEX('Desconto Processos'!$B$5:$G$32,MATCH(180-$A37,'Desconto Processos'!$A$5:$A$32,0),MATCH(D$9,'Desconto Processos'!$B$3:$G$3,0))+INDEX('Acrescimo Tangente'!$B$4:$N$31,MATCH($A37,$A$10:$A$37,0),MATCH(D$9,$B$9:$N$9,0))) -> 20.177945 | E37: =2*(-1*INDEX('Desconto Processos'!$B$5:$G$32,MATCH(180-$A37,'Desconto Processos'!$A$5:$A$32,0),MATCH(E$9,'Desconto Processos'!$B$3:$G$3,0))+INDEX('Acrescimo Tangente'!$B$4:$N$31,MATCH($A37,$A$10:$A$37,0),MATCH(E$9,$B$9:$N$9,0))) -> 20.824356 | F37: =2*(-1*INDEX('Desconto Processos'!$B$5:$G$32,MATCH(180-$A37,'Desconto Processos'!$A$5:$A$32,0),MATCH(F$9,'Desconto Processos'!$B$3:$G$3,0))+INDEX('Acrescimo Tangente'!$B$4:$N$31,MATCH($A37,$A$10:$A$37,0),MATCH(F$9,$B$9:$N$9,0))) -> 21.070766 | G37: 0 | H37: =2*(-1*INDEX('Desconto Processos'!$B$5:$G$32,MATCH(180-$A37,'Desconto Processos'!$A$5:$A$32,0),MATCH(H$9,'Desconto Processos'!$B$3:$G$3,0))+INDEX('Acrescimo Tangente'!$B$4:$N$31,MATCH($A37,$A$10:$A$37,0),MATCH(H$9,$B$9:$N$9,0))) -> 23.502817 | I37: =2*(-1*INDEX('Desconto Processos'!$B$5:$G$32,MATCH(180-$A37,'Desconto Processos'!$A$5:$A$32,0),MATCH(I$9,'Desconto Processos'!$B$3:$G$3,0))+INDEX('Acrescimo Tangente'!$B$4:$N$31,MATCH($A37,$A$10:$A$37,0),MATCH(I$9,$B$9:$N$9,0))) -> 25.388457 | J37: 0 | K37: 0 | L37: 0 | M37: 0 | N37: 0
A39: Thickness: | B39: 3.2
A40: Angle | B40: Raio
B41: 0.5 | C41: 1.3 | D41: 1.4 | E41: 1.5 | F41: 1.6 | G41: 2 | H41: 2.1 | I41: 2.5 | J41: 2.8 | K41: 3.2 | L41: 3.3 | M41: 4 | N41: 4.2
A42: 15 | B42: 0.8 | C42: 0 | D42: 0 | E42: 0 | F42: 0 | G42: =2*(-1*INDEX('Desconto Processos'!$H$5:$J$32,MATCH(180-$A42,'Desconto Processos'!$A$5:$A$32,0),MATCH(G$41,'Desconto Processos'!$H$3:$J$3,0))+INDEX('Acrescimo Tangente'!$B$36:$N$63,MATCH($A42,$A$10:$A$37,0),MATCH(G$41,$B$9:$N$9,0))) -> 0.6 | H42: =2*(-1*INDEX('Desconto Processos'!$H$5:$J$32,MATCH(180-$A42,'Desconto Processos'!$A$5:$A$32,0),MATCH(H$41,'Desconto Processos'!$H$3:$J$3,0))+INDEX('Acrescimo Tangente'!$B$36:$N$63,MATCH($A42,$A$10:$A$37,0),MATCH(H$41,$B$9:$N$9,0))) -> 0.7 | I42: 0 | J42: =2*(-1*INDEX('Desconto Processos'!$H$5:$J$32,MATCH(180-$A42,'Desconto Processos'!$A$5:$A$32,0),MATCH(J$41,'Desconto Processos'!$H$3:$J$3,0))+INDEX('Acrescimo Tangente'!$B$36:$N$63,MATCH($A42,$A$10:$A$37,0),MATCH(J$41,$B$9:$N$9,0))) -> 0.9 | K42: 0 | L42: 0 | M42: 0 | N42: 0
A43: 20 | B43: 0.8 | C43: 0 | D43: 0 | E43: 0 | F43: 0 | G43: =2*(-1*INDEX('Desconto Processos'!$H$5:$J$32,MATCH(180-$A43,'Desconto Processos'!$A$5:$A$32,0),MATCH(G$41,'Desconto Processos'!$H$3:$J$3,0))+INDEX('Acrescimo Tangente'!$B$36:$N$63,MATCH($A43,$A$10:$A$37,0),MATCH(G$41,$B$9:$N$9,0))) -> 0.8 | H43: =2*(-1*INDEX('Desconto Processos'!$H$5:$J$32,MATCH(180-$A43,'Desconto Processos'!$A$5:$A$32,0),MATCH(H$41,'Desconto Processos'!$H$3:$J$3,0))+INDEX('Acrescimo Tangente'!$B$36:$N$63,MATCH($A43,$A$10:$A$37,0),MATCH(H$41,$B$9:$N$9,0))) -> 0.8 | I43: 0 | J43: =2*(-1*INDEX('Desconto Processos'!$H$5:$J$32,MATCH(180-$A43,'Desconto Processos'!$A$5:$A$32,0),MATCH(J$41,'Desconto Processos'!$H$3:$J$3,0))+INDEX('Acrescimo Tangente'!$B$36:$N$63,MATCH($A43,$A$10:$A$37,0),MATCH(J$41,$B$9:$N$9,0))) -> 1 | K43: 0 | L43: 0 | M43: 0 | N43: 0
A44: 25 | B44: 0.8 | C44: 0 | D44: 0 | E44: 0 | F44: 0 | G44: =2*(-1*INDEX('Desconto Processos'!$H$5:$J$32,MATCH(180-$A44,'Desconto Processos'!$A$5:$A$32,0),MATCH(G$41,'Desconto Processos'!$H$3:$J$3,0))+INDEX('Acrescimo Tangente'!$B$36:$N$63,MATCH($A44,$A$10:$A$37,0),MATCH(G$41,$B$9:$N$9,0))) -> 1 | H44: =2*(-1*INDEX('Desconto Processos'!$H$5:$J$32,MATCH(180-$A44,'Desconto Processos'!$A$5:$A$32,0),MATCH(H$41,'Desconto Processos'!$H$3:$J$3,0))+INDEX('Acrescimo Tangente'!$B$36:$N$63,MATCH($A44,$A$10:$A$37,0),MATCH(H$41,$B$9:$N$9,0))) -> 1 | I44: 0 | J44: =2*(-1*INDEX('Desconto Processos'!$H$5:$J$32,MATCH(180-$A44,'Desconto Processos'!$A$5:$A$32,0),MATCH(J$41,'Desconto Processos'!$H$3:$J$3,0))+INDEX('Acrescimo Tangente'!$B$36:$N$63,MATCH($A44,$A$10:$A$37,0),MATCH(J$41,$B$9:$N$9,0))) -> 1.2 | K44: 0 | L44: 0 | M44: 0 | N44: 0
A45: 30 | B45: 0.8 | C45: 0 | D45: 0 | E45: 0 | F45: 0 | G45: =2*(-1*INDEX('Desconto Processos'!$H$5:$J$32,MATCH(180-$A45,'Desconto Processos'!$A$5:$A$32,0),MATCH(G$41,'Desconto Processos'!$H$3:$J$3,0))+INDEX('Acrescimo Tangente'!$B$36:$N$63,MATCH($A45,$A$10:$A$37,0),MATCH(G$41,$B$9:$N$9,0))) -> 1.2 | H45: =2*(-1*INDEX('Desconto Processos'!$H$5:$J$32,MATCH(180-$A45,'Desconto Processos'!$A$5:$A$32,0),MATCH(H$41,'Desconto Processos'!$H$3:$J$3,0))+INDEX('Acrescimo Tangente'!$B$36:$N$63,MATCH($A45,$A$10:$A$37,0),MATCH(H$41,$B$9:$N$9,0))) -> 1.2 | I45: 0 | J45: =2*(-1*INDEX('Desconto Processos'!$H$5:$J$32,MATCH(180-$A45,'Desconto Processos'!$A$5:$A$32,0),MATCH(J$41,'Desconto Processos'!$H$3:$J$3,0))+INDEX('Acrescimo Tangente'!$B$36:$N$63,MATCH($A45,$A$10:$A$37,0),MATCH(J$41,$B$9:$N$9,0))) -> 1.3 | K45: 0 | L45: 0 | M45: 0 | N45: 0
A46: 35 | B46: 0.8 | C46: 0 | D46: 0 | E46: 0 | F46: 0 | G46: =2*(-1*INDEX('Desconto Processos'!$H$5:$J$32,MATCH(180-$A46,'Desconto Processos'!$A$5:$A$32,0),MATCH(G$41,'Desconto Processos'!$H$3:$J$3,0))+INDEX('Acrescimo Tangente'!$B$36:$N$63,MATCH($A46,$A$10:$A$37,0),MATCH(G$41,$B$9:$N$9,0))) -> 1.5 | H46: =2*(-1*INDEX('Desconto Processos'!$H$5:$J$32,MATCH(180-$A46,'Desconto Processos'!$A$5:$A$32,0),MATCH(H$41,'Desconto Processos'!$H$3:$J$3,0))+INDEX('Acrescimo Tangente'!$B$36:$N$63,MATCH($A46,$A$10:$A$37,0),MATCH(H$41,$B$9:$N$9,0))) -> 1.5 | I46: 0 | J46: =2*(-1*INDEX('Desconto Processos'!$H$5:$J$32,MATCH(180-$A46,'Desconto Processos'!$A$5:$A$32,0),MATCH(J$41,'Desconto Processos'!$H$3:$J$3,0))+INDEX('Acrescimo Tangente'!$B$36:$N$63,MATCH($A46,$A$10:$A$37,0),MATCH(J$41,$B$9:$N$9,0))) -> 1.4 | K46: 0 | L46: 0 | M46: 0 | N46: 0
A47: 40 | B47: 0.8 | C47: 0 | D47: 0 | E47: 0 | F47: 0 | G47: =2*(-1*INDEX('Desconto Processos'!$H$5:$J$32,MATCH(180-$A47,'Desconto Processos'!$A$5:$A$32,0),MATCH(G$41,'Desconto Processos'!$H$3:$J$3,0))+INDEX('Acrescimo Tangente'!$B$36:$N$63,MATCH($A47,$A$10:$A$37,0),MATCH(G$41,$B$9:$N$9,0))) -> 1.6 | H47: =2*(-1*INDEX('Desconto Processos'!$H$5:$J$32,MATCH(180-$A47,'Desconto Processos'!$A$5:$A$32,0),MATCH(H$41,'Desconto Processos'!$H$3:$J$3,0))+INDEX('Acrescimo Tangente'!$B$36:$N$63,MATCH($A47,$A$10:$A$37,0),MATCH(H$41,$B$9:$N$9,0))) -> 1.8 | I47: 0 | J47: =2*(-1*INDEX('Desconto Processos'!$H$5:$J$32,MATCH(180-$A47,'Desconto Processos'!$A$5:$A$32,0),MATCH(J$41,'Desconto Processos'!$H$3:$J$3,0))+INDEX('Acrescimo Tangente'!$B$36:$N$63,MATCH($A47,$A$10:$A$37,0),MATCH(J$41,$B$9:$N$9,0))) -> 1.7 | K47: 0 | L47: 0 | M47: 0 | N47: 0
A48: 45 | B48: 0.8 | C48: 0 | D48: 0 | E48: 0 | F48: 0 | G48: =2*(-1*INDEX('Desconto Processos'!$H$5:$J$32,MATCH(180-$A48,'Desconto Processos'!$A$5:$A$32,0),MATCH(G$41,'Desconto Processos'!$H$3:$J$3,0))+INDEX('Acrescimo Tangente'!$B$36:$N$63,MATCH($A48,$A$10:$A$37,0),MATCH(G$41,$B$9:$N$9,0))) -> 1.9 | H48: =2*(-1*INDEX('Desconto Processos'!$H$5:$J$32,MATCH(180-$A48,'Desconto Processos'!$A$5:$A$32,0),MATCH(H$41,'Desconto Processos'!$H$3:$J$3,0))+INDEX('Acrescimo Tangente'!$B$36:$N$63,MATCH($A48,$A$10:$A$37,0),MATCH(H$41,$B$9:$N$9,0))) -> 2 | I48: 0 | J48: =2*(-1*INDEX('Desconto Processos'!$H$5:$J$32,MATCH(180-$A48,'Desconto Processos'!$A$5:$A$32,0),MATCH(J$41,'Desconto Processos'!$H$3:$J$3,0))+INDEX('Acrescimo Tangente'!$B$36:$N$63,MATCH($A48,$A$10:$A$37,0),MATCH(J$41,$B$9:$N$9,0))) -> 2 | K48: 0 | L48: 0 | M48: 0 | N48: 0
A49: 50 | B49: 0.8 | C49: 0 | D49: 0 | E49: 0 | F49: 0 | G49: =2*(-1*INDEX('Desconto Processos'!$H$5:$J$32,MATCH(180-$A49,'Desconto Processos'!$A$5:$A$32,0),MATCH(G$41,'Desconto Processos'!$H$3:$J$3,0))+INDEX('Acrescimo Tangente'!$B$36:$N$63,MATCH($A49,$A$10:$A$37,0),MATCH(G$41,$B$9:$N$9,0))) -> 2.1 | H49: =2*(-1*INDEX('Desconto Processos'!$H$5:$J$32,MATCH(180-$A49,'Desconto Processos'!$A$5:$A$32,0),MATCH(H$41,'Desconto Processos'!$H$3:$J$3,0))+INDEX('Acrescimo Tangente'!$B$36:$N$63,MATCH($A49,$A$10:$A$37,0),MATCH(H$41,$B$9:$N$9,0))) -> 2.2 | I49: 0 | J49: =2*(-1*INDEX('Desconto Processos'!$H$5:$J$32,MATCH(180-$A49,'Desconto Processos'!$A$5:$A$32,0),MATCH(J$41,'Desconto Processos'!$H$3:$J$3,0))+INDEX('Acrescimo Tangente'!$B$36:$N$63,MATCH($A49,$A$10:$A$37,0),MATCH(J$41,$B$9:$N$9,0))) -> 2.3 | K49: 0 | L49: 0 | M49: 0 | N49: 0
A50: 55 | B50: 0.8 | C50: 0 | D50: 0 | E50: 0 | F50: 0 | G50: =2*(-1*INDEX('Desconto Processos'!$H$5:$J$32,MATCH(180-$A50,'Desconto Processos'!$A$5:$A$32,0),MATCH(G$41,'Desconto Processos'!$H$3:$J$3,0))+INDEX('Acrescimo Tangente'!$B$36:$N$63,MATCH($A50,$A$10:$A$37,0),MATCH(G$41,$B$9:$N$9,0))) -> 2.3 | H50: =2*(-1*INDEX('Desconto Processos'!$H$5:$J$32,MATCH(180-$A50,'Desconto Processos'!$A$5:$A$32,0),MATCH(H$41,'Desconto Processos'!$H$3:$J$3,0))+INDEX('Acrescimo Tangente'!$B$36:$N$63,MATCH($A50,$A$10:$A$37,0),MATCH(H$41,$B$9:$N$9,0))) -> 2.5 | I50: 0 | J50: =2*(-1*INDEX('Desconto Processos'!$H$5:$J$32,MATCH(180-$A50,'Desconto Processos'!$A$5:$A$32,0),MATCH(J$41,'Desconto Processos'!$H$3:$J$3,0))+INDEX('Acrescimo Tangente'!$B$36:$N$63,MATCH($A50,$A$10:$A$37,0),MATCH(J$41,$B$9:$N$9,0))) -> 2.6 | K50: 0 | L50: 0 | M50: 0 | N50: 0
A51: 60 | B51: 0.8 | C51: 0 | D51: 0 | E51: 0 | F51: 0 | G51: =2*(-1*INDEX('Desconto Processos'!$H$5:$J$32,MATCH(180-$A51,'Desconto Processos'!$A$5:$A$32,0),MATCH(G$41,'Desconto Processos'!$H$3:$J$3,0))+INDEX('Acrescimo Tangente'!$B$36:$N$63,MATCH($A51,$A$10:$A$37,0),MATCH(G$41,$B$9:$N$9,0))) -> 2.6 | H51: =2*(-1*INDEX('Desconto Processos'!$H$5:$J$32,MATCH(180-$A51,'Desconto Processos'!$A$5:$A$32,0),MATCH(H$41,'Desconto Processos'!$H$3:$J$3,0))+INDEX('Acrescimo Tangente'!$B$36:$N$63,MATCH($A51,$A$10:$A$37,0),MATCH(H$41,$B$9:$N$9,0))) -> 2.8 | I51: 0 | J51: =2*(-1*INDEX('Desconto Processos'!$H$5:$J$32,MATCH(180-$A51,'Desconto Processos'!$A$5:$A$32,0),MATCH(J$41,'Desconto Processos'!$H$3:$J$3,0))+INDEX('Acrescimo Tangente'!$B$36:$N$63,MATCH($A51,$A$10:$A$37,0),MATCH(J$41,$B$9:$N$9,0))) -> 2.8 | K51: 0 | L51: 0 | M51: 0 | N51: 0
A52: 65 | B52: 0.8 | C52: 0 | D52: 0 | E52: 0 | F52: 0 | G52: =2*(-1*INDEX('Desconto Processos'!$H$5:$J$32,MATCH(180-$A52,'Desconto Processos'!$A$5:$A$32,0),MATCH(G$41,'Desconto Processos'!$H$3:$J$3,0))+INDEX('Acrescimo Tangente'!$B$36:$N$63,MATCH($A52,$A$10:$A$37,0),MATCH(G$41,$B$9:$N$9,0))) -> 3.1 | H52: =2*(-1*INDEX('Desconto Processos'!$H$5:$J$32,MATCH(180-$A52,'Desconto Processos'!$A$5:$A$32,0),MATCH(H$41,'Desconto Processos'!$H$3:$J$3,0))+INDEX('Acrescimo Tangente'!$B$36:$N$63,MATCH($A52,$A$10:$A$37,0),MATCH(H$41,$B$9:$N$9,0))) -> 3.3 | I52: 0 | J52: =2*(-1*INDEX('Desconto Processos'!$H$5:$J$32,MATCH(180-$A52,'Desconto Processos'!$A$5:$A$32,0),MATCH(J$41,'Desconto Processos'!$H$3:$J$3,0))+INDEX('Acrescimo Tangente'!$B$36:$N$63,MATCH($A52,$A$10:$A$37,0),MATCH(J$41,$B$9:$N$9,0))) -> 3.3 | K52: 0 | L52: 0 | M52: 0 | N52: 0
A53: 70 | B53: 0.8 | C53: 0 | D53: 0 | E53: 0 | F53: 0 | G53: =2*(-1*INDEX('Desconto Processos'!$H$5:$J$32,MATCH(180-$A53,'Desconto Processos'!$A$5:$A$32,0),MATCH(G$41,'Desconto Processos'!$H$3:$J$3,0))+INDEX('Acrescimo Tangente'!$B$36:$N$63,MATCH($A53,$A$10:$A$37,0),MATCH(G$41,$B$9:$N$9,0))) -> 3.4 | H53: =2*(-1*INDEX('Desconto Processos'!$H$5:$J$32,MATCH(180-$A53,'Desconto Processos'!$A$5:$A$32,0),MATCH(H$41,'Desconto Processos'!$H$3:$J$3,0))+INDEX('Acrescimo Tangente'!$B$36:$N$63,MATCH($A53,$A$10:$A$37,0),MATCH(H$41,$B$9:$N$9,0))) -> 3.8 | I53: 0 | J53: =2*(-1*INDEX('Desconto Processos'!$H$5:$J$32,MATCH(180-$A53,'Desconto Processos'!$A$5:$A$32,0),MATCH(J$41,'Desconto Processos'!$H$3:$J$3,0))+INDEX('Acrescimo Tangente'!$B$36:$N$63,MATCH($A53,$A$10:$A$37,0),MATCH(J$41,$B$9:$N$9,0))) -> 3.7 | K53: 0 | L53: 0 | M53: 0 | N53: 0
... A69: 150 | B69: 0.8 | C69: 0 | D69: 0 | E69: 0 | F69: 0 | G69: =2*(-1*INDEX('Desconto Processos'!$H$5:$J$32,MATCH(180-$A69,'Desconto Processos'!$A$5:$A$32,0),MATCH(G$41,'Desconto Processos'!$H$3:$J$3,0))+INDEX('Acrescimo Tangente'!$B$36:$N$63,MATCH($A69,$A$10:$A$37,0),MATCH(G$41,$B$9:$N$9,0))) -> 31.213328 | H69: =2*(-1*INDEX('Desconto Processos'!$H$5:$J$32,MATCH(180-$A69,'Desconto Processos'!$A$5:$A$32,0),MATCH(H$41,'Desconto Processos'!$H$3:$J$3,0))+INDEX('Acrescimo Tangente'!$B$36:$N$63,MATCH($A69,$A$10:$A$37,0),MATCH(H$41,$B$9:$N$9,0))) -> 31.759739 | I69: 0 | J69: =2*(-1*INDEX('Desconto Processos'!$H$5:$J$32,MATCH(180-$A69,'Desconto Processos'!$A$5:$A$32,0),MATCH(J$41,'Desconto Processos'!$H$3:$J$3,0))+INDEX('Acrescimo Tangente'!$B$36:$N$63,MATCH($A69,$A$10:$A$37,0),MATCH(J$41,$B$9:$N$9,0))) -> 34.98461 | K69: 0 | L69: 0 | M69: 0 | N69: 0
A71: Thickness: | B71: 4
A72: Angle | B72: Raio
B73: 0.5 | C73: 1.3 | D73: 1.4 | E73: 1.5 | F73: 1.6 | G73: 2 | H73: 2.1 | I73: 2.5 | J73: 2.8 | K73: 3.2 | L73: 3.3 | M73: 4 | N73: 4.2
A74: 15 | B74: 0 | C74: 0 | D74: 0 | E74: 0 | F74: 0 | G74: 0 | H74: 0 | I74: 0 | J74: 0 | K74: =2*(-1*INDEX('Desconto Processos'!$K$5:$L$32,MATCH(180-$A74,'Desconto Processos'!$A$5:$A$32,0),MATCH(K$73,'Desconto Processos'!$K$3:$L$3,0))) -> 1 | L74: =2*(-1*INDEX('Desconto Processos'!$K$5:$L$32,MATCH(180-$A74,'Desconto Processos'!$A$5:$A$32,0),MATCH(L$73,'Desconto Processos'!$K$3:$L$3,0))) -> 1.1 | M74: 0 | N74: 0
A75: 20 | B75: 0 | C75: 0 | D75: 0 | E75: 0 | F75: 0 | G75: 0 | H75: 0 | I75: 0 | J75: 0 | K75: =2*(-1*INDEX('Desconto Processos'!$K$5:$L$32,MATCH(180-$A75,'Desconto Processos'!$A$5:$A$32,0),MATCH(K$73,'Desconto Processos'!$K$3:$L$3,0))) -> 0 | L75: =2*(-1*INDEX('Desconto Processos'!$K$5:$L$32,MATCH(180-$A75,'Desconto Processos'!$A$5:$A$32,0),MATCH(L$73,'Desconto Processos'!$K$3:$L$3,0))) -> 0 | M75: 0 | N75: 0
...

Sheet Desconto Processos
A1: ESPESSURA | B1: 2 mm | H1: 3.2 mm | K1: 4.0mm | M1: 5.0mm
A2: MATRIZ | B2: 8 | C2: 10 | D2: 12 | E2: 16 | F2: 20 | G2: 24 | H2: 16 | I2: 20 | J2: 24 | K2: 20 | L2: 24 | M2: 20 | N2: 24
A3: RAIO | B3: 1.3 | C3: 1.4 | D3: 1.5 | E3: 1.6 | F3: 2.1 | G3: 2.5 | H3: 2 | I3: 2.1 | J3: 2.8 | K3: 3.2 | L3: 3.3 | M3: 4 | N3: 4.2
A4: ÂNGULO ( b) | B4: ENCURTAMENTO ( ∆ L)
A5: 30 | B5: -0.8 | C5: -0.8 | D5: -0.85 | E5: -0.7 | F5: -0.55 | G5: -0.4 | H5: -1.4 | I5: -1.4 | J5: -1.1
A6: 35 | B6: -0.9 | C6: -0.9 | D6: -0.95 | E6: -0.8 | F6: -0.65 | G6: -0.5 | H6: -1.5 | I6: -1.55 | J6: -1.25
A7: 40 | B7: -1 | C7: -1 | D7: -1.05 | E7: -0.9 | F7: -0.75 | G7: -0.6 | H7: -1.55 | I7: -1.7 | J7: -1.45
A8: 45 | B8: -1.1 | C8: -1.1 | D8: -1.15 | E8: -1 | F8: -0.85 | G8: -0.7 | H8: -1.6 | I8: -1.8 | J8: -1.6
A9: 50 | B9: -1.2 | C9: -1.15 | D9: -1.2 | E9: -1.1 | F9: -0.95 | G9: -0.85 | H9: -1.7 | I9: -1.95 | J9: -1.8
A10: 55 | B10: -1.25 | C10: -1.25 | D10: -1.3 | E10: -1.2 | F10: -1.05 | G10: -1 | H10: -1.8 | I10: -2 | J10: -2
A11: 60 | B11: -1.3 | C11: -1.35 | D11: -1.35 | E11: -1.3 | F11: -1.2 | G11: -1.2 | H11: -1.9 | I11: -2.1 | J11: -2.1
A12: 65 | B12: -1.4 | C12: -1.4 | D12: -1.45 | E12: -1.4 | F12: -1.35 | G12: -1.3 | H12: -2.05 | I12: -2.15 | J12: -2.2
A13: 70 | B13: -1.5 | C13: -1.45 | D13: -1.55 | E13: -1.55 | F13: -1.5 | G13: -1.45 | H13: -2.1 | I13: -2.2 | J13: -2.35
A14: 75 | B14: -1.55 | C14: -1.5 | D14: -1.6 | E14: -1.6 | F14: -1.6 | G14: -1.6 | H14: -2.2 | I14: -2.25 | J14: -2.4
A15: 80 | B15: -1.6 | C15: -1.55 | D15: -1.65 | E15: -1.65 | F15: -1.7 | G15: -1.7 | H15: -2.3 | I15: -2.35 | J15: -2.5
A16: 85 | B16: -1.65 | C16: -1.65 | D16: -1.7 | E16: -1.7 | F16: -1.75 | G16: -1.8 | H16: -2.4 | I16: -2.45 | J16: -2.6
A17: 90 | B17: -1.7 | C17: -1.75 | D17: -1.75 | E17: -1.8 | F17: -1.85 | G17: -1.9 | H17: -2.5 | I17: -2.6 | J17: -2.7 | K17: -3.3 | L17: -3.35 | M17: -4.1 | N17: -4.15
A18: 95 | B18: -1.55 | C18: -1.6 | D18: -1.65 | E18: -1.7 | F18: -1.75 | G18: -1.7 | H18: -2.25 | I18: -2.45 | J18: -2.55
A19: 100 | B19: -1.35 | C19: -1.45 | D19: -1.5 | E19: -1.55 | F19: -1.5 | G19: -1.55 | H19: -2.05 | I19: -2.25 | J19: -2.3
A20: 105 | B20: -1.25 | C20: -1.3 | D20: -1.3 | E20: -1.3 | F20: -1.35 | G20: -1.4 | H20: -1.85 | I20: -2.05 | J20: -2.15 | K20: -2.35 | L20: -2.4 | M20: -2.8 | N20: -2.9
A21: 110 | B21: -1.1 | C21: -1.2 | D21: -1.15 | E21: -1.2 | F21: -1.25 | G21: -1.25 | H21: -1.7 | I21: -1.9 | J21: -1.85
A22: 115 | B22: -1 | C22: -1 | D22: -1.05 | E22: -1.05 | F22: -1.1 | G22: -1.1 | H22: -1.55 | I22: -1.65 | J22: -1.65
A23: 120 | B23: -0.85 | C23: -0.9 | D23: -0.9 | E23: -0.95 | F23: -0.95 | G23: -1 | H23: -1.3 | I23: -1.4 | J23: -1.4 | K23: -1.6 | L23: -1.7 | M23: -2 | N23: -2.1
A24: 125 | B24: -0.8 | C24: -0.8 | D24: -0.8 | E24: -0.85 | F24: -0.8 | G24: -0.85 | H24: -1.15 | I24: -1.25 | J24: -1.3
A25: 130 | B25: -0.7 | C25: -0.7 | D25: -0.7 | E25: -0.7 | F25: -0.7 | G25: -0.7 | H25: -1.05 | I25: -1.1 | J25: -1.15
A26: 135 | B26: -0.6 | C26: -0.6 | D26: -0.6 | E26: -0.65 | F26: -0.65 | G26: -0.6 | H26: -0.95 | I26: -1 | J26: -1 | K26: -1.1 | L26: -1.2 | M26: -1.25 | N26: -1.3
A27: 140 | B27: -0.55 | C27: -0.55 | D27: -0.5 | E27: -0.55 | F27: -0.55 | G27: -0.5 | H27: -0.8 | I27: -0.9 | J27: -0.85
A28: 145 | B28: -0.45 | C28: -0.4 | D28: -0.4 | E28: -0.5 | F28: -0.5 | G28: -0.45 | H28: -0.75 | I28: -0.75 | J28: -0.7
A29: 150 | B29: -0.35 | C29: -0.35 | D29: -0.35 | E29: -0.4 | F29: -0.4 | G29: -0.4 | H29: -0.6 | I29: -0.6 | J29: -0.65 | K29: -0.65 | L29: -0.75 | M29: -0.8 | N29: -0.85
A30: 155 | B30: -0.3 | C30: -0.3 | D30: -0.3 | E30: -0.35 | F30: -0.3 | G30: -0.3 | H30: -0.5 | I30: -0.5 | J30: -0.6
A31: 160 | B31: -0.2 | C31: -0.2 | D31: -0.25 | E31: -0.25 | F31: -0.25 | G31: -0.25 | H31: -0.4 | I31: -0.4 | J31: -0.5
A32: 165 | B32: -0.15 | C32: -0.15 | D32: -0.2 | E32: -0.2 | F32: -0.2 | G32: -0.2 | H32: -0.3 | I32: -0.35 | J32: -0.45 | K32: -0.5 | L32: -0.55 | M32: -0.25 | N32: -0.3

Sheet Acrescimo Tangente
A1: Thickness: | B1: 2
A2: Angle | B2: Raio
B3: 0.5 | C3: 1.3 | D3: 1.4 | E3: 1.5 | F3: 1.6 | G3: 2 | H3: 2.1 | I3: 2.5 | J3: 2.8 | K3: 3.2 | L3: 3.3 | M3: 4 | N3: 4.2
A4: 15 | B4: 0 | C4: 0 | D4: 0 | E4: 0 | F4: 0 | G4: 0 | H4: 0 | I4: 0 | J4: 0 | K4: 0 | L4: 0 | M4: 0 | N4: 0
A5: 20 | B5: 0 | C5: 0 | D5: 0 | E5: 0 | F5: 0 | G5: 0 | H5: 0 | I5: 0 | J5: 0 | K5: 0 | L5: 0 | M5: 0 | N5: 0
A6: 25 | B6: 0 | C6: 0 | D6: 0 | E6: 0 | F6: 0 | G6: 0 | H6: 0 | I6: 0 | J6: 0 | K6: 0 | L6: 0 | M6: 0 | N6: 0
A7: 30 | B7: 0 | C7: 0 | D7: 0 | E7: 0 | F7: 0 | G7: 0 | H7: 0 | I7: 0 | J7: 0 | K7: 0 | L7: 0 | M7: 0 | N7: 0
A8: 35 | B8: 0 | C8: 0 | D8: 0 | E8: 0 | F8: 0 | G8: 0 | H8: 0 | I8: 0 | J8: 0 | K8: 0 | L8: 0 | M8: 0 | N8: 0
A9: 40 | B9: 0 | C9: 0 | D9: 0 | E9: 0 | F9: 0 | G9: 0 | H9: 0 | I9: 0 | J9: 0 | K9: 0 | L9: 0 | M9: 0 | N9: 0
A10: 45 | B10: 0 | C10: 0 | D10: 0 | E10: 0 | F10: 0 | G10: 0 | H10: 0 | I10: 0 | J10: 0 | K10: 0 | L10: 0 | M10: 0 | N10: 0
A11: 50 | B11: 0 | C11: 0 | D11: 0 | E11: 0 | F11: 0 | G11: 0 | H11: 0 | I11: 0 | J11: 0 | K11: 0 | L11: 0 | M11: 0 | N11: 0
A12: 55 | B12: 0 | C12: 0 | D12: 0 | E12: 0 | F12: 0 | G12: 0 | H12: 0 | I12: 0 | J12: 0 | K12: 0 | L12: 0 | M12: 0 | N12: 0
A13: 60 | B13: 0 | C13: 0 | D13: 0 | E13: 0 | F13: 0 | G13: 0 | H13: 0 | I13: 0 | J13: 0 | K13: 0 | L13: 0 | M13: 0 | N13: 0
A14: 65 | B14: 0 | C14: 0 | D14: 0 | E14: 0 | F14: 0 | G14: 0 | H14: 0 | I14: 0 | J14: 0 | K14: 0 | L14: 0 | M14: 0 | N14: 0
A15: 70 | B15: 0 | C15: 0 | D15: 0 | E15: 0 | F15: 0 | G15: 0 | H15: 0 | I15: 0 | J15: 0 | K15: 0 | L15: 0 | M15: 0 | N15: 0
... A19: 90 | B19: 0 | C19: 0 | D19: 0 | E19: 0 | F19: 0 | G19: 0 | H19: 0 | I19: 0 | J19: 0 | K19: 0 | L19: 0 | M19: 0 | N19: 0
A20: 95 | B20: 0 | C20: =($B$1+C$3)*(1-TAN(RADIANS(180-$A20)/2))/TAN(RADIANS(180-$A20)/2) -> 0.30131805 | D20: =($B$1+D$3)*(1-TAN(RADIANS(180-$A20)/2))/TAN(RADIANS(180-$A20)/2) -> 0.3104489 | E20: =($B$1+E$3)*(1-TAN(RADIANS(180-$A20)/2))/TAN(RADIANS(180-$A20)/2) -> 0.31957975 | F20: =($B$1+F$3)*(1-TAN(RADIANS(180-$A20)/2))/TAN(RADIANS(180-$A20)/2) -> 0.3287106 | G20: 0 | H20: =($B$1+H$3)*(1-TAN(RADIANS(180-$A20)/2))/TAN(RADIANS(180-$A20)/2) -> 0.37436485 | I20: =($B$1+I$3)*(1-TAN(RADIANS(180-$A20)/2))/TAN(RADIANS(180-$A20)/2) -> 0.41088825 | J20: 0 | K20: 0 | L20: 0 | M20: 0 | N20: 0
A21: 100 | B21: 0 | C21: =($B$1+C$3)*(1-TAN(RADIANS(180-$A21)/2))/TAN(RADIANS(180-$A21)/2) -> 0.63278686 | D21: =($B$1+D$3)*(1-TAN(RADIANS(180-$A21)/2))/TAN(RADIANS(180-$A21)/2) -> 0.65196221 | E21: =($B$1+E$3)*(1-TAN(RADIANS(180-$A21)/2))/TAN(RADIANS(180-$A21)/2) -> 0.67113757 | F21: =($B$1+F$3)*(1-TAN(RADIANS(180-$A21)/2))/TAN(RADIANS(180-$A21)/2) -> 0.69031293 | G21: 0 | H21: =($B$1+H$3)*(1-TAN(RADIANS(180-$A21)/2))/TAN(RADIANS(180-$A21)/2) -> 0.78618973 | I21: =($B$1+I$3)*(1-TAN(RADIANS(180-$A21)/2))/TAN(RADIANS(180-$A21)/2) -> 0.86289117 | J21: 0 | K21: 0 | L21: 0 | M21: 0 | N21: 0
A22: 105 | B22: 0 | C22: =($B$1+C$3)*(1-TAN(RADIANS(180-$A22)/2))/TAN(RADIANS(180-$A22)/2) -> 1.0006437 | D22: =($B$1+D$3)*(1-TAN(RADIANS(180-$A22)/2))/TAN(RADIANS(180-$A22)/2) -> 1.0309663 | E22: =($B$1+E$3)*(1-TAN(RADIANS(180-$A22)/2))/TAN(RADIANS(180-$A22)/2) -> 1.0612888 | F22: =($B$1+F$3)*(1-TAN(RADIANS(180-$A22)/2))/TAN(RADIANS(180-$A22)/2) -> 1.0916113 | G22: 0 | H22: =($B$1+H$3)*(1-TAN(RADIANS(180-$A22)/2))/TAN(RADIANS(180-$A22)/2) -> 1.243224 | I22: =($B$1+I$3)*(1-TAN(RADIANS(180-$A22)/2))/TAN(RADIANS(180-$A22)/2) -> 1.3645142 | J22: 0 | K22: 0 | L22: 0 | M22: 0 | N22: 0
A23: 110 | B23: 0 | C23: =($B$1+C$3)*(1-TAN(RADIANS(180-$A23)/2))/TAN(RADIANS(180-$A23)/2) -> 1.4128884 | D23: =($B$1+D$3)*(1-TAN(RADIANS(180-$A23)/2))/TAN(RADIANS(180-$A23)/2) -> 1.4557032 | E23: =($B$1+E$3)*(1-TAN(RADIANS(180-$A23)/2))/TAN(RADIANS(180-$A23)/2) -> 1.498518 | F23: =($B$1+F$3)*(1-TAN(RADIANS(180-$A23)/2))/TAN(RADIANS(180-$A23)/2) -> 1.5413328 | G23: 0 | H23: =($B$1+H$3)*(1-TAN(RADIANS(180-$A23)/2))/TAN(RADIANS(180-$A23)/2) -> 1.7554068 | I23: =($B$1+I$3)*(1-TAN(RADIANS(180-$A23)/2))/TAN(RADIANS(180-$A23)/2) -> 1.926666 | J23: 0 | K23: 0 | L23: 0 | M23: 0 | N23: 0
A24: 115 | B24: 0 | C24: =($B$1+C$3)*(1-TAN(RADIANS(180-$A24)/2))/TAN(RADIANS(180-$A24)/2) -> 1.8799624 | D24: =($B$1+D$3)*(1-TAN(RADIANS(180-$A24)/2))/TAN(RADIANS(180-$A24)/2) -> 1.936931 | E24: =($B$1+E$3)*(1-TAN(RADIANS(180-$A24)/2))/TAN(RADIANS(180-$A24)/2) -> 1.9938995 | F24: =($B$1+F$3)*(1-TAN(RADIANS(180-$A24)/2))/TAN(RADIANS(180-$A24)/2) -> 2.0508681 | G24: 0 | H24: =($B$1+H$3)*(1-TAN(RADIANS(180-$A24)/2))/TAN(RADIANS(180-$A24)/2) -> 2.3357109 | I24: =($B$1+I$3)*(1-TAN(RADIANS(180-$A24)/2))/TAN(RADIANS(180-$A24)/2) -> 2.5635851 | J24: 0 | K24: 0 | L24: 0 | M24: 0 | N24: 0
A25: 120 | B25: 0 | C25: =($B$1+C$3)*(1-TAN(RADIANS(180-$A25)/2))/TAN(RADIANS(180-$A25)/2) -> 2.4157677 | D25: =($B$1+D$3)*(1-TAN(RADIANS(180-$A25)/2))/TAN(RADIANS(180-$A25)/2) -> 2.4889727 | E25: =($B$1+E$3)*(1-TAN(RADIANS(180-$A25)/2))/TAN(RADIANS(180-$A25)/2) -> 2.5621778 | F25: =($B$1+F$3)*(1-TAN(RADIANS(180-$A25)/2))/TAN(RADIANS(180-$A25)/2) -> 2.6353829 | G25: 0 | H25: =($B$1+H$3)*(1-TAN(RADIANS(180-$A25)/2))/TAN(RADIANS(180-$A25)/2) -> 3.0014083 | I25: =($B$1+I$3)*(1-TAN(RADIANS(180-$A25)/2))/TAN(RADIANS(180-$A25)/2) -> 3.2942286 | J25: 0 | K25: 0 | L25: 0 | M25: 0 | N25: 0
A26: 125 | B26: 0 | C26: =($B$1+C$3)*(1-TAN(RADIANS(180-$A26)/2))/TAN(RADIANS(180-$A26)/2) -> 3.039241 | D26: =($B$1+D$3)*(1-TAN(RADIANS(180-$A26)/2))/TAN(RADIANS(180-$A26)/2) -> 3.1313392 | E26: =($B$1+E$3)*(1-TAN(RADIANS(180-$A26)/2))/TAN(RADIANS(180-$A26)/2) -> 3.2234374 | F26: =($B$1+F$3)*(1-TAN(RADIANS(180-$A26)/2))/TAN(RADIANS(180-$A26)/2) -> 3.3155357 | G26: 0 | H26: =($B$1+H$3)*(1-TAN(RADIANS(180-$A26)/2))/TAN(RADIANS(180-$A26)/2) -> 3.7760267 | I26: =($B$1+I$3)*(1-TAN(RADIANS(180-$A26)/2))/TAN(RADIANS(180-$A26)/2) -> 4.1444196 | J26: 0 | K26: 0 | L26: 0 | M26: 0 | N26: 0
A27: 130 | B27: 0 | C27: =($B$1+C$3)*(1-TAN(RADIANS(180-$A27)/2))/TAN(RADIANS(180-$A27)/2) -> 3.7768728 | D27: =($B$1+D$3)*(1-TAN(RADIANS(180-$A27)/2))/TAN(RADIANS(180-$A27)/2) -> 3.8913235 | E27: =($B$1+E$3)*(1-TAN(RADIANS(180-$A27)/2))/TAN(RADIANS(180-$A27)/2) -> 4.0057742 | F27: =($B$1+F$3)*(1-TAN(RADIANS(180-$A27)/2))/TAN(RADIANS(180-$A27)/2) -> 4.1202249 | G27: 0 | H27: =($B$1+H$3)*(1-TAN(RADIANS(180-$A27)/2))/TAN(RADIANS(180-$A27)/2) -> 4.6924784 | I27: =($B$1+I$3)*(1-TAN(RADIANS(180-$A27)/2))/TAN(RADIANS(180-$A27)/2) -> 5.1502811 | J27: 0 | K27: 0 | L27: 0 | M27: 0 | N27: 0
A28: 135 | B28: 0 | C28: =($B$1+C$3)*(1-TAN(RADIANS(180-$A28)/2))/TAN(RADIANS(180-$A28)/2) -> 4.6669048 | D28: =($B$1+D$3)*(1-TAN(RADIANS(180-$A28)/2))/TAN(RADIANS(180-$A28)/2) -> 4.8083261 | E28: =($B$1+E$3)*(1-TAN(RADIANS(180-$A28)/2))/TAN(RADIANS(180-$A28)/2) -> 4.9497475 | F28: =($B$1+F$3)*(1-TAN(RADIANS(180-$A28)/2))/TAN(RADIANS(180-$A28)/2) -> 5.0911688 | G28: 0 | H28: =($B$1+H$3)*(1-TAN(RADIANS(180-$A28)/2))/TAN(RADIANS(180-$A28)/2) -> 5.7982756 | I28: =($B$1+I$3)*(1-TAN(RADIANS(180-$A28)/2))/TAN(RADIANS(180-$A28)/2) -> 6.363961 | J28: 0 | K28: 0 | L28: 0 | M28: 0 | N28: 0
A29: 140 | B29: 0 | C29: =($B$1+C$3)*(1-TAN(RADIANS(180-$A29)/2))/TAN(RADIANS(180-$A29)/2) -> 5.7666755 | D29: =($B$1+D$3)*(1-TAN(RADIANS(180-$A29)/2))/TAN(RADIANS(180-$A29)/2) -> 5.9414232 | E29: =($B$1+E$3)*(1-TAN(RADIANS(180-$A29)/2))/TAN(RADIANS(180-$A29)/2) -> 6.116171 | F29: =($B$1+F$3)*(1-TAN(RADIANS(180-$A29)/2))/TAN(RADIANS(180-$A29)/2) -> 6.2909187 | G29: 0 | H29: =($B$1+H$3)*(1-TAN(RADIANS(180-$A29)/2))/TAN(RADIANS(180-$A29)/2) -> 7.1646574 | I29: =($B$1+I$3)*(1-TAN(RADIANS(180-$A29)/2))/TAN(RADIANS(180-$A29)/2) -> 7.8636484 | J29: 0 | K29: 0 | L29: 0 | M29: 0 | N29: 0
A30: 145 | B30: 0 | C30: =($B$1+C$3)*(1-TAN(RADIANS(180-$A30)/2))/TAN(RADIANS(180-$A30)/2) -> 7.1662628 | D30: =($B$1+D$3)*(1-TAN(RADIANS(180-$A30)/2))/TAN(RADIANS(180-$A30)/2) -> 7.3834223 | E30: =($B$1+E$3)*(1-TAN(RADIANS(180-$A30)/2))/TAN(RADIANS(180-$A30)/2) -> 7.6005818 | F30: =($B$1+F$3)*(1-TAN(RADIANS(180-$A30)/2))/TAN(RADIANS(180-$A30)/2) -> 7.8177413 | G30: 0 | H30: =($B$1+H$3)*(1-TAN(RADIANS(180-$A30)/2))/TAN(RADIANS(180-$A30)/2) -> 8.9035387 | I30: =($B$1+I$3)*(1-TAN(RADIANS(180-$A30)/2))/TAN(RADIANS(180-$A30)/2) -> 9.7721766 | J30: 0 | K30: 0 | L30: 0 | M30: 0 | N30: 0
A31: 150 | B31: 0 | C31: =($B$1+C$3)*(1-TAN(RADIANS(180-$A31)/2))/TAN(RADIANS(180-$A31)/2) -> 9.0157677 | D31: =($B$1+D$3)*(1-TAN(RADIANS(180-$A31)/2))/TAN(RADIANS(180-$A31)/2) -> 9.2889727 | E31: =($B$1+E$3)*(1-TAN(RADIANS(180-$A31)/2))/TAN(RADIANS(180-$A31)/2) -> 9.5621778 | F31: =($B$1+F$3)*(1-TAN(RADIANS(180-$A31)/2))/TAN(RADIANS(180-$A31)/2) -> 9.8353829 | G31: 0 | H31: =($B$1+H$3)*(1-TAN(RADIANS(180-$A31)/2))/TAN(RADIANS(180-$A31)/2) -> 11.201408 | I31: =($B$1+I$3)*(1-TAN(RADIANS(180-$A31)/2))/TAN(RADIANS(180-$A31)/2) -> 12.294229 | J31: 0 | K31: 0 | L31: 0 | M31: 0 | N31: 0
A33: Thickness: | B33: 3.2
A34: Angle | B34: Raio
B35: 0.5 | C35: 1.3 | D35: 1.4 | E35: 1.5 | F35: 1.6 | G35: 2 | H35: 2.1 | I35: 2.5 | J35: 2.8 | K35: 3.2 | L35: 3.3 | M35: 4 | N35: 4.2
A36: 15 | B36: 0 | C36: 0 | D36: 0 | E36: 0 | F36: 0 | G36: 0 | H36: 0 | I36: 0 | J36: 0 | K36: 0 | L36: 0 | M36: 0 | N36: 0
A37: 20 | B37: 0 | C37: 0 | D37: 0 | E37: 0 | F37: 0 | G37: 0 | H37: 0 | I37: 0 | J37: 0 | K37: 0 | L37: 0 | M37: 0 | N37: 0
A38: 25 | B38: 0 | C38: 0 | D38: 0 | E38: 0 | F38: 0 | G38: 0 | H38: 0 | I38: 0 | J38: 0 | K38: 0 | L38: 0 | M38: 0 | N38: 0
A39: 30 | B39: 0 | C39: 0 | D39: 0 | E39: 0 | F39: 0 | G39: 0 | H39: 0 | I39: 0 | J39: 0 | K39: 0 | L39: 0 | M39: 0 | N39: 0
A40: 35 | B40: 0 | C40: 0 | D40: 0 | E40: 0 | F40: 0 | G40: 0 | H40: 0 | I40: 0 | J40: 0 | K40: 0 | L40: 0 | M40: 0 | N40: 0
A41: 40 | B41: 0 | C41: 0 | D41: 0 | E41: 0 | F41: 0 | G41: 0 | H41: 0 | I41: 0 | J41: 0 | K41: 0 | L41: 0 | M41: 0 | N41: 0
A42: 45 | B42: 0 | C42: 0 | D42: 0 | E42: 0 | F42: 0 | G42: 0 | H42: 0 | I42: 0 | J42: 0 | K42: 0 | L42: 0 | M42: 0 | N42: 0
A43: 50 | B43: 0 | C43: 0 | D43: 0 | E43: 0 | F43: 0 | G43: 0 | H43: 0 | I43: 0 | J43: 0 | K43: 0 | L43: 0 | M43: 0 | N43: 0
A44: 55 | B44: 0 | C44: 0 | D44: 0 | E44: 0 | F44: 0 | G44: 0 | H44: 0 | I44: 0 | J44: 0 | K44: 0 | L44: 0 | M44: 0 | N44: 0
...
