Workbook

Sheet Sheet1
A2: Unit: | B2: Millimeters
A3: Type: | B3: Bend Deduction
A4: Material: | B4: _INOX
A7: Thickness: | B7: 1.2
A8: Angle | B8: Radius
B9: 1.1 | C9: 1.3 | D9: 1.6 | E9: 2 | F9: 2.4 | G9: 2.6 | H9: 3.8
A10: 15 | B10: =2*(-1*INDEX('Desconto Processos'!$B$5:$F$32,MATCH(180-$A10,'Desconto Processos'!$A$5:$A$32,0),MATCH(B$9,'Desconto Processos'!$B$3:$F$3,0))+INDEX('Acrescimo Tangente'!$B$4:$H$13,MATCH($A10,$A$10:$A$19,0),MATCH(B$9,$B$9:$H$9,0))) -> 0.2 | C10: =2*(-1*INDEX('Desconto Processos'!$B$5:$F$32,MATCH(180-$A10,'Desconto Processos'!$A$5:$A$32,0),MATCH(C$9,'Desconto Processos'!$B$3:$F$3,0))+INDEX('Acrescimo Tangente'!$B$4:$H$13,MATCH($A10,$A$10:$A$19,0),MATCH(C$9,$B$9:$H$9,0))) -> 0.2 | D10: =2*(-1*INDEX('Desconto Processos'!$B$5:$F$32,MATCH(180-$A10,'Desconto Processos'!$A$5:$A$32,0),MATCH(D$9,'Desconto Processos'!$B$3:$F$3,0))+INDEX('Acrescimo Tangente'!$B$4:$H$13,MATCH($A10,$A$10:$A$19,0),MATCH(D$9,$B$9:$H$9,0))) -> 0.2 | E10: =2*(-1*INDEX('Desconto Processos'!$B$5:$F$32,MATCH(180-$A10,'Desconto Processos'!$A$5:$A$32,0),MATCH(E$9,'Desconto Processos'!$B$3:$F$3,0))+INDEX('Acrescimo Tangente'!$B$4:$H$13,MATCH($A10,$A$10:$A$19,0),MATCH(E$9,$B$9:$H$9,0))) -> 0.2 | F10: 0 | G10: =2*(-1*INDEX('Desconto Processos'!$B$5:$F$32,MATCH(180-$A10,'Desconto Processos'!$A$5:$A$32,0),MATCH(G$9,'Desconto Processos'!$B$3:$F$3,0))+INDEX('Acrescimo Tangente'!$B$4:$H$13,MATCH($A10,$A$10:$A$19,0),MATCH(G$9,$B$9:$H$9,0))) -> 0.2 | H10: 0
A11: 30 | B11: =2*(-1*INDEX('Desconto Processos'!$B$5:$F$32,MATCH(180-$A11,'Desconto Processos'!$A$5:$A$32,0),MATCH(B$9,'Desconto Processos'!$B$3:$F$3,0))+INDEX('Acrescimo Tangente'!$B$4:$H$13,MATCH($A11,$A$10:$A$19,0),MATCH(B$9,$B$9:$H$9,0))) -> 0.5 | C11: =2*(-1*INDEX('Desconto Processos'!$B$5:$F$32,MATCH(180-$A11,'Desconto Processos'!$A$5:$A$32,0),MATCH(C$9,'Desconto Processos'!$B$3:$F$3,0))+INDEX('Acrescimo Tangente'!$B$4:$H$13,MATCH($A11,$A$10:$A$19,0),MATCH(C$9,$B$9:$H$9,0))) -> 0.5 | D11: =2*(-1*INDEX('Desconto Processos'!$B$5:$F$32,MATCH(180-$A11,'Desconto Processos'!$A$5:$A$32,0),MATCH(D$9,'Desconto Processos'!$B$3:$F$3,0))+INDEX('Acrescimo Tangente'!$B$4:$H$13,MATCH($A11,$A$10:$A$19,0),MATCH(D$9,$B$9:$H$9,0))) -> 0.4 | E11: =2*(-1*INDEX('Desconto Processos'!$B$5:$F$32,MATCH(180-$A11,'Desconto Processos'!$A$5:$A$32,0),MATCH(E$9,'Desconto Processos'!$B$3:$F$3,0))+INDEX('Acrescimo Tangente'!$B$4:$H$13,MATCH($A11,$A$10:$A$19,0),MATCH(E$9,$B$9:$H$9,0))) -> 0.4 | F11: 0 | G11: =2*(-1*INDEX('Desconto Processos'!$B$5:$F$32,MATCH(180-$A11,'Desconto Processos'!$A$5:$A$32,0),MATCH(G$9,'Desconto Processos'!$B$3:$F$3,0))+INDEX('Acrescimo Tangente'!$B$4:$H$13,MATCH($A11,$A$10:$A$19,0),MATCH(G$9,$B$9:$H$9,0))) -> 0.4 | H11: 0
A12: 45 | B12: =2*(-1*INDEX('Desconto Processos'!$B$5:$F$32,MATCH(180-$A12,'Desconto Processos'!$A$5:$A$32,0),MATCH(B$9,'Desconto Processos'!$B$3:$F$3,0))+INDEX('Acrescimo Tangente'!$B$4:$H$13,MATCH($A12,$A$10:$A$19,0),MATCH(B$9,$B$9:$H$9,0))) -> 0.8 | C12: =2*(-1*INDEX('Desconto Processos'!$B$5:$F$32,MATCH(180-$A12,'Desconto Processos'!$A$5:$A$32,0),MATCH(C$9,'Desconto Processos'!$B$3:$F$3,0))+INDEX('Acrescimo Tangente'!$B$4:$H$13,MATCH($A12,$A$10:$A$19,0),MATCH(C$9,$B$9:$H$9,0))) -> 0.7 | D12: =2*(-1*INDEX('Desconto Processos'!$B$5:$F$32,MATCH(180-$A12,'Desconto Processos'!$A$5:$A$32,0),MATCH(D$9,'Desconto Processos'!$B$3:$F$3,0))+INDEX('Acrescimo Tangente'!$B$4:$H$13,MATCH($A12,$A$10:$A$19,0),MATCH(D$9,$B$9:$H$9,0))) -> 0.7 | E12: =2*(-1*INDEX('Desconto Processos'!$B$5:$F$32,MATCH(180-$A12,'Desconto Processos'!$A$5:$A$32,0),MATCH(E$9,'Desconto Processos'!$B$3:$F$3,0))+INDEX('Acrescimo Tangente'!$B$4:$H$13,MATCH($A12,$A$10:$A$19,0),MATCH(E$9,$B$9:$H$9,0))) -> 0.7 | F12: 0 | G12: =2*(-1*INDEX('Desconto Processos'!$B$5:$F$32,MATCH(180-$A12,'Desconto Processos'!$A$5:$A$32,0),MATCH(G$9,'Desconto Processos'!$B$3:$F$3,0))+INDEX('Acrescimo Tangente'!$B$4:$H$13,MATCH($A12,$A$10:$A$19,0),MATCH(G$9,$B$9:$H$9,0))) -> 0.7 | H12: 0
A13: 60 | B13: =2*(-1*INDEX('Desconto Processos'!$B$5:$F$32,MATCH(180-$A13,'Desconto Processos'!$A$5:$A$32,0),MATCH(B$9,'Desconto Processos'!$B$3:$F$3,0))+INDEX('Acrescimo Tangente'!$B$4:$H$13,MATCH($A13,$A$10:$A$19,0),MATCH(B$9,$B$9:$H$9,0))) -> 1.1 | C13: =2*(-1*INDEX('Desconto Processos'!$B$5:$F$32,MATCH(180-$A13,'Desconto Processos'!$A$5:$A$32,0),MATCH(C$9,'Desconto Processos'!$B$3:$F$3,0))+INDEX('Acrescimo Tangente'!$B$4:$H$13,MATCH($A13,$A$10:$A$19,0),MATCH(C$9,$B$9:$H$9,0))) -> 1.1 | D13: =2*(-1*INDEX('Desconto Processos'!$B$5:$F$32,MATCH(180-$A13,'Desconto Processos'!$A$5:$A$32,0),MATCH(D$9,'Desconto Processos'!$B$3:$F$3,0))+INDEX('Acrescimo Tangente'!$B$4:$H$13,MATCH($A13,$A$10:$A$19,0),MATCH(D$9,$B$9:$H$9,0))) -> 1.1 | E13: =2*(-1*INDEX('Desconto Processos'!$B$5:$F$32,MATCH(180-$A13,'Desconto Processos'!$A$5:$A$32,0),MATCH(E$9,'Desconto Processos'!$B$3:$F$3,0))+INDEX('Acrescimo Tangente'!$B$4:$H$13,MATCH($A13,$A$10:$A$19,0),MATCH(E$9,$B$9:$H$9,0))) -> 1.1 | F13: 0 | G13: =2*(-1*INDEX('Desconto Processos'!$B$5:$F$32,MATCH(180-$A13,'Desconto Processos'!$A$5:$A$32,0),MATCH(G$9,'Desconto Processos'!$B$3:$F$3,0))+INDEX('Acrescimo Tangente'!$B$4:$H$13,MATCH($A13,$A$10:$A$19,0),MATCH(G$9,$B$9:$H$9,0))) -> 1.2 | H13: 0
A14: 75 | B14: =2*(-1*INDEX('Desconto Processos'!$B$5:$F$32,MATCH(180-$A14,'Desconto Processos'!$A$5:$A$32,0),MATCH(B$9,'Desconto Processos'!$B$3:$F$3,0))+INDEX('Acrescimo Tangente'!$B$4:$H$13,MATCH($A14,$A$10:$A$19,0),MATCH(B$9,$B$9:$H$9,0))) -> 1.6 | C14: =2*(-1*INDEX('Desconto Processos'!$B$5:$F$32,MATCH(180-$A14,'Desconto Processos'!$A$5:$A$32,0),MATCH(C$9,'Desconto Processos'!$B$3:$F$3,0))+INDEX('Acrescimo Tangente'!$B$4:$H$13,MATCH($A14,$A$10:$A$19,0),MATCH(C$9,$B$9:$H$9,0))) -> 1.6 | D14: =2*(-1*INDEX('Desconto Processos'!$B$5:$F$32,MATCH(180-$A14,'Desconto Processos'!$A$5:$A$32,0),MATCH(D$9,'Desconto Processos'!$B$3:$F$3,0))+INDEX('Acrescimo Tangente'!$B$4:$H$13,MATCH($A14,$A$10:$A$19,0),MATCH(D$9,$B$9:$H$9,0))) -> 1.6 | E14: =2*(-1*INDEX('Desconto Processos'!$B$5:$F$32,MATCH(180-$A14,'Desconto Processos'!$A$5:$A$32,0),MATCH(E$9,'Desconto Processos'!$B$3:$F$3,0))+INDEX('Acrescimo Tangente'!$B$4:$H$13,MATCH($A14,$A$10:$A$19,0),MATCH(E$9,$B$9:$H$9,0))) -> 1.7 | F14: 0 | G14: =2*(-1*INDEX('Desconto Processos'!$B$5:$F$32,MATCH(180-$A14,'Desconto Processos'!$A$5:$A$32,0),MATCH(G$9,'Desconto Processos'!$B$3:$F$3,0))+INDEX('Acrescimo Tangente'!$B$4:$H$13,MATCH($A14,$A$10:$A$19,0),MATCH(G$9,$B$9:$H$9,0))) -> 1.7 | H14: 0
A15: 90 | B15: =2*(-1*INDEX('Desconto Processos'!$B$5:$F$32,MATCH(180-$A15,'Desconto Processos'!$A$5:$A$32,0),MATCH(B$9,'Desconto Processos'!$B$3:$F$3,0))+INDEX('Acrescimo Tangente'!$B$4:$H$13,MATCH($A15,$A$10:$A$19,0),MATCH(B$9,$B$9:$H$9,0))) -> 2.4 | C15: =2*(-1*INDEX('Desconto Processos'!$B$5:$F$32,MATCH(180-$A15,'Desconto Processos'!$A$5:$A$32,0),MATCH(C$9,'Desconto Processos'!$B$3:$F$3,0))+INDEX('Acrescimo Tangente'!$B$4:$H$13,MATCH($A15,$A$10:$A$19,0),MATCH(C$9,$B$9:$H$9,0))) -> 2.4 | D15: =2*(-1*INDEX('Desconto Processos'!$B$5:$F$32,MATCH(180-$A15,'Desconto Processos'!$A$5:$A$32,0),MATCH(D$9,'Desconto Processos'!$B$3:$F$3,0))+INDEX('Acrescimo Tangente'!$B$4:$H$13,MATCH($A15,$A$10:$A$19,0),MATCH(D$9,$B$9:$H$9,0))) -> 2.6 | E15: =2*(-1*INDEX('Desconto Processos'!$B$5:$F$32,MATCH(180-$A15,'Desconto Processos'!$A$5:$A$32,0),MATCH(E$9,'Desconto Processos'!$B$3:$F$3,0))+INDEX('Acrescimo Tangente'!$B$4:$H$13,MATCH($A15,$A$10:$A$19,0),MATCH(E$9,$B$9:$H$9,0))) -> 2.7 | F15: 0 | G15: =2*(-1*INDEX('Desconto Processos'!$B$5:$F$32,MATCH(180-$A15,'Desconto Processos'!$A$5:$A$32,0),MATCH(G$9,'Desconto Processos'!$B$3:$F$3,0))+INDEX('Acrescimo Tangente'!$B$4:$H$13,MATCH($A15,$A$10:$A$19,0),MATCH(G$9,$B$9:$H$9,0))) -> 2.8 | H15: 0
A16: 105 | B16: =2*(-1*INDEX('Desconto Processos'!$B$5:$F$32,MATCH(180-$A16,'Desconto Processos'!$A$5:$A$32,0),MATCH(B$9,'Desconto Processos'!$B$3:$F$3,0))+INDEX('Acrescimo Tangente'!$B$4:$H$13,MATCH($A16,$A$10:$A$19,0),MATCH(B$9,$B$9:$H$9,0))) -> 3.4948367 | C16: =2*(-1*INDEX('Desconto Processos'!$B$5:$F$32,MATCH(180-$A16,'Desconto Processos'!$A$5:$A$32,0),MATCH(C$9,'Desconto Processos'!$B$3:$F$3,0))+INDEX('Acrescimo Tangente'!$B$4:$H$13,MATCH($A16,$A$10:$A$19,0),MATCH(C$9,$B$9:$H$9,0))) -> 3.6161269 | D16: =2*(-1*INDEX('Desconto Processos'!$B$5:$F$32,MATCH(180-$A16,'Desconto Processos'!$A$5:$A$32,0),MATCH(D$9,'Desconto Processos'!$B$3:$F$3,0))+INDEX('Acrescimo Tangente'!$B$4:$H$13,MATCH($A16,$A$10:$A$19,0),MATCH(D$9,$B$9:$H$9,0))) -> 3.7980621 | E16: =2*(-1*INDEX('Desconto Processos'!$B$5:$F$32,MATCH(180-$A16,'Desconto Processos'!$A$5:$A$32,0),MATCH(E$9,'Desconto Processos'!$B$3:$F$3,0))+INDEX('Acrescimo Tangente'!$B$4:$H$13,MATCH($A16,$A$10:$A$19,0),MATCH(E$9,$B$9:$H$9,0))) -> 4.0406424 | F16: 0 | G16: =2*(-1*INDEX('Desconto Processos'!$B$5:$F$32,MATCH(180-$A16,'Desconto Processos'!$A$5:$A$32,0),MATCH(G$9,'Desconto Processos'!$B$3:$F$3,0))+INDEX('Acrescimo Tangente'!$B$4:$H$13,MATCH($A16,$A$10:$A$19,0),MATCH(G$9,$B$9:$H$9,0))) -> 4.4045128 | H16: 0
A17: 120 | B17: =2*(-1*INDEX('Desconto Processos'!$B$5:$F$32,MATCH(180-$A17,'Desconto Processos'!$A$5:$A$32,0),MATCH(B$9,'Desconto Processos'!$B$3:$F$3,0))+INDEX('Acrescimo Tangente'!$B$4:$H$13,MATCH($A17,$A$10:$A$19,0),MATCH(B$9,$B$9:$H$9,0))) -> 4.8674337 | C17: =2*(-1*INDEX('Desconto Processos'!$B$5:$F$32,MATCH(180-$A17,'Desconto Processos'!$A$5:$A$32,0),MATCH(C$9,'Desconto Processos'!$B$3:$F$3,0))+INDEX('Acrescimo Tangente'!$B$4:$H$13,MATCH($A17,$A$10:$A$19,0),MATCH(C$9,$B$9:$H$9,0))) -> 5.060254 | D17: =2*(-1*INDEX('Desconto Processos'!$B$5:$F$32,MATCH(180-$A17,'Desconto Processos'!$A$5:$A$32,0),MATCH(D$9,'Desconto Processos'!$B$3:$F$3,0))+INDEX('Acrescimo Tangente'!$B$4:$H$13,MATCH($A17,$A$10:$A$19,0),MATCH(D$9,$B$9:$H$9,0))) -> 5.4994845 | E17: =2*(-1*INDEX('Desconto Processos'!$B$5:$F$32,MATCH(180-$A17,'Desconto Processos'!$A$5:$A$32,0),MATCH(E$9,'Desconto Processos'!$B$3:$F$3,0))+INDEX('Acrescimo Tangente'!$B$4:$H$13,MATCH($A17,$A$10:$A$19,0),MATCH(E$9,$B$9:$H$9,0))) -> 5.9851252 | F17: 0 | G17: =2*(-1*INDEX('Desconto Processos'!$B$5:$F$32,MATCH(180-$A17,'Desconto Processos'!$A$5:$A$32,0),MATCH(G$9,'Desconto Processos'!$B$3:$F$3,0))+INDEX('Acrescimo Tangente'!$B$4:$H$13,MATCH($A17,$A$10:$A$19,0),MATCH(G$9,$B$9:$H$9,0))) -> 6.6635861 | H17: 0
A18: 135 | B18: =2*(-1*INDEX('Desconto Processos'!$B$5:$F$32,MATCH(180-$A18,'Desconto Processos'!$A$5:$A$32,0),MATCH(B$9,'Desconto Processos'!$B$3:$F$3,0))+INDEX('Acrescimo Tangente'!$B$4:$H$13,MATCH($A18,$A$10:$A$19,0),MATCH(B$9,$B$9:$H$9,0))) -> 7.7053824 | C18: =2*(-1*INDEX('Desconto Processos'!$B$5:$F$32,MATCH(180-$A18,'Desconto Processos'!$A$5:$A$32,0),MATCH(C$9,'Desconto Processos'!$B$3:$F$3,0))+INDEX('Acrescimo Tangente'!$B$4:$H$13,MATCH($A18,$A$10:$A$19,0),MATCH(C$9,$B$9:$H$9,0))) -> 8.0710678 | D18: =2*(-1*INDEX('Desconto Processos'!$B$5:$F$32,MATCH(180-$A18,'Desconto Processos'!$A$5:$A$32,0),MATCH(D$9,'Desconto Processos'!$B$3:$F$3,0))+INDEX('Acrescimo Tangente'!$B$4:$H$13,MATCH($A18,$A$10:$A$19,0),MATCH(D$9,$B$9:$H$9,0))) -> 8.7195959 | E18: =2*(-1*INDEX('Desconto Processos'!$B$5:$F$32,MATCH(180-$A18,'Desconto Processos'!$A$5:$A$32,0),MATCH(E$9,'Desconto Processos'!$B$3:$F$3,0))+INDEX('Acrescimo Tangente'!$B$4:$H$13,MATCH($A18,$A$10:$A$19,0),MATCH(E$9,$B$9:$H$9,0))) -> 9.6509668 | F18: 0 | G18: =2*(-1*INDEX('Desconto Processos'!$B$5:$F$32,MATCH(180-$A18,'Desconto Processos'!$A$5:$A$32,0),MATCH(G$9,'Desconto Processos'!$B$3:$F$3,0))+INDEX('Acrescimo Tangente'!$B$4:$H$13,MATCH($A18,$A$10:$A$19,0),MATCH(G$9,$B$9:$H$9,0))) -> 11.148023 | H18: 0
A19: 150 | B19: =2*(-1*INDEX('Desconto Processos'!$B$5:$F$32,MATCH(180-$A19,'Desconto Processos'!$A$5:$A$32,0),MATCH(B$9,'Desconto Processos'!$B$3:$F$3,0))+INDEX('Acrescimo Tangente'!$B$4:$H$13,MATCH($A19,$A$10:$A$19,0),MATCH(B$9,$B$9:$H$9,0))) -> 13.367434 | C19: =2*(-1*INDEX('Desconto Processos'!$B$5:$F$32,MATCH(180-$A19,'Desconto Processos'!$A$5:$A$32,0),MATCH(C$9,'Desconto Processos'!$B$3:$F$3,0))+INDEX('Acrescimo Tangente'!$B$4:$H$13,MATCH($A19,$A$10:$A$19,0),MATCH(C$9,$B$9:$H$9,0))) -> 14.260254 | D19: =2*(-1*INDEX('Desconto Processos'!$B$5:$F$32,MATCH(180-$A19,'Desconto Processos'!$A$5:$A$32,0),MATCH(D$9,'Desconto Processos'!$B$3:$F$3,0))+INDEX('Acrescimo Tangente'!$B$4:$H$13,MATCH($A19,$A$10:$A$19,0),MATCH(D$9,$B$9:$H$9,0))) -> 15.599485 | E19: =2*(-1*INDEX('Desconto Processos'!$B$5:$F$32,MATCH(180-$A19,'Desconto Processos'!$A$5:$A$32,0),MATCH(E$9,'Desconto Processos'!$B$3:$F$3,0))+INDEX('Acrescimo Tangente'!$B$4:$H$13,MATCH($A19,$A$10:$A$19,0),MATCH(E$9,$B$9:$H$9,0))) -> 17.685125 | F19: 0 | G19: =2*(-1*INDEX('Desconto Processos'!$B$5:$F$32,MATCH(180-$A19,'Desconto Processos'!$A$5:$A$32,0),MATCH(G$9,'Desconto Processos'!$B$3:$F$3,0))+INDEX('Acrescimo Tangente'!$B$4:$H$13,MATCH($A19,$A$10:$A$19,0),MATCH(G$9,$B$9:$H$9,0))) -> 21.263586 | H19: 0
A21: Thickness: | B21: 1.5
A22: Angle | B22: Radius
B23: 1.1 | C23: 1.3 | D23: 1.6 | E23: 2 | F23: 2.4 | G23: 2.6 | H23: 3.8
A24: 15 | B24: 0 | C24: 0 | D24: 0 | E24: =2*(-1*INDEX('Desconto Processos'!$G$5:$G$32,MATCH(180-$A24,'Desconto Processos'!$A$5:$A$32,0),MATCH(E$23,'Desconto Processos'!$G$3,0))+INDEX('Acrescimo Tangente'!$B$18:$H$27,MATCH($A24,$A$10:$A$19,0),MATCH(E$23,$B$9:$H$9,0))) -> 0.2 | F24: 0 | G24: 0 | H24: 0
A25: 30 | B25: 0 | C25: 0 | D25: 0 | E25: =2*(-1*INDEX('Desconto Processos'!$G$5:$G$32,MATCH(180-$A25,'Desconto Processos'!$A$5:$A$32,0),MATCH(E$23,'Desconto Processos'!$G$3,0))+INDEX('Acrescimo Tangente'!$B$18:$H$27,MATCH($A25,$A$10:$A$19,0),MATCH(E$23,$B$9:$H$9,0))) -> 0.5 | F25: 0 | G25: 0 | H25: 0
A26: 45 | B26: 0 | C26: 0 | D26: 0 | E26: =2*(-1*INDEX('Desconto Processos'!$G$5:$G$32,MATCH(180-$A26,'Desconto Processos'!$A$5:$A$32,0),MATCH(E$23,'Desconto Processos'!$G$3,0))+INDEX('Acrescimo Tangente'!$B$18:$H$27,MATCH($A26,$A$10:$A$19,0),MATCH(E$23,$B$9:$H$9,0))) -> 0.8 | F26: 0 | G26: 0 | H26: 0
A27: 60 | B27: 0 | C27: 0 | D27: 0 | E27: =2*(-1*INDEX('Desconto Processos'!$G$5:$G$32,MATCH(180-$A27,'Desconto Processos'!$A$5:$A$32,0),MATCH(E$23,'Desconto Processos'!$G$3,0))+INDEX('Acrescimo Tangente'!$B$18:$H$27,MATCH($A27,$A$10:$A$19,0),MATCH(E$23,$B$9:$H$9,0))) -> 1.2 | F27: 0 | G27: 0 | H27: 0
A28: 75 | B28: 0 | C28: 0 | D28: 0 | E28: =2*(-1*INDEX('Desconto Processos'!$G$5:$G$32,MATCH(180-$A28,'Desconto Processos'!$A$5:$A$32,0),MATCH(E$23,'Desconto Processos'!$G$3,0))+INDEX('Acrescimo Tangente'!$B$18:$H$27,MATCH($A28,$A$10:$A$19,0),MATCH(E$23,$B$9:$H$9,0))) -> 1.9 | F28: 0 | G28: 0 | H28: 0
A29: 90 | B29: 0 | C29: 0 | D29: 0 | E29: =2*(-1*INDEX('Desconto Processos'!$G$5:$G$32,MATCH(180-$A29,'Desconto Processos'!$A$5:$A$32,0),MATCH(E$23,'Desconto Processos'!$G$3,0))+INDEX('Acrescimo Tangente'!$B$18:$H$27,MATCH($A29,$A$10:$A$19,0),MATCH(E$23,$B$9:$H$9,0))) -> 3 | F29: 0 | G29: 0 | H29: 0
A30: 105 | B30: 0 | C30: 0 | D30: 0 | E30: =2*(-1*INDEX('Desconto Processos'!$G$5:$G$32,MATCH(180-$A30,'Desconto Processos'!$A$5:$A$32,0),MATCH(E$23,'Desconto Processos'!$G$3,0))+INDEX('Acrescimo Tangente'!$B$18:$H$27,MATCH($A30,$A$10:$A$19,0),MATCH(E$23,$B$9:$H$9,0))) -> 4.1225776 | F30: 0 | G30: 0 | H30: 0
A31: 120 | B31: 0 | C31: 0 | D31: 0 | E31: =2*(-1*INDEX('Desconto Processos'!$G$5:$G$32,MATCH(180-$A31,'Desconto Processos'!$A$5:$A$32,0),MATCH(E$23,'Desconto Processos'!$G$3,0))+INDEX('Acrescimo Tangente'!$B$18:$H$27,MATCH($A31,$A$10:$A$19,0),MATCH(E$23,$B$9:$H$9,0))) -> 6.4243557 | F31: 0 | G31: 0 | H31: 0
A32: 135 | B32: 0 | C32: 0 | D32: 0 | E32: =2*(-1*INDEX('Desconto Processos'!$G$5:$G$32,MATCH(180-$A32,'Desconto Processos'!$A$5:$A$32,0),MATCH(E$23,'Desconto Processos'!$G$3,0))+INDEX('Acrescimo Tangente'!$B$18:$H$27,MATCH($A32,$A$10:$A$19,0),MATCH(E$23,$B$9:$H$9,0))) -> 10.599495 | F32: 0 | G32: 0 | H32: 0
A33: 150 | B33: 0 | C33: 0 | D33: 0 | E33: =2*(-1*INDEX('Desconto Processos'!$G$5:$G$32,MATCH(180-$A33,'Desconto Processos'!$A$5:$A$32,0),MATCH(E$23,'Desconto Processos'!$G$3,0))+INDEX('Acrescimo Tangente'!$B$18:$H$27,MATCH($A33,$A$10:$A$19,0),MATCH(E$23,$B$9:$H$9,0))) -> 19.324356 | F33: 0 | G33: 0 | H33: 0
A35: Thickness: | B35: 2
A36: Angle | B36: Radius
B37: 1.1 | C37: 1.3 | D37: 1.6 | E37: 2 | F37: 2.4 | G37: 2.6 | H37: 3.8
A38: 15 | B38: 0 | C38: 0 | D38: 0 | E38: 0 | F38: =2*(-1*INDEX('Desconto Processos'!$H$5:$H$32,MATCH(180-$A38,'Desconto Processos'!$A$5:$A$32,0),MATCH(F$37,'Desconto Processos'!$H$3,0))+INDEX('Acrescimo Tangente'!$B$32:$H$41,MATCH($A38,$A$10:$A$19,0),MATCH(F$37,$B$9:$H$9,0))) -> 0.2 | G38: 0 | H38: 0
A39: 30 | B39: 0 | C39: 0 | D39: 0 | E39: 0 | F39: =2*(-1*INDEX('Desconto Processos'!$H$5:$H$32,MATCH(180-$A39,'Desconto Processos'!$A$5:$A$32,0),MATCH(F$37,'Desconto Processos'!$H$3,0))+INDEX('Acrescimo Tangente'!$B$32:$H$41,MATCH($A39,$A$10:$A$19,0),MATCH(F$37,$B$9:$H$9,0))) -> 0.6 | G39: 0 | H39: 0
A40: 45 | B40: 0 | C40: 0 | D40: 0 | E40: 0 | F40: =2*(-1*INDEX('Desconto Processos'!$H$5:$H$32,MATCH(180-$A40,'Desconto Processos'!$A$5:$A$32,0),MATCH(F$37,'Desconto Processos'!$H$3,0))+INDEX('Acrescimo Tangente'!$B$32:$H$41,MATCH($A40,$A$10:$A$19,0),MATCH(F$37,$B$9:$H$9,0))) -> 1.1 | G40: 0 | H40: 0
A41: 60 | B41: 0 | C41: 0 | D41: 0 | E41: 0 | F41: =2*(-1*INDEX('Desconto Processos'!$H$5:$H$32,MATCH(180-$A41,'Desconto Processos'!$A$5:$A$32,0),MATCH(F$37,'Desconto Processos'!$H$3,0))+INDEX('Acrescimo Tangente'!$B$32:$H$41,MATCH($A41,$A$10:$A$19,0),MATCH(F$37,$B$9:$H$9,0))) -> 1.8 | G41: 0 | H41: 0
A42: 75 | B42: 0 | C42: 0 | D42: 0 | E42: 0 | F42: =2*(-1*INDEX('Desconto Processos'!$H$5:$H$32,MATCH(180-$A42,'Desconto Processos'!$A$5:$A$32,0),MATCH(F$37,'Desconto Processos'!$H$3,0))+INDEX('Acrescimo Tangente'!$B$32:$H$41,MATCH($A42,$A$10:$A$19,0),MATCH(F$37,$B$9:$H$9,0))) -> 2.6 | G42: 0 | H42: 0
A43: 90 | B43: 0 | C43: 0 | D43: 0 | E43: 0 | F43: =2*(-1*INDEX('Desconto Processos'!$H$5:$H$32,MATCH(180-$A43,'Desconto Processos'!$A$5:$A$32,0),MATCH(F$37,'Desconto Processos'!$H$3,0))+INDEX('Acrescimo Tangente'!$B$32:$H$41,MATCH($A43,$A$10:$A$19,0),MATCH(F$37,$B$9:$H$9,0))) -> 4 | G43: 0 | H43: 0
A44: 105 | B44: 0 | C44: 0 | D44: 0 | E44: 0 | F44: =2*(-1*INDEX('Desconto Processos'!$H$5:$H$32,MATCH(180-$A44,'Desconto Processos'!$A$5:$A$32,0),MATCH(F$37,'Desconto Processos'!$H$3,0))+INDEX('Acrescimo Tangente'!$B$32:$H$41,MATCH($A44,$A$10:$A$19,0),MATCH(F$37,$B$9:$H$9,0))) -> 5.4683833 | G44: 0 | H44: 0
A45: 120 | B45: 0 | C45: 0 | D45: 0 | E45: 0 | F45: =2*(-1*INDEX('Desconto Processos'!$H$5:$H$32,MATCH(180-$A45,'Desconto Processos'!$A$5:$A$32,0),MATCH(F$37,'Desconto Processos'!$H$3,0))+INDEX('Acrescimo Tangente'!$B$32:$H$41,MATCH($A45,$A$10:$A$19,0),MATCH(F$37,$B$9:$H$9,0))) -> 8.4420471 | G45: 0 | H45: 0
...

Sheet Desconto Processos
A1: ESPESSURA | B1: 1.2 mm | G1: 1.5mm | H1: 2.0mm | I1: 3.0mm
A2: MATRIZ | B2: 6 | C2: 8 | D2: 10 | E2: 12 | F2: 16 | G2: 12 | H2: 12 | I2: 20
A3: RAIO | B3: 1.1 | C3: 1.3 | D3: 1.6 | E3: 2 | F3: 2.6 | G3: 2 | H3: 2.4 | I3: 3.8
A4: ÂNGULO ( b) | B4: ENCURTAMENTO (∆L)
A5: 30 | B5: -0.4 | C5: -0.3 | D5: -0.15 | E5: -0.1 | F5: -0.25 | G5: -0.1 | H5: -0.25 | I5: -0.15
A6: 35
A7: 40
A8: 45 | B8: -0.6 | C8: -0.5 | D8: -0.4 | E8: -0.3 | F8: -0.2 | G8: -0.35 | H8: -0.5 | I8: -0.75
A9: 50
A10: 55
A11: 60 | B11: -0.75 | C11: -0.7 | D11: -0.7 | E11: -0.65 | F11: -0.55 | G11: -0.65 | H11: -1 | I11: -1.45
A12: 65
A13: 70
A14: 75 | B14: -1.05 | C14: -1.05 | D14: -1.05 | E14: -1.05 | F14: -1.05 | G14: -1 | H14: -1.4 | I14: -2.15
A15: 80
A16: 85
A17: 90 | B17: -1.2 | C17: -1.2 | D17: -1.3 | E17: -1.35 | F17: -1.4 | G17: -1.5 | H17: -2 | I17: -3
A18: 95
A19: 100
A20: 105 | B20: -0.8 | C20: -0.8 | D20: -0.8 | E20: -0.85 | F20: -0.85 | G20: -0.95 | H20: -1.3 | I20: -2.05
A21: 110
A22: 115
A23: 120 | B23: -0.55 | C23: -0.55 | D23: -0.55 | E23: -0.55 | F23: -0.6 | G23: -0.6 | H23: -0.9 | I23: -1.4
A24: 125
A25: 130
A26: 135 | B26: -0.4 | C26: -0.35 | D26: -0.35 | E26: -0.35 | F26: -0.35 | G26: -0.4 | H26: -0.55 | I26: -0.9
A27: 140
A28: 145
A29: 150 | B29: -0.25 | C29: -0.25 | D29: -0.2 | E29: -0.2 | F29: -0.2 | G29: -0.25 | H29: -0.3 | I29: -0.45
A30: 155
A31: 160
A32: 165 | B32: -0.1 | C32: -0.1 | D32: -0.1 | E32: -0.1 | F32: -0.1 | G32: -0.1 | H32: -0.1 | I32: -0.15

Sheet Acrescimo Tangente
A1: Thickness: | B1: 1.2
A2: Angle | B2: Radius
B3: 1.1 | C3: 1.3 | D3: 1.6 | E3: 2 | F3: 2.4 | G3: 2.6 | H3: 3.8
A4: 15 | B4: 0 | C4: 0 | D4: 0 | E4: 0 | F4: 0 | G4: 0 | H4: 0
A5: 30 | B5: 0 | C5: 0 | D5: 0 | E5: 0 | F5: 0 | G5: 0 | H5: 0
A6: 45 | B6: 0 | C6: 0 | D6: 0 | E6: 0 | F6: 0 | G6: 0 | H6: 0
A7: 60 | B7: 0 | C7: 0 | D7: 0 | E7: 0 | F7: 0 | G7: 0 | H7: 0
A8: 75 | B8: 0 | C8: 0 | D8: 0 | E8: 0 | F8: 0 | G8: 0 | H8: 0
A9: 90 | B9: 0 | C9: 0 | D9: 0 | E9: 0 | F9: 0 | G9: 0 | H9: 0
A10: 105 | B10: =($B$1+B$3)*(1-TAN(RADIANS(180-$A10)/2))/TAN(RADIANS(180-$A10)/2) -> 0.69741836 | C10: =($B$1+C$3)*(1-TAN(RADIANS(180-$A10)/2))/TAN(RADIANS(180-$A10)/2) -> 0.75806343 | D10: =($B$1+D$3)*(1-TAN(RADIANS(180-$A10)/2))/TAN(RADIANS(180-$A10)/2) -> 0.84903104 | E10: =($B$1+E$3)*(1-TAN(RADIANS(180-$A10)/2))/TAN(RADIANS(180-$A10)/2) -> 0.97032119 | F10: 0 | G10: =($B$1+G$3)*(1-TAN(RADIANS(180-$A10)/2))/TAN(RADIANS(180-$A10)/2) -> 1.1522564 | H10: 0
A11: 120 | B11: =($B$1+B$3)*(1-TAN(RADIANS(180-$A11)/2))/TAN(RADIANS(180-$A11)/2) -> 1.6837169 | C11: =($B$1+C$3)*(1-TAN(RADIANS(180-$A11)/2))/TAN(RADIANS(180-$A11)/2) -> 1.830127 | D11: =($B$1+D$3)*(1-TAN(RADIANS(180-$A11)/2))/TAN(RADIANS(180-$A11)/2) -> 2.0497423 | E11: =($B$1+E$3)*(1-TAN(RADIANS(180-$A11)/2))/TAN(RADIANS(180-$A11)/2) -> 2.3425626 | F11: 0 | G11: =($B$1+G$3)*(1-TAN(RADIANS(180-$A11)/2))/TAN(RADIANS(180-$A11)/2) -> 2.7817931 | H11: 0
A12: 135 | B12: =($B$1+B$3)*(1-TAN(RADIANS(180-$A12)/2))/TAN(RADIANS(180-$A12)/2) -> 3.2526912 | C12: =($B$1+C$3)*(1-TAN(RADIANS(180-$A12)/2))/TAN(RADIANS(180-$A12)/2) -> 3.5355339 | D12: =($B$1+D$3)*(1-TAN(RADIANS(180-$A12)/2))/TAN(RADIANS(180-$A12)/2) -> 3.959798 | E12: =($B$1+E$3)*(1-TAN(RADIANS(180-$A12)/2))/TAN(RADIANS(180-$A12)/2) -> 4.5254834 | F12: 0 | G12: =($B$1+G$3)*(1-TAN(RADIANS(180-$A12)/2))/TAN(RADIANS(180-$A12)/2) -> 5.3740115 | H12: 0
A13: 150 | B13: =($B$1+B$3)*(1-TAN(RADIANS(180-$A13)/2))/TAN(RADIANS(180-$A13)/2) -> 6.2837169 | C13: =($B$1+C$3)*(1-TAN(RADIANS(180-$A13)/2))/TAN(RADIANS(180-$A13)/2) -> 6.830127 | D13: =($B$1+D$3)*(1-TAN(RADIANS(180-$A13)/2))/TAN(RADIANS(180-$A13)/2) -> 7.6497423 | E13: =($B$1+E$3)*(1-TAN(RADIANS(180-$A13)/2))/TAN(RADIANS(180-$A13)/2) -> 8.7425626 | F13: 0 | G13: =($B$1+G$3)*(1-TAN(RADIANS(180-$A13)/2))/TAN(RADIANS(180-$A13)/2) -> 10.381793 | H13: 0
A15: Thickness: | B15: 1.5
A16: Angle | B16: Radius
B17: 1.1 | C17: 1.3 | D17: 1.6 | E17: 2 | F17: 2.4 | G17: 2.6 | H17: 3.8
A18: 15 | B18: 0 | C18: 0 | D18: 0 | E18: 0 | F18: 0 | G18: 0 | H18: 0
A19: 30 | B19: 0 | C19: 0 | D19: 0 | E19: 0 | F19: 0 | G19: 0 | H19: 0
A20: 45 | B20: 0 | C20: 0 | D20: 0 | E20: 0 | F20: 0 | G20: 0 | H20: 0
A21: 60 | B21: 0 | C21: 0 | D21: 0 | E21: 0 | F21: 0 | G21: 0 | H21: 0
A22: 75 | B22: 0 | C22: 0 | D22: 0 | E22: 0 | F22: 0 | G22: 0 | H22: 0
A23: 90 | B23: 0 | C23: 0 | D23: 0 | E23: 0 | F23: 0 | G23: 0 | H23: 0
A24: 105 | B24: 0 | C24: 0 | D24: 0 | E24: =($B$15+E$17)*(1-TAN(RADIANS(180-$A24)/2))/TAN(RADIANS(180-$A24)/2) -> 1.0612888 | F24: 0 | G24: 0 | H24: 0
A25: 120 | B25: 0 | C25: 0 | D25: 0 | E25: =($B$15+E$17)*(1-TAN(RADIANS(180-$A25)/2))/TAN(RADIANS(180-$A25)/2) -> 2.5621778 | F25: 0 | G25: 0 | H25: 0
A26: 135 | B26: 0 | C26: 0 | D26: 0 | E26: =($B$15+E$17)*(1-TAN(RADIANS(180-$A26)/2))/TAN(RADIANS(180-$A26)/2) -> 4.9497475 | F26: 0 | G26: 0 | H26: 0
A27: 150 | B27: 0 | C27: 0 | D27: 0 | E27: =($B$15+E$17)*(1-TAN(RADIANS(180-$A27)/2))/TAN(RADIANS(180-$A27)/2) -> 9.5621778 | F27: 0 | G27: 0 | H27: 0
A29: Thickness: | B29: 2
A30: Angle | B30: Radius
B31: 1.1 | C31: 1.3 | D31: 1.6 | E31: 2 | F31: 2.4 | G31: 2.6 | H31: 3.8
A32: 15 | B32: 0 | C32: 0 | D32: 0 | E32: 0 | F32: 0 | G32: 0 | H32: 0
A33: 30 | B33: 0 | C33: 0 | D33: 0 | E33: 0 | F33: 0 | G33: 0 | H33: 0
A34: 45 | B34: 0 | C34: 0 | D34: 0 | E34: 0 | F34: 0 | G34: 0 | H34: 0
A35: 60 | B35: 0 | C35: 0 | D35: 0 | E35: 0 | F35: 0 | G35: 0 | H35: 0
A36: 75 | B36: 0 | C36: 0 | D36: 0 | E36: 0 | F36: 0 | G36: 0 | H36: 0
A37: 90 | B37: 0 | C37: 0 | D37: 0 | E37: 0 | F37: 0 | G37: 0 | H37: 0
A38: 105 | B38: 0 | C38: 0 | D38: 0 | E38: 0 | F38: =($B$29+F$31)*(1-TAN(RADIANS(180-$A38)/2))/TAN(RADIANS(180-$A38)/2) -> 1.3341916 | G38: 0 | H38: 0
A39: 120 | B39: 0 | C39: 0 | D39: 0 | E39: 0 | F39: =($B$29+F$31)*(1-TAN(RADIANS(180-$A39)/2))/TAN(RADIANS(180-$A39)/2) -> 3.2210236 | G39: 0 | H39: 0
A40: 135 | B40: 0 | C40: 0 | D40: 0 | E40: 0 | F40: =($B$29+F$31)*(1-TAN(RADIANS(180-$A40)/2))/TAN(RADIANS(180-$A40)/2) -> 6.2225397 | G40: 0 | H40: 0
A41: 150 | B41: 0 | C41: 0 | D41: 0 | E41: 0 | F41: =($B$29+F$31)*(1-TAN(RADIANS(180-$A41)/2))/TAN(RADIANS(180-$A41)/2) -> 12.021024 | G41: 0 | H41: 0
A43: Thickness: | B43: 3
...
